ERROR 2025-03-18 10:53:09,068 D:\projects\qr\qr\env\scripts\python.py\Lib\site-packages\django\utils\log.py:248 Internal Server Error: /
Traceback (most recent call last):
  File "D:\projects\qr\qr\env\scripts\python.py\Lib\site-packages\django\core\handlers\exception.py", line 55, in inner
    response = get_response(request)
               ^^^^^^^^^^^^^^^^^^^^^
  File "D:\projects\qr\qr\env\scripts\python.py\Lib\site-packages\django\core\handlers\base.py", line 197, in _get_response
    response = wrapped_callback(request, *callback_args, **callback_kwargs)
               ^^^^^^^^^^^^^^^^^^^^^^^^^^^^^^^^^^^^^^^^^^^^^^^^^^^^^^^^^^^^
  File "D:\projects\qr\qr\qr\website\views.py", line 6, in home
    return render(request, 'website/pages/index.html', context)
           ^^^^^^^^^^^^^^^^^^^^^^^^^^^^^^^^^^^^^^^^^^^^^^^^^^^^
  File "D:\projects\qr\qr\env\scripts\python.py\Lib\site-packages\django\shortcuts.py", line 25, in render
    content = loader.render_to_string(template_name, context, request, using=using)
              ^^^^^^^^^^^^^^^^^^^^^^^^^^^^^^^^^^^^^^^^^^^^^^^^^^^^^^^^^^^^^^^^^^^^^
  File "D:\projects\qr\qr\env\scripts\python.py\Lib\site-packages\django\template\loader.py", line 61, in render_to_string
    template = get_template(template_name, using=using)
               ^^^^^^^^^^^^^^^^^^^^^^^^^^^^^^^^^^^^^^^^
  File "D:\projects\qr\qr\env\scripts\python.py\Lib\site-packages\django\template\loader.py", line 19, in get_template
    raise TemplateDoesNotExist(template_name, chain=chain)
django.template.exceptions.TemplateDoesNotExist: website/pages/index.html
ERROR 2025-03-18 10:53:09,101 D:\projects\qr\qr\env\scripts\python.py\Lib\site-packages\django\utils\log.py:248 Internal Server Error: /
Traceback (most recent call last):
  File "D:\projects\qr\qr\env\scripts\python.py\Lib\site-packages\django\urls\base.py", line 71, in reverse
    extra, resolver = resolver.namespace_dict[ns]
                      ~~~~~~~~~~~~~~~~~~~~~~~^^^^
KeyError: 'django_browser_reload'

During handling of the above exception, another exception occurred:

Traceback (most recent call last):
  File "D:\projects\qr\qr\env\scripts\python.py\Lib\site-packages\django\core\handlers\exception.py", line 55, in inner
    response = get_response(request)
               ^^^^^^^^^^^^^^^^^^^^^
  File "D:\projects\qr\qr\env\scripts\python.py\Lib\site-packages\django_browser_reload\middleware.py", line 50, in __call__
    self.maybe_inject(response)
  File "D:\projects\qr\qr\env\scripts\python.py\Lib\site-packages\django_browser_reload\middleware.py", line 82, in maybe_inject
    response.content = head + django_browser_reload_script() + tag + tail
                              ^^^^^^^^^^^^^^^^^^^^^^^^^^^^^^
  File "D:\projects\qr\qr\env\scripts\python.py\Lib\site-packages\django_browser_reload\jinja.py", line 21, in django_browser_reload_script
    reverse("django_browser_reload:events"),
    ^^^^^^^^^^^^^^^^^^^^^^^^^^^^^^^^^^^^^^^
  File "D:\projects\qr\qr\env\scripts\python.py\Lib\site-packages\django\urls\base.py", line 82, in reverse
    raise NoReverseMatch("%s is not a registered namespace" % key)
django.urls.exceptions.NoReverseMatch: 'django_browser_reload' is not a registered namespace
ERROR 2025-03-18 10:53:09,102 D:\projects\qr\qr\env\scripts\python.py\Lib\site-packages\django\core\servers\basehttp.py:213 "GET / HTTP/1.1" 500 93204
ERROR 2025-03-18 10:53:37,193 D:\projects\qr\qr\env\scripts\python.py\Lib\site-packages\django\utils\log.py:248 Internal Server Error: /
Traceback (most recent call last):
  File "D:\projects\qr\qr\env\scripts\python.py\Lib\site-packages\django\core\handlers\exception.py", line 55, in inner
    response = get_response(request)
               ^^^^^^^^^^^^^^^^^^^^^
  File "D:\projects\qr\qr\env\scripts\python.py\Lib\site-packages\django\core\handlers\base.py", line 197, in _get_response
    response = wrapped_callback(request, *callback_args, **callback_kwargs)
               ^^^^^^^^^^^^^^^^^^^^^^^^^^^^^^^^^^^^^^^^^^^^^^^^^^^^^^^^^^^^
  File "D:\projects\qr\qr\qr\website\views.py", line 6, in home
    return render(request, 'website/pages/index.html', context)
           ^^^^^^^^^^^^^^^^^^^^^^^^^^^^^^^^^^^^^^^^^^^^^^^^^^^^
  File "D:\projects\qr\qr\env\scripts\python.py\Lib\site-packages\django\shortcuts.py", line 25, in render
    content = loader.render_to_string(template_name, context, request, using=using)
              ^^^^^^^^^^^^^^^^^^^^^^^^^^^^^^^^^^^^^^^^^^^^^^^^^^^^^^^^^^^^^^^^^^^^^
  File "D:\projects\qr\qr\env\scripts\python.py\Lib\site-packages\django\template\loader.py", line 61, in render_to_string
    template = get_template(template_name, using=using)
               ^^^^^^^^^^^^^^^^^^^^^^^^^^^^^^^^^^^^^^^^
  File "D:\projects\qr\qr\env\scripts\python.py\Lib\site-packages\django\template\loader.py", line 19, in get_template
    raise TemplateDoesNotExist(template_name, chain=chain)
django.template.exceptions.TemplateDoesNotExist: website/pages/index.html
ERROR 2025-03-18 10:53:37,197 D:\projects\qr\qr\env\scripts\python.py\Lib\site-packages\django\core\servers\basehttp.py:213 "GET / HTTP/1.1" 500 83931
ERROR 2025-03-18 10:54:03,459 D:\projects\qr\qr\env\scripts\python.py\Lib\site-packages\django\utils\log.py:248 Internal Server Error: /
Traceback (most recent call last):
  File "D:\projects\qr\qr\env\scripts\python.py\Lib\site-packages\django\core\handlers\exception.py", line 55, in inner
    response = get_response(request)
               ^^^^^^^^^^^^^^^^^^^^^
  File "D:\projects\qr\qr\env\scripts\python.py\Lib\site-packages\django\core\handlers\base.py", line 197, in _get_response
    response = wrapped_callback(request, *callback_args, **callback_kwargs)
               ^^^^^^^^^^^^^^^^^^^^^^^^^^^^^^^^^^^^^^^^^^^^^^^^^^^^^^^^^^^^
  File "D:\projects\qr\qr\qr\website\views.py", line 6, in home
    return render(request, 'website/pages/index.html', context)
           ^^^^^^^^^^^^^^^^^^^^^^^^^^^^^^^^^^^^^^^^^^^^^^^^^^^^
  File "D:\projects\qr\qr\env\scripts\python.py\Lib\site-packages\django\shortcuts.py", line 25, in render
    content = loader.render_to_string(template_name, context, request, using=using)
              ^^^^^^^^^^^^^^^^^^^^^^^^^^^^^^^^^^^^^^^^^^^^^^^^^^^^^^^^^^^^^^^^^^^^^
  File "D:\projects\qr\qr\env\scripts\python.py\Lib\site-packages\django\template\loader.py", line 61, in render_to_string
    template = get_template(template_name, using=using)
               ^^^^^^^^^^^^^^^^^^^^^^^^^^^^^^^^^^^^^^^^
  File "D:\projects\qr\qr\env\scripts\python.py\Lib\site-packages\django\template\loader.py", line 19, in get_template
    raise TemplateDoesNotExist(template_name, chain=chain)
django.template.exceptions.TemplateDoesNotExist: website/pages/index.html
ERROR 2025-03-18 10:54:03,466 D:\projects\qr\qr\env\scripts\python.py\Lib\site-packages\django\core\servers\basehttp.py:213 "GET / HTTP/1.1" 500 83951
ERROR 2025-03-18 10:54:05,096 D:\projects\qr\qr\env\scripts\python.py\Lib\site-packages\django\utils\log.py:248 Internal Server Error: /
Traceback (most recent call last):
  File "D:\projects\qr\qr\env\scripts\python.py\Lib\site-packages\django\core\handlers\exception.py", line 55, in inner
    response = get_response(request)
               ^^^^^^^^^^^^^^^^^^^^^
  File "D:\projects\qr\qr\env\scripts\python.py\Lib\site-packages\django\core\handlers\base.py", line 197, in _get_response
    response = wrapped_callback(request, *callback_args, **callback_kwargs)
               ^^^^^^^^^^^^^^^^^^^^^^^^^^^^^^^^^^^^^^^^^^^^^^^^^^^^^^^^^^^^
  File "D:\projects\qr\qr\qr\website\views.py", line 6, in home
    return render(request, 'website/pages/index.html', context)
           ^^^^^^^^^^^^^^^^^^^^^^^^^^^^^^^^^^^^^^^^^^^^^^^^^^^^
  File "D:\projects\qr\qr\env\scripts\python.py\Lib\site-packages\django\shortcuts.py", line 25, in render
    content = loader.render_to_string(template_name, context, request, using=using)
              ^^^^^^^^^^^^^^^^^^^^^^^^^^^^^^^^^^^^^^^^^^^^^^^^^^^^^^^^^^^^^^^^^^^^^
  File "D:\projects\qr\qr\env\scripts\python.py\Lib\site-packages\django\template\loader.py", line 61, in render_to_string
    template = get_template(template_name, using=using)
               ^^^^^^^^^^^^^^^^^^^^^^^^^^^^^^^^^^^^^^^^
  File "D:\projects\qr\qr\env\scripts\python.py\Lib\site-packages\django\template\loader.py", line 19, in get_template
    raise TemplateDoesNotExist(template_name, chain=chain)
django.template.exceptions.TemplateDoesNotExist: website/pages/index.html
ERROR 2025-03-18 10:54:05,096 D:\projects\qr\qr\env\scripts\python.py\Lib\site-packages\django\core\servers\basehttp.py:213 "GET / HTTP/1.1" 500 84082
ERROR 2025-03-18 10:54:05,824 D:\projects\qr\qr\env\scripts\python.py\Lib\site-packages\django\utils\log.py:248 Internal Server Error: /
Traceback (most recent call last):
  File "D:\projects\qr\qr\env\scripts\python.py\Lib\site-packages\django\core\handlers\exception.py", line 55, in inner
    response = get_response(request)
               ^^^^^^^^^^^^^^^^^^^^^
  File "D:\projects\qr\qr\env\scripts\python.py\Lib\site-packages\django\core\handlers\base.py", line 197, in _get_response
    response = wrapped_callback(request, *callback_args, **callback_kwargs)
               ^^^^^^^^^^^^^^^^^^^^^^^^^^^^^^^^^^^^^^^^^^^^^^^^^^^^^^^^^^^^
  File "D:\projects\qr\qr\qr\website\views.py", line 6, in home
    return render(request, 'website/pages/index.html', context)
           ^^^^^^^^^^^^^^^^^^^^^^^^^^^^^^^^^^^^^^^^^^^^^^^^^^^^
  File "D:\projects\qr\qr\env\scripts\python.py\Lib\site-packages\django\shortcuts.py", line 25, in render
    content = loader.render_to_string(template_name, context, request, using=using)
              ^^^^^^^^^^^^^^^^^^^^^^^^^^^^^^^^^^^^^^^^^^^^^^^^^^^^^^^^^^^^^^^^^^^^^
  File "D:\projects\qr\qr\env\scripts\python.py\Lib\site-packages\django\template\loader.py", line 61, in render_to_string
    template = get_template(template_name, using=using)
               ^^^^^^^^^^^^^^^^^^^^^^^^^^^^^^^^^^^^^^^^
  File "D:\projects\qr\qr\env\scripts\python.py\Lib\site-packages\django\template\loader.py", line 19, in get_template
    raise TemplateDoesNotExist(template_name, chain=chain)
django.template.exceptions.TemplateDoesNotExist: website/pages/index.html
ERROR 2025-03-18 10:54:05,825 D:\projects\qr\qr\env\scripts\python.py\Lib\site-packages\django\core\servers\basehttp.py:213 "GET / HTTP/1.1" 500 84210
ERROR 2025-03-18 10:54:55,691 D:\projects\qr\qr\env\scripts\python.py\Lib\site-packages\django\utils\log.py:248 Internal Server Error: /
Traceback (most recent call last):
  File "D:\projects\qr\qr\env\scripts\python.py\Lib\site-packages\django\core\handlers\exception.py", line 55, in inner
    response = get_response(request)
               ^^^^^^^^^^^^^^^^^^^^^
  File "D:\projects\qr\qr\env\scripts\python.py\Lib\site-packages\django\core\handlers\base.py", line 197, in _get_response
    response = wrapped_callback(request, *callback_args, **callback_kwargs)
               ^^^^^^^^^^^^^^^^^^^^^^^^^^^^^^^^^^^^^^^^^^^^^^^^^^^^^^^^^^^^
  File "D:\projects\qr\qr\qr\website\views.py", line 6, in home
    return render(request, 'website/pages/index.html', context)
           ^^^^^^^^^^^^^^^^^^^^^^^^^^^^^^^^^^^^^^^^^^^^^^^^^^^^
  File "D:\projects\qr\qr\env\scripts\python.py\Lib\site-packages\django\shortcuts.py", line 25, in render
    content = loader.render_to_string(template_name, context, request, using=using)
              ^^^^^^^^^^^^^^^^^^^^^^^^^^^^^^^^^^^^^^^^^^^^^^^^^^^^^^^^^^^^^^^^^^^^^
  File "D:\projects\qr\qr\env\scripts\python.py\Lib\site-packages\django\template\loader.py", line 61, in render_to_string
    template = get_template(template_name, using=using)
               ^^^^^^^^^^^^^^^^^^^^^^^^^^^^^^^^^^^^^^^^
  File "D:\projects\qr\qr\env\scripts\python.py\Lib\site-packages\django\template\loader.py", line 19, in get_template
    raise TemplateDoesNotExist(template_name, chain=chain)
django.template.exceptions.TemplateDoesNotExist: website/pages/index.html
ERROR 2025-03-18 10:54:55,696 D:\projects\qr\qr\env\scripts\python.py\Lib\site-packages\django\core\servers\basehttp.py:213 "GET / HTTP/1.1" 500 83794
ERROR 2025-03-18 10:55:33,007 D:\projects\qr\qr\env\scripts\python.py\Lib\site-packages\django\utils\log.py:248 Internal Server Error: /
Traceback (most recent call last):
  File "D:\projects\qr\qr\env\scripts\python.py\Lib\site-packages\django\core\handlers\exception.py", line 55, in inner
    response = get_response(request)
               ^^^^^^^^^^^^^^^^^^^^^
  File "D:\projects\qr\qr\env\scripts\python.py\Lib\site-packages\django\core\handlers\base.py", line 197, in _get_response
    response = wrapped_callback(request, *callback_args, **callback_kwargs)
               ^^^^^^^^^^^^^^^^^^^^^^^^^^^^^^^^^^^^^^^^^^^^^^^^^^^^^^^^^^^^
  File "D:\projects\qr\qr\qr\website\views.py", line 6, in home
    return render(request, 'website/pages/index.html', context)
           ^^^^^^^^^^^^^^^^^^^^^^^^^^^^^^^^^^^^^^^^^^^^^^^^^^^^
  File "D:\projects\qr\qr\env\scripts\python.py\Lib\site-packages\django\shortcuts.py", line 25, in render
    content = loader.render_to_string(template_name, context, request, using=using)
              ^^^^^^^^^^^^^^^^^^^^^^^^^^^^^^^^^^^^^^^^^^^^^^^^^^^^^^^^^^^^^^^^^^^^^
  File "D:\projects\qr\qr\env\scripts\python.py\Lib\site-packages\django\template\loader.py", line 61, in render_to_string
    template = get_template(template_name, using=using)
               ^^^^^^^^^^^^^^^^^^^^^^^^^^^^^^^^^^^^^^^^
  File "D:\projects\qr\qr\env\scripts\python.py\Lib\site-packages\django\template\loader.py", line 19, in get_template
    raise TemplateDoesNotExist(template_name, chain=chain)
django.template.exceptions.TemplateDoesNotExist: website/pages/index.html
ERROR 2025-03-18 10:55:33,009 D:\projects\qr\qr\env\scripts\python.py\Lib\site-packages\django\core\servers\basehttp.py:213 "GET / HTTP/1.1" 500 83951
ERROR 2025-03-18 10:55:37,145 D:\projects\qr\qr\env\scripts\python.py\Lib\site-packages\django\utils\log.py:248 Internal Server Error: /
Traceback (most recent call last):
  File "D:\projects\qr\qr\env\scripts\python.py\Lib\site-packages\django\core\handlers\exception.py", line 55, in inner
    response = get_response(request)
               ^^^^^^^^^^^^^^^^^^^^^
  File "D:\projects\qr\qr\env\scripts\python.py\Lib\site-packages\django\core\handlers\base.py", line 197, in _get_response
    response = wrapped_callback(request, *callback_args, **callback_kwargs)
               ^^^^^^^^^^^^^^^^^^^^^^^^^^^^^^^^^^^^^^^^^^^^^^^^^^^^^^^^^^^^
  File "D:\projects\qr\qr\qr\website\views.py", line 6, in home
    return render(request, 'website/pages/index.html', context)
           ^^^^^^^^^^^^^^^^^^^^^^^^^^^^^^^^^^^^^^^^^^^^^^^^^^^^
  File "D:\projects\qr\qr\env\scripts\python.py\Lib\site-packages\django\shortcuts.py", line 25, in render
    content = loader.render_to_string(template_name, context, request, using=using)
              ^^^^^^^^^^^^^^^^^^^^^^^^^^^^^^^^^^^^^^^^^^^^^^^^^^^^^^^^^^^^^^^^^^^^^
  File "D:\projects\qr\qr\env\scripts\python.py\Lib\site-packages\django\template\loader.py", line 61, in render_to_string
    template = get_template(template_name, using=using)
               ^^^^^^^^^^^^^^^^^^^^^^^^^^^^^^^^^^^^^^^^
  File "D:\projects\qr\qr\env\scripts\python.py\Lib\site-packages\django\template\loader.py", line 19, in get_template
    raise TemplateDoesNotExist(template_name, chain=chain)
django.template.exceptions.TemplateDoesNotExist: website/pages/index.html
ERROR 2025-03-18 10:55:37,149 D:\projects\qr\qr\env\scripts\python.py\Lib\site-packages\django\core\servers\basehttp.py:213 "GET / HTTP/1.1" 500 83951
ERROR 2025-03-18 10:55:40,076 D:\projects\qr\qr\env\scripts\python.py\Lib\site-packages\django\utils\log.py:248 Internal Server Error: /
Traceback (most recent call last):
  File "D:\projects\qr\qr\env\scripts\python.py\Lib\site-packages\django\core\handlers\exception.py", line 55, in inner
    response = get_response(request)
               ^^^^^^^^^^^^^^^^^^^^^
  File "D:\projects\qr\qr\env\scripts\python.py\Lib\site-packages\django\core\handlers\base.py", line 197, in _get_response
    response = wrapped_callback(request, *callback_args, **callback_kwargs)
               ^^^^^^^^^^^^^^^^^^^^^^^^^^^^^^^^^^^^^^^^^^^^^^^^^^^^^^^^^^^^
  File "D:\projects\qr\qr\qr\website\views.py", line 6, in home
    return render(request, 'website/pages/index.html', context)
           ^^^^^^^^^^^^^^^^^^^^^^^^^^^^^^^^^^^^^^^^^^^^^^^^^^^^
  File "D:\projects\qr\qr\env\scripts\python.py\Lib\site-packages\django\shortcuts.py", line 25, in render
    content = loader.render_to_string(template_name, context, request, using=using)
              ^^^^^^^^^^^^^^^^^^^^^^^^^^^^^^^^^^^^^^^^^^^^^^^^^^^^^^^^^^^^^^^^^^^^^
  File "D:\projects\qr\qr\env\scripts\python.py\Lib\site-packages\django\template\loader.py", line 61, in render_to_string
    template = get_template(template_name, using=using)
               ^^^^^^^^^^^^^^^^^^^^^^^^^^^^^^^^^^^^^^^^
  File "D:\projects\qr\qr\env\scripts\python.py\Lib\site-packages\django\template\loader.py", line 19, in get_template
    raise TemplateDoesNotExist(template_name, chain=chain)
django.template.exceptions.TemplateDoesNotExist: website/pages/index.html
ERROR 2025-03-18 10:55:40,079 D:\projects\qr\qr\env\scripts\python.py\Lib\site-packages\django\core\servers\basehttp.py:213 "GET / HTTP/1.1" 500 84082
ERROR 2025-03-18 11:25:31,550 D:\projects\qr\qr\env\scripts\python.py\Lib\site-packages\django\utils\log.py:248 Internal Server Error: /
Traceback (most recent call last):
  File "D:\projects\qr\qr\env\scripts\python.py\Lib\site-packages\django\core\handlers\exception.py", line 55, in inner
    response = get_response(request)
               ^^^^^^^^^^^^^^^^^^^^^
  File "D:\projects\qr\qr\env\scripts\python.py\Lib\site-packages\django\core\handlers\base.py", line 197, in _get_response
    response = wrapped_callback(request, *callback_args, **callback_kwargs)
               ^^^^^^^^^^^^^^^^^^^^^^^^^^^^^^^^^^^^^^^^^^^^^^^^^^^^^^^^^^^^
  File "D:\projects\qr\qr\qr\website\views.py", line 12, in home
    image = Image.get_last_updated_image_for_user(user)
            ^^^^^^^^^^^^^^^^^^^^^^^^^^^^^^^^^^^^^^^^^^^
  File "D:\projects\qr\qr\qr\website\models.py", line 50, in get_last_updated_image_for_user
    return cls.objects.filter(user=user).order_by('-updated_at').first()
           ^^^^^^^^^^^^^^^^^^^^^^^^^^^^^^^^^^^^^^^^^^^^^^^^^^^^^
  File "D:\projects\qr\qr\env\scripts\python.py\Lib\site-packages\django\db\models\query.py", line 1701, in order_by
    obj.query.add_ordering(*field_names)
  File "D:\projects\qr\qr\env\scripts\python.py\Lib\site-packages\django\db\models\sql\query.py", line 2249, in add_ordering
    self.names_to_path(item.split(LOOKUP_SEP), self.model._meta)
  File "D:\projects\qr\qr\env\scripts\python.py\Lib\site-packages\django\db\models\sql\query.py", line 1768, in names_to_path
    raise FieldError(
django.core.exceptions.FieldError: Cannot resolve keyword 'updated_at' into field. Choices are: id, image, qr_code, user, user_id
ERROR 2025-03-18 11:25:31,554 D:\projects\qr\qr\env\scripts\python.py\Lib\site-packages\django\core\servers\basehttp.py:213 "GET / HTTP/1.1" 500 88111
ERROR 2025-03-18 11:26:17,770 D:\projects\qr\qr\env\scripts\python.py\Lib\site-packages\django\utils\log.py:248 Internal Server Error: /
Traceback (most recent call last):
  File "D:\projects\qr\qr\env\scripts\python.py\Lib\site-packages\django\db\backends\utils.py", line 105, in _execute
    return self.cursor.execute(sql, params)
           ^^^^^^^^^^^^^^^^^^^^^^^^^^^^^^^^
  File "D:\projects\qr\qr\env\scripts\python.py\Lib\site-packages\django\db\backends\sqlite3\base.py", line 354, in execute
    return super().execute(query, params)
           ^^^^^^^^^^^^^^^^^^^^^^^^^^^^^^
sqlite3.OperationalError: no such column: website_image.updated_at

The above exception was the direct cause of the following exception:

Traceback (most recent call last):
  File "D:\projects\qr\qr\env\scripts\python.py\Lib\site-packages\django\core\handlers\exception.py", line 55, in inner
    response = get_response(request)
               ^^^^^^^^^^^^^^^^^^^^^
  File "D:\projects\qr\qr\env\scripts\python.py\Lib\site-packages\django\core\handlers\base.py", line 197, in _get_response
    response = wrapped_callback(request, *callback_args, **callback_kwargs)
               ^^^^^^^^^^^^^^^^^^^^^^^^^^^^^^^^^^^^^^^^^^^^^^^^^^^^^^^^^^^^
  File "D:\projects\qr\qr\qr\website\views.py", line 12, in home
    image = Image.get_last_updated_image_for_user(user)
            ^^^^^^^^^^^^^^^^^^^^^^^^^^^^^^^^^^^^^^^^^^^
  File "D:\projects\qr\qr\qr\website\models.py", line 51, in get_last_updated_image_for_user
    return cls.objects.filter(user=user).order_by('-updated_at').first()
           ^^^^^^^^^^^^^^^^^^^^^^^^^^^^^^^^^^^^^^^^^^^^^^^^^^^^^^^^^^^^^
  File "D:\projects\qr\qr\env\scripts\python.py\Lib\site-packages\django\db\models\query.py", line 1097, in first
    for obj in queryset[:1]:
               ~~~~~~~~^^^^
  File "D:\projects\qr\qr\env\scripts\python.py\Lib\site-packages\django\db\models\query.py", line 400, in __iter__
    self._fetch_all()
  File "D:\projects\qr\qr\env\scripts\python.py\Lib\site-packages\django\db\models\query.py", line 1928, in _fetch_all
    self._result_cache = list(self._iterable_class(self))
                         ^^^^^^^^^^^^^^^^^^^^^^^^^^^^^^^^
  File "D:\projects\qr\qr\env\scripts\python.py\Lib\site-packages\django\db\models\query.py", line 91, in __iter__
    results = compiler.execute_sql(
              ^^^^^^^^^^^^^^^^^^^^^
  File "D:\projects\qr\qr\env\scripts\python.py\Lib\site-packages\django\db\models\sql\compiler.py", line 1574, in execute_sql
    cursor.execute(sql, params)
  File "D:\projects\qr\qr\env\scripts\python.py\Lib\site-packages\django\db\backends\utils.py", line 122, in execute
    return super().execute(sql, params)
           ^^^^^^^^^^^^^^^^^^^^^^^^^^^^
  File "D:\projects\qr\qr\env\scripts\python.py\Lib\site-packages\django\db\backends\utils.py", line 79, in execute
    return self._execute_with_wrappers(
           ^^^^^^^^^^^^^^^^^^^^^^^^^^^^
  File "D:\projects\qr\qr\env\scripts\python.py\Lib\site-packages\django\db\backends\utils.py", line 92, in _execute_with_wrappers
    return executor(sql, params, many, context)
           ^^^^^^^^^^^^^^^^^^^^^^^^^^^^^^^^^^^^
  File "D:\projects\qr\qr\env\scripts\python.py\Lib\site-packages\django\db\backends\utils.py", line 100, in _execute
    with self.db.wrap_database_errors:
         ^^^^^^^^^^^^^^^^^^^^^^^^^^^^
  File "D:\projects\qr\qr\env\scripts\python.py\Lib\site-packages\django\db\utils.py", line 91, in __exit__
    raise dj_exc_value.with_traceback(traceback) from exc_value
  File "D:\projects\qr\qr\env\scripts\python.py\Lib\site-packages\django\db\backends\utils.py", line 105, in _execute
    return self.cursor.execute(sql, params)
           ^^^^^^^^^^^^^^^^^^^^^^^^^^^^^^^^
  File "D:\projects\qr\qr\env\scripts\python.py\Lib\site-packages\django\db\backends\sqlite3\base.py", line 354, in execute
    return super().execute(query, params)
           ^^^^^^^^^^^^^^^^^^^^^^^^^^^^^^
django.db.utils.OperationalError: no such column: website_image.updated_at
ERROR 2025-03-18 11:26:17,775 D:\projects\qr\qr\env\scripts\python.py\Lib\site-packages\django\core\servers\basehttp.py:213 "GET / HTTP/1.1" 500 140027
ERROR 2025-03-18 12:07:32,027 D:\projects\qr\qr\env\scripts\python.py\Lib\site-packages\django\core\handlers\exception.py:124 Invalid HTTP_HOST header: '127.0.0.1:8000'. You may need to add '127.0.0.1' to ALLOWED_HOSTS.
Traceback (most recent call last):
  File "D:\projects\qr\qr\env\scripts\python.py\Lib\site-packages\django\core\handlers\exception.py", line 55, in inner
    response = get_response(request)
               ^^^^^^^^^^^^^^^^^^^^^
  File "D:\projects\qr\qr\env\scripts\python.py\Lib\site-packages\django\utils\deprecation.py", line 128, in __call__
    response = self.process_request(request)
               ^^^^^^^^^^^^^^^^^^^^^^^^^^^^^
  File "D:\projects\qr\qr\env\scripts\python.py\Lib\site-packages\django\middleware\common.py", line 48, in process_request
    host = request.get_host()
           ^^^^^^^^^^^^^^^^^^
  File "D:\projects\qr\qr\env\scripts\python.py\Lib\site-packages\django\http\request.py", line 151, in get_host
    raise DisallowedHost(msg)
django.core.exceptions.DisallowedHost: Invalid HTTP_HOST header: '127.0.0.1:8000'. You may need to add '127.0.0.1' to ALLOWED_HOSTS.
ERROR 2025-03-18 12:07:32,183 D:\projects\qr\qr\env\scripts\python.py\Lib\site-packages\django\core\handlers\exception.py:124 Invalid HTTP_HOST header: '127.0.0.1:8000'. You may need to add '127.0.0.1' to ALLOWED_HOSTS.
Traceback (most recent call last):
  File "D:\projects\qr\qr\env\scripts\python.py\Lib\site-packages\django\core\handlers\exception.py", line 55, in inner
    response = get_response(request)
               ^^^^^^^^^^^^^^^^^^^^^
  File "D:\projects\qr\qr\env\scripts\python.py\Lib\site-packages\django\utils\deprecation.py", line 128, in __call__
    response = self.process_request(request)
               ^^^^^^^^^^^^^^^^^^^^^^^^^^^^^
  File "D:\projects\qr\qr\env\scripts\python.py\Lib\site-packages\django\middleware\common.py", line 48, in process_request
    host = request.get_host()
           ^^^^^^^^^^^^^^^^^^
  File "D:\projects\qr\qr\env\scripts\python.py\Lib\site-packages\django\http\request.py", line 151, in get_host
    raise DisallowedHost(msg)
django.core.exceptions.DisallowedHost: Invalid HTTP_HOST header: '127.0.0.1:8000'. You may need to add '127.0.0.1' to ALLOWED_HOSTS.
ERROR 2025-03-18 12:07:32,302 D:\projects\qr\qr\env\scripts\python.py\Lib\site-packages\django\core\handlers\exception.py:124 Invalid HTTP_HOST header: '127.0.0.1:8000'. You may need to add '127.0.0.1' to ALLOWED_HOSTS.
Traceback (most recent call last):
  File "D:\projects\qr\qr\env\scripts\python.py\Lib\site-packages\django\core\handlers\exception.py", line 55, in inner
    response = get_response(request)
               ^^^^^^^^^^^^^^^^^^^^^
  File "D:\projects\qr\qr\env\scripts\python.py\Lib\site-packages\django\utils\deprecation.py", line 128, in __call__
    response = self.process_request(request)
               ^^^^^^^^^^^^^^^^^^^^^^^^^^^^^
  File "D:\projects\qr\qr\env\scripts\python.py\Lib\site-packages\django\middleware\common.py", line 48, in process_request
    host = request.get_host()
           ^^^^^^^^^^^^^^^^^^
  File "D:\projects\qr\qr\env\scripts\python.py\Lib\site-packages\django\http\request.py", line 151, in get_host
    raise DisallowedHost(msg)
django.core.exceptions.DisallowedHost: Invalid HTTP_HOST header: '127.0.0.1:8000'. You may need to add '127.0.0.1' to ALLOWED_HOSTS.
ERROR 2025-03-18 12:07:32,430 D:\projects\qr\qr\env\scripts\python.py\Lib\site-packages\django\core\handlers\exception.py:124 Invalid HTTP_HOST header: '127.0.0.1:8000'. You may need to add '127.0.0.1' to ALLOWED_HOSTS.
Traceback (most recent call last):
  File "D:\projects\qr\qr\env\scripts\python.py\Lib\site-packages\django\core\handlers\exception.py", line 55, in inner
    response = get_response(request)
               ^^^^^^^^^^^^^^^^^^^^^
  File "D:\projects\qr\qr\env\scripts\python.py\Lib\site-packages\django\utils\deprecation.py", line 128, in __call__
    response = self.process_request(request)
               ^^^^^^^^^^^^^^^^^^^^^^^^^^^^^
  File "D:\projects\qr\qr\env\scripts\python.py\Lib\site-packages\django\middleware\common.py", line 48, in process_request
    host = request.get_host()
           ^^^^^^^^^^^^^^^^^^
  File "D:\projects\qr\qr\env\scripts\python.py\Lib\site-packages\django\http\request.py", line 151, in get_host
    raise DisallowedHost(msg)
django.core.exceptions.DisallowedHost: Invalid HTTP_HOST header: '127.0.0.1:8000'. You may need to add '127.0.0.1' to ALLOWED_HOSTS.
ERROR 2025-03-18 12:07:32,555 D:\projects\qr\qr\env\scripts\python.py\Lib\site-packages\django\core\handlers\exception.py:124 Invalid HTTP_HOST header: '127.0.0.1:8000'. You may need to add '127.0.0.1' to ALLOWED_HOSTS.
Traceback (most recent call last):
  File "D:\projects\qr\qr\env\scripts\python.py\Lib\site-packages\django\core\handlers\exception.py", line 55, in inner
    response = get_response(request)
               ^^^^^^^^^^^^^^^^^^^^^
  File "D:\projects\qr\qr\env\scripts\python.py\Lib\site-packages\django\utils\deprecation.py", line 128, in __call__
    response = self.process_request(request)
               ^^^^^^^^^^^^^^^^^^^^^^^^^^^^^
  File "D:\projects\qr\qr\env\scripts\python.py\Lib\site-packages\django\middleware\common.py", line 48, in process_request
    host = request.get_host()
           ^^^^^^^^^^^^^^^^^^
  File "D:\projects\qr\qr\env\scripts\python.py\Lib\site-packages\django\http\request.py", line 151, in get_host
    raise DisallowedHost(msg)
django.core.exceptions.DisallowedHost: Invalid HTTP_HOST header: '127.0.0.1:8000'. You may need to add '127.0.0.1' to ALLOWED_HOSTS.
ERROR 2025-03-18 12:07:32,680 D:\projects\qr\qr\env\scripts\python.py\Lib\site-packages\django\core\handlers\exception.py:124 Invalid HTTP_HOST header: '127.0.0.1:8000'. You may need to add '127.0.0.1' to ALLOWED_HOSTS.
Traceback (most recent call last):
  File "D:\projects\qr\qr\env\scripts\python.py\Lib\site-packages\django\core\handlers\exception.py", line 55, in inner
    response = get_response(request)
               ^^^^^^^^^^^^^^^^^^^^^
  File "D:\projects\qr\qr\env\scripts\python.py\Lib\site-packages\django\utils\deprecation.py", line 128, in __call__
    response = self.process_request(request)
               ^^^^^^^^^^^^^^^^^^^^^^^^^^^^^
  File "D:\projects\qr\qr\env\scripts\python.py\Lib\site-packages\django\middleware\common.py", line 48, in process_request
    host = request.get_host()
           ^^^^^^^^^^^^^^^^^^
  File "D:\projects\qr\qr\env\scripts\python.py\Lib\site-packages\django\http\request.py", line 151, in get_host
    raise DisallowedHost(msg)
django.core.exceptions.DisallowedHost: Invalid HTTP_HOST header: '127.0.0.1:8000'. You may need to add '127.0.0.1' to ALLOWED_HOSTS.
ERROR 2025-03-18 12:07:32,816 D:\projects\qr\qr\env\scripts\python.py\Lib\site-packages\django\core\handlers\exception.py:124 Invalid HTTP_HOST header: '127.0.0.1:8000'. You may need to add '127.0.0.1' to ALLOWED_HOSTS.
Traceback (most recent call last):
  File "D:\projects\qr\qr\env\scripts\python.py\Lib\site-packages\django\core\handlers\exception.py", line 55, in inner
    response = get_response(request)
               ^^^^^^^^^^^^^^^^^^^^^
  File "D:\projects\qr\qr\env\scripts\python.py\Lib\site-packages\django\utils\deprecation.py", line 128, in __call__
    response = self.process_request(request)
               ^^^^^^^^^^^^^^^^^^^^^^^^^^^^^
  File "D:\projects\qr\qr\env\scripts\python.py\Lib\site-packages\django\middleware\common.py", line 48, in process_request
    host = request.get_host()
           ^^^^^^^^^^^^^^^^^^
  File "D:\projects\qr\qr\env\scripts\python.py\Lib\site-packages\django\http\request.py", line 151, in get_host
    raise DisallowedHost(msg)
django.core.exceptions.DisallowedHost: Invalid HTTP_HOST header: '127.0.0.1:8000'. You may need to add '127.0.0.1' to ALLOWED_HOSTS.
ERROR 2025-03-18 12:07:32,942 D:\projects\qr\qr\env\scripts\python.py\Lib\site-packages\django\core\handlers\exception.py:124 Invalid HTTP_HOST header: '127.0.0.1:8000'. You may need to add '127.0.0.1' to ALLOWED_HOSTS.
Traceback (most recent call last):
  File "D:\projects\qr\qr\env\scripts\python.py\Lib\site-packages\django\core\handlers\exception.py", line 55, in inner
    response = get_response(request)
               ^^^^^^^^^^^^^^^^^^^^^
  File "D:\projects\qr\qr\env\scripts\python.py\Lib\site-packages\django\utils\deprecation.py", line 128, in __call__
    response = self.process_request(request)
               ^^^^^^^^^^^^^^^^^^^^^^^^^^^^^
  File "D:\projects\qr\qr\env\scripts\python.py\Lib\site-packages\django\middleware\common.py", line 48, in process_request
    host = request.get_host()
           ^^^^^^^^^^^^^^^^^^
  File "D:\projects\qr\qr\env\scripts\python.py\Lib\site-packages\django\http\request.py", line 151, in get_host
    raise DisallowedHost(msg)
django.core.exceptions.DisallowedHost: Invalid HTTP_HOST header: '127.0.0.1:8000'. You may need to add '127.0.0.1' to ALLOWED_HOSTS.
ERROR 2025-03-18 12:07:33,068 D:\projects\qr\qr\env\scripts\python.py\Lib\site-packages\django\core\handlers\exception.py:124 Invalid HTTP_HOST header: '127.0.0.1:8000'. You may need to add '127.0.0.1' to ALLOWED_HOSTS.
Traceback (most recent call last):
  File "D:\projects\qr\qr\env\scripts\python.py\Lib\site-packages\django\core\handlers\exception.py", line 55, in inner
    response = get_response(request)
               ^^^^^^^^^^^^^^^^^^^^^
  File "D:\projects\qr\qr\env\scripts\python.py\Lib\site-packages\django\utils\deprecation.py", line 128, in __call__
    response = self.process_request(request)
               ^^^^^^^^^^^^^^^^^^^^^^^^^^^^^
  File "D:\projects\qr\qr\env\scripts\python.py\Lib\site-packages\django\middleware\common.py", line 48, in process_request
    host = request.get_host()
           ^^^^^^^^^^^^^^^^^^
  File "D:\projects\qr\qr\env\scripts\python.py\Lib\site-packages\django\http\request.py", line 151, in get_host
    raise DisallowedHost(msg)
django.core.exceptions.DisallowedHost: Invalid HTTP_HOST header: '127.0.0.1:8000'. You may need to add '127.0.0.1' to ALLOWED_HOSTS.
ERROR 2025-03-18 12:07:33,190 D:\projects\qr\qr\env\scripts\python.py\Lib\site-packages\django\core\handlers\exception.py:124 Invalid HTTP_HOST header: '127.0.0.1:8000'. You may need to add '127.0.0.1' to ALLOWED_HOSTS.
Traceback (most recent call last):
  File "D:\projects\qr\qr\env\scripts\python.py\Lib\site-packages\django\core\handlers\exception.py", line 55, in inner
    response = get_response(request)
               ^^^^^^^^^^^^^^^^^^^^^
  File "D:\projects\qr\qr\env\scripts\python.py\Lib\site-packages\django\utils\deprecation.py", line 128, in __call__
    response = self.process_request(request)
               ^^^^^^^^^^^^^^^^^^^^^^^^^^^^^
  File "D:\projects\qr\qr\env\scripts\python.py\Lib\site-packages\django\middleware\common.py", line 48, in process_request
    host = request.get_host()
           ^^^^^^^^^^^^^^^^^^
  File "D:\projects\qr\qr\env\scripts\python.py\Lib\site-packages\django\http\request.py", line 151, in get_host
    raise DisallowedHost(msg)
django.core.exceptions.DisallowedHost: Invalid HTTP_HOST header: '127.0.0.1:8000'. You may need to add '127.0.0.1' to ALLOWED_HOSTS.
ERROR 2025-03-18 12:07:33,303 D:\projects\qr\qr\env\scripts\python.py\Lib\site-packages\django\core\handlers\exception.py:124 Invalid HTTP_HOST header: '127.0.0.1:8000'. You may need to add '127.0.0.1' to ALLOWED_HOSTS.
Traceback (most recent call last):
  File "D:\projects\qr\qr\env\scripts\python.py\Lib\site-packages\django\core\handlers\exception.py", line 55, in inner
    response = get_response(request)
               ^^^^^^^^^^^^^^^^^^^^^
  File "D:\projects\qr\qr\env\scripts\python.py\Lib\site-packages\django\utils\deprecation.py", line 128, in __call__
    response = self.process_request(request)
               ^^^^^^^^^^^^^^^^^^^^^^^^^^^^^
  File "D:\projects\qr\qr\env\scripts\python.py\Lib\site-packages\django\middleware\common.py", line 48, in process_request
    host = request.get_host()
           ^^^^^^^^^^^^^^^^^^
  File "D:\projects\qr\qr\env\scripts\python.py\Lib\site-packages\django\http\request.py", line 151, in get_host
    raise DisallowedHost(msg)
django.core.exceptions.DisallowedHost: Invalid HTTP_HOST header: '127.0.0.1:8000'. You may need to add '127.0.0.1' to ALLOWED_HOSTS.
ERROR 2025-03-18 12:07:33,415 D:\projects\qr\qr\env\scripts\python.py\Lib\site-packages\django\core\handlers\exception.py:124 Invalid HTTP_HOST header: '127.0.0.1:8000'. You may need to add '127.0.0.1' to ALLOWED_HOSTS.
Traceback (most recent call last):
  File "D:\projects\qr\qr\env\scripts\python.py\Lib\site-packages\django\core\handlers\exception.py", line 55, in inner
    response = get_response(request)
               ^^^^^^^^^^^^^^^^^^^^^
  File "D:\projects\qr\qr\env\scripts\python.py\Lib\site-packages\django\utils\deprecation.py", line 128, in __call__
    response = self.process_request(request)
               ^^^^^^^^^^^^^^^^^^^^^^^^^^^^^
  File "D:\projects\qr\qr\env\scripts\python.py\Lib\site-packages\django\middleware\common.py", line 48, in process_request
    host = request.get_host()
           ^^^^^^^^^^^^^^^^^^
  File "D:\projects\qr\qr\env\scripts\python.py\Lib\site-packages\django\http\request.py", line 151, in get_host
    raise DisallowedHost(msg)
django.core.exceptions.DisallowedHost: Invalid HTTP_HOST header: '127.0.0.1:8000'. You may need to add '127.0.0.1' to ALLOWED_HOSTS.
ERROR 2025-03-18 12:07:33,543 D:\projects\qr\qr\env\scripts\python.py\Lib\site-packages\django\core\handlers\exception.py:124 Invalid HTTP_HOST header: '127.0.0.1:8000'. You may need to add '127.0.0.1' to ALLOWED_HOSTS.
Traceback (most recent call last):
  File "D:\projects\qr\qr\env\scripts\python.py\Lib\site-packages\django\core\handlers\exception.py", line 55, in inner
    response = get_response(request)
               ^^^^^^^^^^^^^^^^^^^^^
  File "D:\projects\qr\qr\env\scripts\python.py\Lib\site-packages\django\utils\deprecation.py", line 128, in __call__
    response = self.process_request(request)
               ^^^^^^^^^^^^^^^^^^^^^^^^^^^^^
  File "D:\projects\qr\qr\env\scripts\python.py\Lib\site-packages\django\middleware\common.py", line 48, in process_request
    host = request.get_host()
           ^^^^^^^^^^^^^^^^^^
  File "D:\projects\qr\qr\env\scripts\python.py\Lib\site-packages\django\http\request.py", line 151, in get_host
    raise DisallowedHost(msg)
django.core.exceptions.DisallowedHost: Invalid HTTP_HOST header: '127.0.0.1:8000'. You may need to add '127.0.0.1' to ALLOWED_HOSTS.
ERROR 2025-03-18 12:07:33,677 D:\projects\qr\qr\env\scripts\python.py\Lib\site-packages\django\core\handlers\exception.py:124 Invalid HTTP_HOST header: '127.0.0.1:8000'. You may need to add '127.0.0.1' to ALLOWED_HOSTS.
Traceback (most recent call last):
  File "D:\projects\qr\qr\env\scripts\python.py\Lib\site-packages\django\core\handlers\exception.py", line 55, in inner
    response = get_response(request)
               ^^^^^^^^^^^^^^^^^^^^^
  File "D:\projects\qr\qr\env\scripts\python.py\Lib\site-packages\django\utils\deprecation.py", line 128, in __call__
    response = self.process_request(request)
               ^^^^^^^^^^^^^^^^^^^^^^^^^^^^^
  File "D:\projects\qr\qr\env\scripts\python.py\Lib\site-packages\django\middleware\common.py", line 48, in process_request
    host = request.get_host()
           ^^^^^^^^^^^^^^^^^^
  File "D:\projects\qr\qr\env\scripts\python.py\Lib\site-packages\django\http\request.py", line 151, in get_host
    raise DisallowedHost(msg)
django.core.exceptions.DisallowedHost: Invalid HTTP_HOST header: '127.0.0.1:8000'. You may need to add '127.0.0.1' to ALLOWED_HOSTS.
ERROR 2025-03-18 12:07:33,796 D:\projects\qr\qr\env\scripts\python.py\Lib\site-packages\django\core\handlers\exception.py:124 Invalid HTTP_HOST header: '127.0.0.1:8000'. You may need to add '127.0.0.1' to ALLOWED_HOSTS.
Traceback (most recent call last):
  File "D:\projects\qr\qr\env\scripts\python.py\Lib\site-packages\django\core\handlers\exception.py", line 55, in inner
    response = get_response(request)
               ^^^^^^^^^^^^^^^^^^^^^
  File "D:\projects\qr\qr\env\scripts\python.py\Lib\site-packages\django\utils\deprecation.py", line 128, in __call__
    response = self.process_request(request)
               ^^^^^^^^^^^^^^^^^^^^^^^^^^^^^
  File "D:\projects\qr\qr\env\scripts\python.py\Lib\site-packages\django\middleware\common.py", line 48, in process_request
    host = request.get_host()
           ^^^^^^^^^^^^^^^^^^
  File "D:\projects\qr\qr\env\scripts\python.py\Lib\site-packages\django\http\request.py", line 151, in get_host
    raise DisallowedHost(msg)
django.core.exceptions.DisallowedHost: Invalid HTTP_HOST header: '127.0.0.1:8000'. You may need to add '127.0.0.1' to ALLOWED_HOSTS.
ERROR 2025-03-18 12:07:33,921 D:\projects\qr\qr\env\scripts\python.py\Lib\site-packages\django\core\handlers\exception.py:124 Invalid HTTP_HOST header: '127.0.0.1:8000'. You may need to add '127.0.0.1' to ALLOWED_HOSTS.
Traceback (most recent call last):
  File "D:\projects\qr\qr\env\scripts\python.py\Lib\site-packages\django\core\handlers\exception.py", line 55, in inner
    response = get_response(request)
               ^^^^^^^^^^^^^^^^^^^^^
  File "D:\projects\qr\qr\env\scripts\python.py\Lib\site-packages\django\utils\deprecation.py", line 128, in __call__
    response = self.process_request(request)
               ^^^^^^^^^^^^^^^^^^^^^^^^^^^^^
  File "D:\projects\qr\qr\env\scripts\python.py\Lib\site-packages\django\middleware\common.py", line 48, in process_request
    host = request.get_host()
           ^^^^^^^^^^^^^^^^^^
  File "D:\projects\qr\qr\env\scripts\python.py\Lib\site-packages\django\http\request.py", line 151, in get_host
    raise DisallowedHost(msg)
django.core.exceptions.DisallowedHost: Invalid HTTP_HOST header: '127.0.0.1:8000'. You may need to add '127.0.0.1' to ALLOWED_HOSTS.
ERROR 2025-03-18 12:07:34,036 D:\projects\qr\qr\env\scripts\python.py\Lib\site-packages\django\core\handlers\exception.py:124 Invalid HTTP_HOST header: '127.0.0.1:8000'. You may need to add '127.0.0.1' to ALLOWED_HOSTS.
Traceback (most recent call last):
  File "D:\projects\qr\qr\env\scripts\python.py\Lib\site-packages\django\core\handlers\exception.py", line 55, in inner
    response = get_response(request)
               ^^^^^^^^^^^^^^^^^^^^^
  File "D:\projects\qr\qr\env\scripts\python.py\Lib\site-packages\django\utils\deprecation.py", line 128, in __call__
    response = self.process_request(request)
               ^^^^^^^^^^^^^^^^^^^^^^^^^^^^^
  File "D:\projects\qr\qr\env\scripts\python.py\Lib\site-packages\django\middleware\common.py", line 48, in process_request
    host = request.get_host()
           ^^^^^^^^^^^^^^^^^^
  File "D:\projects\qr\qr\env\scripts\python.py\Lib\site-packages\django\http\request.py", line 151, in get_host
    raise DisallowedHost(msg)
django.core.exceptions.DisallowedHost: Invalid HTTP_HOST header: '127.0.0.1:8000'. You may need to add '127.0.0.1' to ALLOWED_HOSTS.
ERROR 2025-03-18 12:07:34,163 D:\projects\qr\qr\env\scripts\python.py\Lib\site-packages\django\core\handlers\exception.py:124 Invalid HTTP_HOST header: '127.0.0.1:8000'. You may need to add '127.0.0.1' to ALLOWED_HOSTS.
Traceback (most recent call last):
  File "D:\projects\qr\qr\env\scripts\python.py\Lib\site-packages\django\core\handlers\exception.py", line 55, in inner
    response = get_response(request)
               ^^^^^^^^^^^^^^^^^^^^^
  File "D:\projects\qr\qr\env\scripts\python.py\Lib\site-packages\django\utils\deprecation.py", line 128, in __call__
    response = self.process_request(request)
               ^^^^^^^^^^^^^^^^^^^^^^^^^^^^^
  File "D:\projects\qr\qr\env\scripts\python.py\Lib\site-packages\django\middleware\common.py", line 48, in process_request
    host = request.get_host()
           ^^^^^^^^^^^^^^^^^^
  File "D:\projects\qr\qr\env\scripts\python.py\Lib\site-packages\django\http\request.py", line 151, in get_host
    raise DisallowedHost(msg)
django.core.exceptions.DisallowedHost: Invalid HTTP_HOST header: '127.0.0.1:8000'. You may need to add '127.0.0.1' to ALLOWED_HOSTS.
ERROR 2025-03-18 12:07:34,292 D:\projects\qr\qr\env\scripts\python.py\Lib\site-packages\django\core\handlers\exception.py:124 Invalid HTTP_HOST header: '127.0.0.1:8000'. You may need to add '127.0.0.1' to ALLOWED_HOSTS.
Traceback (most recent call last):
  File "D:\projects\qr\qr\env\scripts\python.py\Lib\site-packages\django\core\handlers\exception.py", line 55, in inner
    response = get_response(request)
               ^^^^^^^^^^^^^^^^^^^^^
  File "D:\projects\qr\qr\env\scripts\python.py\Lib\site-packages\django\utils\deprecation.py", line 128, in __call__
    response = self.process_request(request)
               ^^^^^^^^^^^^^^^^^^^^^^^^^^^^^
  File "D:\projects\qr\qr\env\scripts\python.py\Lib\site-packages\django\middleware\common.py", line 48, in process_request
    host = request.get_host()
           ^^^^^^^^^^^^^^^^^^
  File "D:\projects\qr\qr\env\scripts\python.py\Lib\site-packages\django\http\request.py", line 151, in get_host
    raise DisallowedHost(msg)
django.core.exceptions.DisallowedHost: Invalid HTTP_HOST header: '127.0.0.1:8000'. You may need to add '127.0.0.1' to ALLOWED_HOSTS.
ERROR 2025-03-18 12:07:34,626 D:\projects\qr\qr\env\scripts\python.py\Lib\site-packages\django\core\handlers\exception.py:124 Invalid HTTP_HOST header: '127.0.0.1:8000'. You may need to add '127.0.0.1' to ALLOWED_HOSTS.
Traceback (most recent call last):
  File "D:\projects\qr\qr\env\scripts\python.py\Lib\site-packages\django\core\handlers\exception.py", line 55, in inner
    response = get_response(request)
               ^^^^^^^^^^^^^^^^^^^^^
  File "D:\projects\qr\qr\env\scripts\python.py\Lib\site-packages\django\utils\deprecation.py", line 128, in __call__
    response = self.process_request(request)
               ^^^^^^^^^^^^^^^^^^^^^^^^^^^^^
  File "D:\projects\qr\qr\env\scripts\python.py\Lib\site-packages\django\middleware\common.py", line 48, in process_request
    host = request.get_host()
           ^^^^^^^^^^^^^^^^^^
  File "D:\projects\qr\qr\env\scripts\python.py\Lib\site-packages\django\http\request.py", line 151, in get_host
    raise DisallowedHost(msg)
django.core.exceptions.DisallowedHost: Invalid HTTP_HOST header: '127.0.0.1:8000'. You may need to add '127.0.0.1' to ALLOWED_HOSTS.
ERROR 2025-03-18 12:07:34,954 D:\projects\qr\qr\env\scripts\python.py\Lib\site-packages\django\core\handlers\exception.py:124 Invalid HTTP_HOST header: '127.0.0.1:8000'. You may need to add '127.0.0.1' to ALLOWED_HOSTS.
Traceback (most recent call last):
  File "D:\projects\qr\qr\env\scripts\python.py\Lib\site-packages\django\core\handlers\exception.py", line 55, in inner
    response = get_response(request)
               ^^^^^^^^^^^^^^^^^^^^^
  File "D:\projects\qr\qr\env\scripts\python.py\Lib\site-packages\django\utils\deprecation.py", line 128, in __call__
    response = self.process_request(request)
               ^^^^^^^^^^^^^^^^^^^^^^^^^^^^^
  File "D:\projects\qr\qr\env\scripts\python.py\Lib\site-packages\django\middleware\common.py", line 48, in process_request
    host = request.get_host()
           ^^^^^^^^^^^^^^^^^^
  File "D:\projects\qr\qr\env\scripts\python.py\Lib\site-packages\django\http\request.py", line 151, in get_host
    raise DisallowedHost(msg)
django.core.exceptions.DisallowedHost: Invalid HTTP_HOST header: '127.0.0.1:8000'. You may need to add '127.0.0.1' to ALLOWED_HOSTS.
ERROR 2025-03-18 12:07:35,277 D:\projects\qr\qr\env\scripts\python.py\Lib\site-packages\django\core\handlers\exception.py:124 Invalid HTTP_HOST header: '127.0.0.1:8000'. You may need to add '127.0.0.1' to ALLOWED_HOSTS.
Traceback (most recent call last):
  File "D:\projects\qr\qr\env\scripts\python.py\Lib\site-packages\django\core\handlers\exception.py", line 55, in inner
    response = get_response(request)
               ^^^^^^^^^^^^^^^^^^^^^
  File "D:\projects\qr\qr\env\scripts\python.py\Lib\site-packages\django\utils\deprecation.py", line 128, in __call__
    response = self.process_request(request)
               ^^^^^^^^^^^^^^^^^^^^^^^^^^^^^
  File "D:\projects\qr\qr\env\scripts\python.py\Lib\site-packages\django\middleware\common.py", line 48, in process_request
    host = request.get_host()
           ^^^^^^^^^^^^^^^^^^
  File "D:\projects\qr\qr\env\scripts\python.py\Lib\site-packages\django\http\request.py", line 151, in get_host
    raise DisallowedHost(msg)
django.core.exceptions.DisallowedHost: Invalid HTTP_HOST header: '127.0.0.1:8000'. You may need to add '127.0.0.1' to ALLOWED_HOSTS.
ERROR 2025-03-18 12:07:35,604 D:\projects\qr\qr\env\scripts\python.py\Lib\site-packages\django\core\handlers\exception.py:124 Invalid HTTP_HOST header: '127.0.0.1:8000'. You may need to add '127.0.0.1' to ALLOWED_HOSTS.
Traceback (most recent call last):
  File "D:\projects\qr\qr\env\scripts\python.py\Lib\site-packages\django\core\handlers\exception.py", line 55, in inner
    response = get_response(request)
               ^^^^^^^^^^^^^^^^^^^^^
  File "D:\projects\qr\qr\env\scripts\python.py\Lib\site-packages\django\utils\deprecation.py", line 128, in __call__
    response = self.process_request(request)
               ^^^^^^^^^^^^^^^^^^^^^^^^^^^^^
  File "D:\projects\qr\qr\env\scripts\python.py\Lib\site-packages\django\middleware\common.py", line 48, in process_request
    host = request.get_host()
           ^^^^^^^^^^^^^^^^^^
  File "D:\projects\qr\qr\env\scripts\python.py\Lib\site-packages\django\http\request.py", line 151, in get_host
    raise DisallowedHost(msg)
django.core.exceptions.DisallowedHost: Invalid HTTP_HOST header: '127.0.0.1:8000'. You may need to add '127.0.0.1' to ALLOWED_HOSTS.
ERROR 2025-03-18 12:07:35,930 D:\projects\qr\qr\env\scripts\python.py\Lib\site-packages\django\core\handlers\exception.py:124 Invalid HTTP_HOST header: '127.0.0.1:8000'. You may need to add '127.0.0.1' to ALLOWED_HOSTS.
Traceback (most recent call last):
  File "D:\projects\qr\qr\env\scripts\python.py\Lib\site-packages\django\core\handlers\exception.py", line 55, in inner
    response = get_response(request)
               ^^^^^^^^^^^^^^^^^^^^^
  File "D:\projects\qr\qr\env\scripts\python.py\Lib\site-packages\django\utils\deprecation.py", line 128, in __call__
    response = self.process_request(request)
               ^^^^^^^^^^^^^^^^^^^^^^^^^^^^^
  File "D:\projects\qr\qr\env\scripts\python.py\Lib\site-packages\django\middleware\common.py", line 48, in process_request
    host = request.get_host()
           ^^^^^^^^^^^^^^^^^^
  File "D:\projects\qr\qr\env\scripts\python.py\Lib\site-packages\django\http\request.py", line 151, in get_host
    raise DisallowedHost(msg)
django.core.exceptions.DisallowedHost: Invalid HTTP_HOST header: '127.0.0.1:8000'. You may need to add '127.0.0.1' to ALLOWED_HOSTS.
ERROR 2025-03-18 12:07:36,249 D:\projects\qr\qr\env\scripts\python.py\Lib\site-packages\django\core\handlers\exception.py:124 Invalid HTTP_HOST header: '127.0.0.1:8000'. You may need to add '127.0.0.1' to ALLOWED_HOSTS.
Traceback (most recent call last):
  File "D:\projects\qr\qr\env\scripts\python.py\Lib\site-packages\django\core\handlers\exception.py", line 55, in inner
    response = get_response(request)
               ^^^^^^^^^^^^^^^^^^^^^
  File "D:\projects\qr\qr\env\scripts\python.py\Lib\site-packages\django\utils\deprecation.py", line 128, in __call__
    response = self.process_request(request)
               ^^^^^^^^^^^^^^^^^^^^^^^^^^^^^
  File "D:\projects\qr\qr\env\scripts\python.py\Lib\site-packages\django\middleware\common.py", line 48, in process_request
    host = request.get_host()
           ^^^^^^^^^^^^^^^^^^
  File "D:\projects\qr\qr\env\scripts\python.py\Lib\site-packages\django\http\request.py", line 151, in get_host
    raise DisallowedHost(msg)
django.core.exceptions.DisallowedHost: Invalid HTTP_HOST header: '127.0.0.1:8000'. You may need to add '127.0.0.1' to ALLOWED_HOSTS.
ERROR 2025-03-18 12:07:36,581 D:\projects\qr\qr\env\scripts\python.py\Lib\site-packages\django\core\handlers\exception.py:124 Invalid HTTP_HOST header: '127.0.0.1:8000'. You may need to add '127.0.0.1' to ALLOWED_HOSTS.
Traceback (most recent call last):
  File "D:\projects\qr\qr\env\scripts\python.py\Lib\site-packages\django\core\handlers\exception.py", line 55, in inner
    response = get_response(request)
               ^^^^^^^^^^^^^^^^^^^^^
  File "D:\projects\qr\qr\env\scripts\python.py\Lib\site-packages\django\utils\deprecation.py", line 128, in __call__
    response = self.process_request(request)
               ^^^^^^^^^^^^^^^^^^^^^^^^^^^^^
  File "D:\projects\qr\qr\env\scripts\python.py\Lib\site-packages\django\middleware\common.py", line 48, in process_request
    host = request.get_host()
           ^^^^^^^^^^^^^^^^^^
  File "D:\projects\qr\qr\env\scripts\python.py\Lib\site-packages\django\http\request.py", line 151, in get_host
    raise DisallowedHost(msg)
django.core.exceptions.DisallowedHost: Invalid HTTP_HOST header: '127.0.0.1:8000'. You may need to add '127.0.0.1' to ALLOWED_HOSTS.
ERROR 2025-03-18 12:07:36,902 D:\projects\qr\qr\env\scripts\python.py\Lib\site-packages\django\core\handlers\exception.py:124 Invalid HTTP_HOST header: '127.0.0.1:8000'. You may need to add '127.0.0.1' to ALLOWED_HOSTS.
Traceback (most recent call last):
  File "D:\projects\qr\qr\env\scripts\python.py\Lib\site-packages\django\core\handlers\exception.py", line 55, in inner
    response = get_response(request)
               ^^^^^^^^^^^^^^^^^^^^^
  File "D:\projects\qr\qr\env\scripts\python.py\Lib\site-packages\django\utils\deprecation.py", line 128, in __call__
    response = self.process_request(request)
               ^^^^^^^^^^^^^^^^^^^^^^^^^^^^^
  File "D:\projects\qr\qr\env\scripts\python.py\Lib\site-packages\django\middleware\common.py", line 48, in process_request
    host = request.get_host()
           ^^^^^^^^^^^^^^^^^^
  File "D:\projects\qr\qr\env\scripts\python.py\Lib\site-packages\django\http\request.py", line 151, in get_host
    raise DisallowedHost(msg)
django.core.exceptions.DisallowedHost: Invalid HTTP_HOST header: '127.0.0.1:8000'. You may need to add '127.0.0.1' to ALLOWED_HOSTS.
ERROR 2025-03-18 12:07:37,220 D:\projects\qr\qr\env\scripts\python.py\Lib\site-packages\django\core\handlers\exception.py:124 Invalid HTTP_HOST header: '127.0.0.1:8000'. You may need to add '127.0.0.1' to ALLOWED_HOSTS.
Traceback (most recent call last):
  File "D:\projects\qr\qr\env\scripts\python.py\Lib\site-packages\django\core\handlers\exception.py", line 55, in inner
    response = get_response(request)
               ^^^^^^^^^^^^^^^^^^^^^
  File "D:\projects\qr\qr\env\scripts\python.py\Lib\site-packages\django\utils\deprecation.py", line 128, in __call__
    response = self.process_request(request)
               ^^^^^^^^^^^^^^^^^^^^^^^^^^^^^
  File "D:\projects\qr\qr\env\scripts\python.py\Lib\site-packages\django\middleware\common.py", line 48, in process_request
    host = request.get_host()
           ^^^^^^^^^^^^^^^^^^
  File "D:\projects\qr\qr\env\scripts\python.py\Lib\site-packages\django\http\request.py", line 151, in get_host
    raise DisallowedHost(msg)
django.core.exceptions.DisallowedHost: Invalid HTTP_HOST header: '127.0.0.1:8000'. You may need to add '127.0.0.1' to ALLOWED_HOSTS.
ERROR 2025-03-18 12:07:37,548 D:\projects\qr\qr\env\scripts\python.py\Lib\site-packages\django\core\handlers\exception.py:124 Invalid HTTP_HOST header: '127.0.0.1:8000'. You may need to add '127.0.0.1' to ALLOWED_HOSTS.
Traceback (most recent call last):
  File "D:\projects\qr\qr\env\scripts\python.py\Lib\site-packages\django\core\handlers\exception.py", line 55, in inner
    response = get_response(request)
               ^^^^^^^^^^^^^^^^^^^^^
  File "D:\projects\qr\qr\env\scripts\python.py\Lib\site-packages\django\utils\deprecation.py", line 128, in __call__
    response = self.process_request(request)
               ^^^^^^^^^^^^^^^^^^^^^^^^^^^^^
  File "D:\projects\qr\qr\env\scripts\python.py\Lib\site-packages\django\middleware\common.py", line 48, in process_request
    host = request.get_host()
           ^^^^^^^^^^^^^^^^^^
  File "D:\projects\qr\qr\env\scripts\python.py\Lib\site-packages\django\http\request.py", line 151, in get_host
    raise DisallowedHost(msg)
django.core.exceptions.DisallowedHost: Invalid HTTP_HOST header: '127.0.0.1:8000'. You may need to add '127.0.0.1' to ALLOWED_HOSTS.
ERROR 2025-03-18 12:07:37,873 D:\projects\qr\qr\env\scripts\python.py\Lib\site-packages\django\core\handlers\exception.py:124 Invalid HTTP_HOST header: '127.0.0.1:8000'. You may need to add '127.0.0.1' to ALLOWED_HOSTS.
Traceback (most recent call last):
  File "D:\projects\qr\qr\env\scripts\python.py\Lib\site-packages\django\core\handlers\exception.py", line 55, in inner
    response = get_response(request)
               ^^^^^^^^^^^^^^^^^^^^^
  File "D:\projects\qr\qr\env\scripts\python.py\Lib\site-packages\django\utils\deprecation.py", line 128, in __call__
    response = self.process_request(request)
               ^^^^^^^^^^^^^^^^^^^^^^^^^^^^^
  File "D:\projects\qr\qr\env\scripts\python.py\Lib\site-packages\django\middleware\common.py", line 48, in process_request
    host = request.get_host()
           ^^^^^^^^^^^^^^^^^^
  File "D:\projects\qr\qr\env\scripts\python.py\Lib\site-packages\django\http\request.py", line 151, in get_host
    raise DisallowedHost(msg)
django.core.exceptions.DisallowedHost: Invalid HTTP_HOST header: '127.0.0.1:8000'. You may need to add '127.0.0.1' to ALLOWED_HOSTS.
ERROR 2025-03-18 12:07:38,202 D:\projects\qr\qr\env\scripts\python.py\Lib\site-packages\django\core\handlers\exception.py:124 Invalid HTTP_HOST header: '127.0.0.1:8000'. You may need to add '127.0.0.1' to ALLOWED_HOSTS.
Traceback (most recent call last):
  File "D:\projects\qr\qr\env\scripts\python.py\Lib\site-packages\django\core\handlers\exception.py", line 55, in inner
    response = get_response(request)
               ^^^^^^^^^^^^^^^^^^^^^
  File "D:\projects\qr\qr\env\scripts\python.py\Lib\site-packages\django\utils\deprecation.py", line 128, in __call__
    response = self.process_request(request)
               ^^^^^^^^^^^^^^^^^^^^^^^^^^^^^
  File "D:\projects\qr\qr\env\scripts\python.py\Lib\site-packages\django\middleware\common.py", line 48, in process_request
    host = request.get_host()
           ^^^^^^^^^^^^^^^^^^
  File "D:\projects\qr\qr\env\scripts\python.py\Lib\site-packages\django\http\request.py", line 151, in get_host
    raise DisallowedHost(msg)
django.core.exceptions.DisallowedHost: Invalid HTTP_HOST header: '127.0.0.1:8000'. You may need to add '127.0.0.1' to ALLOWED_HOSTS.
ERROR 2025-03-18 12:07:38,525 D:\projects\qr\qr\env\scripts\python.py\Lib\site-packages\django\core\handlers\exception.py:124 Invalid HTTP_HOST header: '127.0.0.1:8000'. You may need to add '127.0.0.1' to ALLOWED_HOSTS.
Traceback (most recent call last):
  File "D:\projects\qr\qr\env\scripts\python.py\Lib\site-packages\django\core\handlers\exception.py", line 55, in inner
    response = get_response(request)
               ^^^^^^^^^^^^^^^^^^^^^
  File "D:\projects\qr\qr\env\scripts\python.py\Lib\site-packages\django\utils\deprecation.py", line 128, in __call__
    response = self.process_request(request)
               ^^^^^^^^^^^^^^^^^^^^^^^^^^^^^
  File "D:\projects\qr\qr\env\scripts\python.py\Lib\site-packages\django\middleware\common.py", line 48, in process_request
    host = request.get_host()
           ^^^^^^^^^^^^^^^^^^
  File "D:\projects\qr\qr\env\scripts\python.py\Lib\site-packages\django\http\request.py", line 151, in get_host
    raise DisallowedHost(msg)
django.core.exceptions.DisallowedHost: Invalid HTTP_HOST header: '127.0.0.1:8000'. You may need to add '127.0.0.1' to ALLOWED_HOSTS.
ERROR 2025-03-18 12:07:38,838 D:\projects\qr\qr\env\scripts\python.py\Lib\site-packages\django\core\handlers\exception.py:124 Invalid HTTP_HOST header: '127.0.0.1:8000'. You may need to add '127.0.0.1' to ALLOWED_HOSTS.
Traceback (most recent call last):
  File "D:\projects\qr\qr\env\scripts\python.py\Lib\site-packages\django\core\handlers\exception.py", line 55, in inner
    response = get_response(request)
               ^^^^^^^^^^^^^^^^^^^^^
  File "D:\projects\qr\qr\env\scripts\python.py\Lib\site-packages\django\utils\deprecation.py", line 128, in __call__
    response = self.process_request(request)
               ^^^^^^^^^^^^^^^^^^^^^^^^^^^^^
  File "D:\projects\qr\qr\env\scripts\python.py\Lib\site-packages\django\middleware\common.py", line 48, in process_request
    host = request.get_host()
           ^^^^^^^^^^^^^^^^^^
  File "D:\projects\qr\qr\env\scripts\python.py\Lib\site-packages\django\http\request.py", line 151, in get_host
    raise DisallowedHost(msg)
django.core.exceptions.DisallowedHost: Invalid HTTP_HOST header: '127.0.0.1:8000'. You may need to add '127.0.0.1' to ALLOWED_HOSTS.
ERROR 2025-03-18 12:07:39,166 D:\projects\qr\qr\env\scripts\python.py\Lib\site-packages\django\core\handlers\exception.py:124 Invalid HTTP_HOST header: '127.0.0.1:8000'. You may need to add '127.0.0.1' to ALLOWED_HOSTS.
Traceback (most recent call last):
  File "D:\projects\qr\qr\env\scripts\python.py\Lib\site-packages\django\core\handlers\exception.py", line 55, in inner
    response = get_response(request)
               ^^^^^^^^^^^^^^^^^^^^^
  File "D:\projects\qr\qr\env\scripts\python.py\Lib\site-packages\django\utils\deprecation.py", line 128, in __call__
    response = self.process_request(request)
               ^^^^^^^^^^^^^^^^^^^^^^^^^^^^^
  File "D:\projects\qr\qr\env\scripts\python.py\Lib\site-packages\django\middleware\common.py", line 48, in process_request
    host = request.get_host()
           ^^^^^^^^^^^^^^^^^^
  File "D:\projects\qr\qr\env\scripts\python.py\Lib\site-packages\django\http\request.py", line 151, in get_host
    raise DisallowedHost(msg)
django.core.exceptions.DisallowedHost: Invalid HTTP_HOST header: '127.0.0.1:8000'. You may need to add '127.0.0.1' to ALLOWED_HOSTS.
ERROR 2025-03-18 12:07:39,494 D:\projects\qr\qr\env\scripts\python.py\Lib\site-packages\django\core\handlers\exception.py:124 Invalid HTTP_HOST header: '127.0.0.1:8000'. You may need to add '127.0.0.1' to ALLOWED_HOSTS.
Traceback (most recent call last):
  File "D:\projects\qr\qr\env\scripts\python.py\Lib\site-packages\django\core\handlers\exception.py", line 55, in inner
    response = get_response(request)
               ^^^^^^^^^^^^^^^^^^^^^
  File "D:\projects\qr\qr\env\scripts\python.py\Lib\site-packages\django\utils\deprecation.py", line 128, in __call__
    response = self.process_request(request)
               ^^^^^^^^^^^^^^^^^^^^^^^^^^^^^
  File "D:\projects\qr\qr\env\scripts\python.py\Lib\site-packages\django\middleware\common.py", line 48, in process_request
    host = request.get_host()
           ^^^^^^^^^^^^^^^^^^
  File "D:\projects\qr\qr\env\scripts\python.py\Lib\site-packages\django\http\request.py", line 151, in get_host
    raise DisallowedHost(msg)
django.core.exceptions.DisallowedHost: Invalid HTTP_HOST header: '127.0.0.1:8000'. You may need to add '127.0.0.1' to ALLOWED_HOSTS.
ERROR 2025-03-18 12:07:39,825 D:\projects\qr\qr\env\scripts\python.py\Lib\site-packages\django\core\handlers\exception.py:124 Invalid HTTP_HOST header: '127.0.0.1:8000'. You may need to add '127.0.0.1' to ALLOWED_HOSTS.
Traceback (most recent call last):
  File "D:\projects\qr\qr\env\scripts\python.py\Lib\site-packages\django\core\handlers\exception.py", line 55, in inner
    response = get_response(request)
               ^^^^^^^^^^^^^^^^^^^^^
  File "D:\projects\qr\qr\env\scripts\python.py\Lib\site-packages\django\utils\deprecation.py", line 128, in __call__
    response = self.process_request(request)
               ^^^^^^^^^^^^^^^^^^^^^^^^^^^^^
  File "D:\projects\qr\qr\env\scripts\python.py\Lib\site-packages\django\middleware\common.py", line 48, in process_request
    host = request.get_host()
           ^^^^^^^^^^^^^^^^^^
  File "D:\projects\qr\qr\env\scripts\python.py\Lib\site-packages\django\http\request.py", line 151, in get_host
    raise DisallowedHost(msg)
django.core.exceptions.DisallowedHost: Invalid HTTP_HOST header: '127.0.0.1:8000'. You may need to add '127.0.0.1' to ALLOWED_HOSTS.
ERROR 2025-03-18 12:07:40,146 D:\projects\qr\qr\env\scripts\python.py\Lib\site-packages\django\core\handlers\exception.py:124 Invalid HTTP_HOST header: '127.0.0.1:8000'. You may need to add '127.0.0.1' to ALLOWED_HOSTS.
Traceback (most recent call last):
  File "D:\projects\qr\qr\env\scripts\python.py\Lib\site-packages\django\core\handlers\exception.py", line 55, in inner
    response = get_response(request)
               ^^^^^^^^^^^^^^^^^^^^^
  File "D:\projects\qr\qr\env\scripts\python.py\Lib\site-packages\django\utils\deprecation.py", line 128, in __call__
    response = self.process_request(request)
               ^^^^^^^^^^^^^^^^^^^^^^^^^^^^^
  File "D:\projects\qr\qr\env\scripts\python.py\Lib\site-packages\django\middleware\common.py", line 48, in process_request
    host = request.get_host()
           ^^^^^^^^^^^^^^^^^^
  File "D:\projects\qr\qr\env\scripts\python.py\Lib\site-packages\django\http\request.py", line 151, in get_host
    raise DisallowedHost(msg)
django.core.exceptions.DisallowedHost: Invalid HTTP_HOST header: '127.0.0.1:8000'. You may need to add '127.0.0.1' to ALLOWED_HOSTS.
ERROR 2025-03-18 12:07:40,474 D:\projects\qr\qr\env\scripts\python.py\Lib\site-packages\django\core\handlers\exception.py:124 Invalid HTTP_HOST header: '127.0.0.1:8000'. You may need to add '127.0.0.1' to ALLOWED_HOSTS.
Traceback (most recent call last):
  File "D:\projects\qr\qr\env\scripts\python.py\Lib\site-packages\django\core\handlers\exception.py", line 55, in inner
    response = get_response(request)
               ^^^^^^^^^^^^^^^^^^^^^
  File "D:\projects\qr\qr\env\scripts\python.py\Lib\site-packages\django\utils\deprecation.py", line 128, in __call__
    response = self.process_request(request)
               ^^^^^^^^^^^^^^^^^^^^^^^^^^^^^
  File "D:\projects\qr\qr\env\scripts\python.py\Lib\site-packages\django\middleware\common.py", line 48, in process_request
    host = request.get_host()
           ^^^^^^^^^^^^^^^^^^
  File "D:\projects\qr\qr\env\scripts\python.py\Lib\site-packages\django\http\request.py", line 151, in get_host
    raise DisallowedHost(msg)
django.core.exceptions.DisallowedHost: Invalid HTTP_HOST header: '127.0.0.1:8000'. You may need to add '127.0.0.1' to ALLOWED_HOSTS.
ERROR 2025-03-18 12:07:40,805 D:\projects\qr\qr\env\scripts\python.py\Lib\site-packages\django\core\handlers\exception.py:124 Invalid HTTP_HOST header: '127.0.0.1:8000'. You may need to add '127.0.0.1' to ALLOWED_HOSTS.
Traceback (most recent call last):
  File "D:\projects\qr\qr\env\scripts\python.py\Lib\site-packages\django\core\handlers\exception.py", line 55, in inner
    response = get_response(request)
               ^^^^^^^^^^^^^^^^^^^^^
  File "D:\projects\qr\qr\env\scripts\python.py\Lib\site-packages\django\utils\deprecation.py", line 128, in __call__
    response = self.process_request(request)
               ^^^^^^^^^^^^^^^^^^^^^^^^^^^^^
  File "D:\projects\qr\qr\env\scripts\python.py\Lib\site-packages\django\middleware\common.py", line 48, in process_request
    host = request.get_host()
           ^^^^^^^^^^^^^^^^^^
  File "D:\projects\qr\qr\env\scripts\python.py\Lib\site-packages\django\http\request.py", line 151, in get_host
    raise DisallowedHost(msg)
django.core.exceptions.DisallowedHost: Invalid HTTP_HOST header: '127.0.0.1:8000'. You may need to add '127.0.0.1' to ALLOWED_HOSTS.
ERROR 2025-03-18 12:07:41,839 D:\projects\qr\qr\env\scripts\python.py\Lib\site-packages\django\core\handlers\exception.py:124 Invalid HTTP_HOST header: '127.0.0.1:8000'. You may need to add '127.0.0.1' to ALLOWED_HOSTS.
Traceback (most recent call last):
  File "D:\projects\qr\qr\env\scripts\python.py\Lib\site-packages\django\core\handlers\exception.py", line 55, in inner
    response = get_response(request)
               ^^^^^^^^^^^^^^^^^^^^^
  File "D:\projects\qr\qr\env\scripts\python.py\Lib\site-packages\django\utils\deprecation.py", line 128, in __call__
    response = self.process_request(request)
               ^^^^^^^^^^^^^^^^^^^^^^^^^^^^^
  File "D:\projects\qr\qr\env\scripts\python.py\Lib\site-packages\django\middleware\common.py", line 48, in process_request
    host = request.get_host()
           ^^^^^^^^^^^^^^^^^^
  File "D:\projects\qr\qr\env\scripts\python.py\Lib\site-packages\django\http\request.py", line 151, in get_host
    raise DisallowedHost(msg)
django.core.exceptions.DisallowedHost: Invalid HTTP_HOST header: '127.0.0.1:8000'. You may need to add '127.0.0.1' to ALLOWED_HOSTS.
ERROR 2025-03-18 12:07:42,857 D:\projects\qr\qr\env\scripts\python.py\Lib\site-packages\django\core\handlers\exception.py:124 Invalid HTTP_HOST header: '127.0.0.1:8000'. You may need to add '127.0.0.1' to ALLOWED_HOSTS.
Traceback (most recent call last):
  File "D:\projects\qr\qr\env\scripts\python.py\Lib\site-packages\django\core\handlers\exception.py", line 55, in inner
    response = get_response(request)
               ^^^^^^^^^^^^^^^^^^^^^
  File "D:\projects\qr\qr\env\scripts\python.py\Lib\site-packages\django\utils\deprecation.py", line 128, in __call__
    response = self.process_request(request)
               ^^^^^^^^^^^^^^^^^^^^^^^^^^^^^
  File "D:\projects\qr\qr\env\scripts\python.py\Lib\site-packages\django\middleware\common.py", line 48, in process_request
    host = request.get_host()
           ^^^^^^^^^^^^^^^^^^
  File "D:\projects\qr\qr\env\scripts\python.py\Lib\site-packages\django\http\request.py", line 151, in get_host
    raise DisallowedHost(msg)
django.core.exceptions.DisallowedHost: Invalid HTTP_HOST header: '127.0.0.1:8000'. You may need to add '127.0.0.1' to ALLOWED_HOSTS.
ERROR 2025-03-18 12:07:43,889 D:\projects\qr\qr\env\scripts\python.py\Lib\site-packages\django\core\handlers\exception.py:124 Invalid HTTP_HOST header: '127.0.0.1:8000'. You may need to add '127.0.0.1' to ALLOWED_HOSTS.
Traceback (most recent call last):
  File "D:\projects\qr\qr\env\scripts\python.py\Lib\site-packages\django\core\handlers\exception.py", line 55, in inner
    response = get_response(request)
               ^^^^^^^^^^^^^^^^^^^^^
  File "D:\projects\qr\qr\env\scripts\python.py\Lib\site-packages\django\utils\deprecation.py", line 128, in __call__
    response = self.process_request(request)
               ^^^^^^^^^^^^^^^^^^^^^^^^^^^^^
  File "D:\projects\qr\qr\env\scripts\python.py\Lib\site-packages\django\middleware\common.py", line 48, in process_request
    host = request.get_host()
           ^^^^^^^^^^^^^^^^^^
  File "D:\projects\qr\qr\env\scripts\python.py\Lib\site-packages\django\http\request.py", line 151, in get_host
    raise DisallowedHost(msg)
django.core.exceptions.DisallowedHost: Invalid HTTP_HOST header: '127.0.0.1:8000'. You may need to add '127.0.0.1' to ALLOWED_HOSTS.
ERROR 2025-03-18 12:07:44,926 D:\projects\qr\qr\env\scripts\python.py\Lib\site-packages\django\core\handlers\exception.py:124 Invalid HTTP_HOST header: '127.0.0.1:8000'. You may need to add '127.0.0.1' to ALLOWED_HOSTS.
Traceback (most recent call last):
  File "D:\projects\qr\qr\env\scripts\python.py\Lib\site-packages\django\core\handlers\exception.py", line 55, in inner
    response = get_response(request)
               ^^^^^^^^^^^^^^^^^^^^^
  File "D:\projects\qr\qr\env\scripts\python.py\Lib\site-packages\django\utils\deprecation.py", line 128, in __call__
    response = self.process_request(request)
               ^^^^^^^^^^^^^^^^^^^^^^^^^^^^^
  File "D:\projects\qr\qr\env\scripts\python.py\Lib\site-packages\django\middleware\common.py", line 48, in process_request
    host = request.get_host()
           ^^^^^^^^^^^^^^^^^^
  File "D:\projects\qr\qr\env\scripts\python.py\Lib\site-packages\django\http\request.py", line 151, in get_host
    raise DisallowedHost(msg)
django.core.exceptions.DisallowedHost: Invalid HTTP_HOST header: '127.0.0.1:8000'. You may need to add '127.0.0.1' to ALLOWED_HOSTS.
ERROR 2025-03-18 12:07:45,952 D:\projects\qr\qr\env\scripts\python.py\Lib\site-packages\django\core\handlers\exception.py:124 Invalid HTTP_HOST header: '127.0.0.1:8000'. You may need to add '127.0.0.1' to ALLOWED_HOSTS.
Traceback (most recent call last):
  File "D:\projects\qr\qr\env\scripts\python.py\Lib\site-packages\django\core\handlers\exception.py", line 55, in inner
    response = get_response(request)
               ^^^^^^^^^^^^^^^^^^^^^
  File "D:\projects\qr\qr\env\scripts\python.py\Lib\site-packages\django\utils\deprecation.py", line 128, in __call__
    response = self.process_request(request)
               ^^^^^^^^^^^^^^^^^^^^^^^^^^^^^
  File "D:\projects\qr\qr\env\scripts\python.py\Lib\site-packages\django\middleware\common.py", line 48, in process_request
    host = request.get_host()
           ^^^^^^^^^^^^^^^^^^
  File "D:\projects\qr\qr\env\scripts\python.py\Lib\site-packages\django\http\request.py", line 151, in get_host
    raise DisallowedHost(msg)
django.core.exceptions.DisallowedHost: Invalid HTTP_HOST header: '127.0.0.1:8000'. You may need to add '127.0.0.1' to ALLOWED_HOSTS.
ERROR 2025-03-18 12:07:46,977 D:\projects\qr\qr\env\scripts\python.py\Lib\site-packages\django\core\handlers\exception.py:124 Invalid HTTP_HOST header: '127.0.0.1:8000'. You may need to add '127.0.0.1' to ALLOWED_HOSTS.
Traceback (most recent call last):
  File "D:\projects\qr\qr\env\scripts\python.py\Lib\site-packages\django\core\handlers\exception.py", line 55, in inner
    response = get_response(request)
               ^^^^^^^^^^^^^^^^^^^^^
  File "D:\projects\qr\qr\env\scripts\python.py\Lib\site-packages\django\utils\deprecation.py", line 128, in __call__
    response = self.process_request(request)
               ^^^^^^^^^^^^^^^^^^^^^^^^^^^^^
  File "D:\projects\qr\qr\env\scripts\python.py\Lib\site-packages\django\middleware\common.py", line 48, in process_request
    host = request.get_host()
           ^^^^^^^^^^^^^^^^^^
  File "D:\projects\qr\qr\env\scripts\python.py\Lib\site-packages\django\http\request.py", line 151, in get_host
    raise DisallowedHost(msg)
django.core.exceptions.DisallowedHost: Invalid HTTP_HOST header: '127.0.0.1:8000'. You may need to add '127.0.0.1' to ALLOWED_HOSTS.
ERROR 2025-03-18 12:07:48,001 D:\projects\qr\qr\env\scripts\python.py\Lib\site-packages\django\core\handlers\exception.py:124 Invalid HTTP_HOST header: '127.0.0.1:8000'. You may need to add '127.0.0.1' to ALLOWED_HOSTS.
Traceback (most recent call last):
  File "D:\projects\qr\qr\env\scripts\python.py\Lib\site-packages\django\core\handlers\exception.py", line 55, in inner
    response = get_response(request)
               ^^^^^^^^^^^^^^^^^^^^^
  File "D:\projects\qr\qr\env\scripts\python.py\Lib\site-packages\django\utils\deprecation.py", line 128, in __call__
    response = self.process_request(request)
               ^^^^^^^^^^^^^^^^^^^^^^^^^^^^^
  File "D:\projects\qr\qr\env\scripts\python.py\Lib\site-packages\django\middleware\common.py", line 48, in process_request
    host = request.get_host()
           ^^^^^^^^^^^^^^^^^^
  File "D:\projects\qr\qr\env\scripts\python.py\Lib\site-packages\django\http\request.py", line 151, in get_host
    raise DisallowedHost(msg)
django.core.exceptions.DisallowedHost: Invalid HTTP_HOST header: '127.0.0.1:8000'. You may need to add '127.0.0.1' to ALLOWED_HOSTS.
ERROR 2025-03-18 12:07:49,025 D:\projects\qr\qr\env\scripts\python.py\Lib\site-packages\django\core\handlers\exception.py:124 Invalid HTTP_HOST header: '127.0.0.1:8000'. You may need to add '127.0.0.1' to ALLOWED_HOSTS.
Traceback (most recent call last):
  File "D:\projects\qr\qr\env\scripts\python.py\Lib\site-packages\django\core\handlers\exception.py", line 55, in inner
    response = get_response(request)
               ^^^^^^^^^^^^^^^^^^^^^
  File "D:\projects\qr\qr\env\scripts\python.py\Lib\site-packages\django\utils\deprecation.py", line 128, in __call__
    response = self.process_request(request)
               ^^^^^^^^^^^^^^^^^^^^^^^^^^^^^
  File "D:\projects\qr\qr\env\scripts\python.py\Lib\site-packages\django\middleware\common.py", line 48, in process_request
    host = request.get_host()
           ^^^^^^^^^^^^^^^^^^
  File "D:\projects\qr\qr\env\scripts\python.py\Lib\site-packages\django\http\request.py", line 151, in get_host
    raise DisallowedHost(msg)
django.core.exceptions.DisallowedHost: Invalid HTTP_HOST header: '127.0.0.1:8000'. You may need to add '127.0.0.1' to ALLOWED_HOSTS.
ERROR 2025-03-18 13:31:54,879 D:\projects\qr\qr\env\scripts\python.py\Lib\site-packages\django\utils\log.py:248 Internal Server Error: /admin/website/image/add/
Traceback (most recent call last):
  File "D:\projects\qr\qr\env\scripts\python.py\Lib\site-packages\django\core\handlers\exception.py", line 55, in inner
    response = get_response(request)
               ^^^^^^^^^^^^^^^^^^^^^
  File "D:\projects\qr\qr\env\scripts\python.py\Lib\site-packages\django\core\handlers\base.py", line 197, in _get_response
    response = wrapped_callback(request, *callback_args, **callback_kwargs)
               ^^^^^^^^^^^^^^^^^^^^^^^^^^^^^^^^^^^^^^^^^^^^^^^^^^^^^^^^^^^^
  File "D:\projects\qr\qr\env\scripts\python.py\Lib\site-packages\django\contrib\admin\options.py", line 718, in wrapper
    return self.admin_site.admin_view(view)(*args, **kwargs)
           ^^^^^^^^^^^^^^^^^^^^^^^^^^^^^^^^^^^^^^^^^^^^^^^^^
  File "D:\projects\qr\qr\env\scripts\python.py\Lib\site-packages\django\utils\decorators.py", line 188, in _view_wrapper
    result = _process_exception(request, e)
             ^^^^^^^^^^^^^^^^^^^^^^^^^^^^^^
  File "D:\projects\qr\qr\env\scripts\python.py\Lib\site-packages\django\utils\decorators.py", line 186, in _view_wrapper
    response = view_func(request, *args, **kwargs)
               ^^^^^^^^^^^^^^^^^^^^^^^^^^^^^^^^^^^
  File "D:\projects\qr\qr\env\scripts\python.py\Lib\site-packages\django\views\decorators\cache.py", line 80, in _view_wrapper
    response = view_func(request, *args, **kwargs)
               ^^^^^^^^^^^^^^^^^^^^^^^^^^^^^^^^^^^
  File "D:\projects\qr\qr\env\scripts\python.py\Lib\site-packages\django\contrib\admin\sites.py", line 241, in inner
    return view(request, *args, **kwargs)
           ^^^^^^^^^^^^^^^^^^^^^^^^^^^^^^
  File "D:\projects\qr\qr\env\scripts\python.py\Lib\site-packages\django\contrib\admin\options.py", line 1959, in add_view
    return self.changeform_view(request, None, form_url, extra_context)
           ^^^^^^^^^^^^^^^^^^^^^^^^^^^^^^^^^^^^^^^^^^^^^^^^^^^^^^^^^^^^
  File "D:\projects\qr\qr\env\scripts\python.py\Lib\site-packages\django\utils\decorators.py", line 48, in _wrapper
    return bound_method(*args, **kwargs)
           ^^^^^^^^^^^^^^^^^^^^^^^^^^^^^
  File "D:\projects\qr\qr\env\scripts\python.py\Lib\site-packages\django\utils\decorators.py", line 188, in _view_wrapper
    result = _process_exception(request, e)
             ^^^^^^^^^^^^^^^^^^^^^^^^^^^^^^
  File "D:\projects\qr\qr\env\scripts\python.py\Lib\site-packages\django\utils\decorators.py", line 186, in _view_wrapper
    response = view_func(request, *args, **kwargs)
               ^^^^^^^^^^^^^^^^^^^^^^^^^^^^^^^^^^^
  File "D:\projects\qr\qr\env\scripts\python.py\Lib\site-packages\django\contrib\admin\options.py", line 1818, in changeform_view
    return self._changeform_view(request, object_id, form_url, extra_context)
           ^^^^^^^^^^^^^^^^^^^^^^^^^^^^^^^^^^^^^^^^^^^^^^^^^^^^^^^^^^^^^^^^^^
  File "D:\projects\qr\qr\env\scripts\python.py\Lib\site-packages\django\contrib\admin\options.py", line 1869, in _changeform_view
    self.save_model(request, new_object, form, not add)
  File "D:\projects\qr\qr\env\scripts\python.py\Lib\site-packages\django\contrib\admin\options.py", line 1292, in save_model
    obj.save()
  File "D:\projects\qr\qr\qr\website\models.py", line 27, in save
    qr_code_image = self.generate_qr_code()
                    ^^^^^^^^^^^^^^^^^^^^^^^
TypeError: Image.generate_qr_code() missing 1 required positional argument: 'request'
ERROR 2025-03-18 13:31:54,883 D:\projects\qr\qr\env\scripts\python.py\Lib\site-packages\django\core\servers\basehttp.py:213 "POST /admin/website/image/add/ HTTP/1.1" 500 133043
ERROR 2025-03-18 13:35:17,725 D:\projects\qr\qr\env\scripts\python.py\Lib\site-packages\django\utils\log.py:248 Internal Server Error: /admin/website/image/add/
Traceback (most recent call last):
  File "D:\projects\qr\qr\env\scripts\python.py\Lib\site-packages\django\core\handlers\exception.py", line 55, in inner
    response = get_response(request)
               ^^^^^^^^^^^^^^^^^^^^^
  File "D:\projects\qr\qr\env\scripts\python.py\Lib\site-packages\django\core\handlers\base.py", line 197, in _get_response
    response = wrapped_callback(request, *callback_args, **callback_kwargs)
               ^^^^^^^^^^^^^^^^^^^^^^^^^^^^^^^^^^^^^^^^^^^^^^^^^^^^^^^^^^^^
  File "D:\projects\qr\qr\env\scripts\python.py\Lib\site-packages\django\contrib\admin\options.py", line 718, in wrapper
    return self.admin_site.admin_view(view)(*args, **kwargs)
           ^^^^^^^^^^^^^^^^^^^^^^^^^^^^^^^^^^^^^^^^^^^^^^^^^
  File "D:\projects\qr\qr\env\scripts\python.py\Lib\site-packages\django\utils\decorators.py", line 188, in _view_wrapper
    result = _process_exception(request, e)
             ^^^^^^^^^^^^^^^^^^^^^^^^^^^^^^
  File "D:\projects\qr\qr\env\scripts\python.py\Lib\site-packages\django\utils\decorators.py", line 186, in _view_wrapper
    response = view_func(request, *args, **kwargs)
               ^^^^^^^^^^^^^^^^^^^^^^^^^^^^^^^^^^^
  File "D:\projects\qr\qr\env\scripts\python.py\Lib\site-packages\django\views\decorators\cache.py", line 80, in _view_wrapper
    response = view_func(request, *args, **kwargs)
               ^^^^^^^^^^^^^^^^^^^^^^^^^^^^^^^^^^^
  File "D:\projects\qr\qr\env\scripts\python.py\Lib\site-packages\django\contrib\admin\sites.py", line 241, in inner
    return view(request, *args, **kwargs)
           ^^^^^^^^^^^^^^^^^^^^^^^^^^^^^^
  File "D:\projects\qr\qr\env\scripts\python.py\Lib\site-packages\django\contrib\admin\options.py", line 1959, in add_view
    return self.changeform_view(request, None, form_url, extra_context)
           ^^^^^^^^^^^^^^^^^^^^^^^^^^^^^^^^^^^^^^^^^^^^^^^^^^^^^^^^^^^^
  File "D:\projects\qr\qr\env\scripts\python.py\Lib\site-packages\django\utils\decorators.py", line 48, in _wrapper
    return bound_method(*args, **kwargs)
           ^^^^^^^^^^^^^^^^^^^^^^^^^^^^^
  File "D:\projects\qr\qr\env\scripts\python.py\Lib\site-packages\django\utils\decorators.py", line 188, in _view_wrapper
    result = _process_exception(request, e)
             ^^^^^^^^^^^^^^^^^^^^^^^^^^^^^^
  File "D:\projects\qr\qr\env\scripts\python.py\Lib\site-packages\django\utils\decorators.py", line 186, in _view_wrapper
    response = view_func(request, *args, **kwargs)
               ^^^^^^^^^^^^^^^^^^^^^^^^^^^^^^^^^^^
  File "D:\projects\qr\qr\env\scripts\python.py\Lib\site-packages\django\contrib\admin\options.py", line 1818, in changeform_view
    return self._changeform_view(request, object_id, form_url, extra_context)
           ^^^^^^^^^^^^^^^^^^^^^^^^^^^^^^^^^^^^^^^^^^^^^^^^^^^^^^^^^^^^^^^^^^
  File "D:\projects\qr\qr\env\scripts\python.py\Lib\site-packages\django\contrib\admin\options.py", line 1869, in _changeform_view
    self.save_model(request, new_object, form, not add)
  File "D:\projects\qr\qr\env\scripts\python.py\Lib\site-packages\django\contrib\admin\options.py", line 1292, in save_model
    obj.save()
  File "D:\projects\qr\qr\qr\website\models.py", line 26, in save
    qr_code_image = self.generate_qr_code()
                    ^^^^^^^^^^^^^^^^^^^^^^^
TypeError: Image.generate_qr_code() missing 1 required positional argument: 'request'
ERROR 2025-03-18 13:35:17,730 D:\projects\qr\qr\env\scripts\python.py\Lib\site-packages\django\core\servers\basehttp.py:213 "POST /admin/website/image/add/ HTTP/1.1" 500 132988
ERROR 2025-03-18 13:35:34,114 D:\projects\qr\qr\env\scripts\python.py\Lib\site-packages\django\utils\log.py:248 Internal Server Error: /admin/website/image/add/
Traceback (most recent call last):
  File "D:\projects\qr\qr\env\scripts\python.py\Lib\site-packages\django\core\handlers\exception.py", line 55, in inner
    response = get_response(request)
               ^^^^^^^^^^^^^^^^^^^^^
  File "D:\projects\qr\qr\env\scripts\python.py\Lib\site-packages\django\core\handlers\base.py", line 197, in _get_response
    response = wrapped_callback(request, *callback_args, **callback_kwargs)
               ^^^^^^^^^^^^^^^^^^^^^^^^^^^^^^^^^^^^^^^^^^^^^^^^^^^^^^^^^^^^
  File "D:\projects\qr\qr\env\scripts\python.py\Lib\site-packages\django\contrib\admin\options.py", line 718, in wrapper
    return self.admin_site.admin_view(view)(*args, **kwargs)
           ^^^^^^^^^^^^^^^^^^^^^^^^^^^^^^^^^^^^^^^^^^^^^^^^^
  File "D:\projects\qr\qr\env\scripts\python.py\Lib\site-packages\django\utils\decorators.py", line 188, in _view_wrapper
    result = _process_exception(request, e)
             ^^^^^^^^^^^^^^^^^^^^^^^^^^^^^^
  File "D:\projects\qr\qr\env\scripts\python.py\Lib\site-packages\django\utils\decorators.py", line 186, in _view_wrapper
    response = view_func(request, *args, **kwargs)
               ^^^^^^^^^^^^^^^^^^^^^^^^^^^^^^^^^^^
  File "D:\projects\qr\qr\env\scripts\python.py\Lib\site-packages\django\views\decorators\cache.py", line 80, in _view_wrapper
    response = view_func(request, *args, **kwargs)
               ^^^^^^^^^^^^^^^^^^^^^^^^^^^^^^^^^^^
  File "D:\projects\qr\qr\env\scripts\python.py\Lib\site-packages\django\contrib\admin\sites.py", line 241, in inner
    return view(request, *args, **kwargs)
           ^^^^^^^^^^^^^^^^^^^^^^^^^^^^^^
  File "D:\projects\qr\qr\env\scripts\python.py\Lib\site-packages\django\contrib\admin\options.py", line 1959, in add_view
    return self.changeform_view(request, None, form_url, extra_context)
           ^^^^^^^^^^^^^^^^^^^^^^^^^^^^^^^^^^^^^^^^^^^^^^^^^^^^^^^^^^^^
  File "D:\projects\qr\qr\env\scripts\python.py\Lib\site-packages\django\utils\decorators.py", line 48, in _wrapper
    return bound_method(*args, **kwargs)
           ^^^^^^^^^^^^^^^^^^^^^^^^^^^^^
  File "D:\projects\qr\qr\env\scripts\python.py\Lib\site-packages\django\utils\decorators.py", line 188, in _view_wrapper
    result = _process_exception(request, e)
             ^^^^^^^^^^^^^^^^^^^^^^^^^^^^^^
  File "D:\projects\qr\qr\env\scripts\python.py\Lib\site-packages\django\utils\decorators.py", line 186, in _view_wrapper
    response = view_func(request, *args, **kwargs)
               ^^^^^^^^^^^^^^^^^^^^^^^^^^^^^^^^^^^
  File "D:\projects\qr\qr\env\scripts\python.py\Lib\site-packages\django\contrib\admin\options.py", line 1818, in changeform_view
    return self._changeform_view(request, object_id, form_url, extra_context)
           ^^^^^^^^^^^^^^^^^^^^^^^^^^^^^^^^^^^^^^^^^^^^^^^^^^^^^^^^^^^^^^^^^^
  File "D:\projects\qr\qr\env\scripts\python.py\Lib\site-packages\django\contrib\admin\options.py", line 1869, in _changeform_view
    self.save_model(request, new_object, form, not add)
  File "D:\projects\qr\qr\env\scripts\python.py\Lib\site-packages\django\contrib\admin\options.py", line 1292, in save_model
    obj.save()
  File "D:\projects\qr\qr\qr\website\models.py", line 26, in save
    qr_code_image = self.generate_qr_code()
                    ^^^^^^^^^^^^^^^^^^^^^^^
TypeError: Image.generate_qr_code() missing 1 required positional argument: 'request'
ERROR 2025-03-18 13:35:34,120 D:\projects\qr\qr\env\scripts\python.py\Lib\site-packages\django\core\servers\basehttp.py:213 "POST /admin/website/image/add/ HTTP/1.1" 500 132988
ERROR 2025-03-18 13:35:36,876 D:\projects\qr\qr\env\scripts\python.py\Lib\site-packages\django\utils\log.py:248 Internal Server Error: /admin/website/image/add/
Traceback (most recent call last):
  File "D:\projects\qr\qr\env\scripts\python.py\Lib\site-packages\django\core\handlers\exception.py", line 55, in inner
    response = get_response(request)
               ^^^^^^^^^^^^^^^^^^^^^
  File "D:\projects\qr\qr\env\scripts\python.py\Lib\site-packages\django\core\handlers\base.py", line 197, in _get_response
    response = wrapped_callback(request, *callback_args, **callback_kwargs)
               ^^^^^^^^^^^^^^^^^^^^^^^^^^^^^^^^^^^^^^^^^^^^^^^^^^^^^^^^^^^^
  File "D:\projects\qr\qr\env\scripts\python.py\Lib\site-packages\django\contrib\admin\options.py", line 718, in wrapper
    return self.admin_site.admin_view(view)(*args, **kwargs)
           ^^^^^^^^^^^^^^^^^^^^^^^^^^^^^^^^^^^^^^^^^^^^^^^^^
  File "D:\projects\qr\qr\env\scripts\python.py\Lib\site-packages\django\utils\decorators.py", line 188, in _view_wrapper
    result = _process_exception(request, e)
             ^^^^^^^^^^^^^^^^^^^^^^^^^^^^^^
  File "D:\projects\qr\qr\env\scripts\python.py\Lib\site-packages\django\utils\decorators.py", line 186, in _view_wrapper
    response = view_func(request, *args, **kwargs)
               ^^^^^^^^^^^^^^^^^^^^^^^^^^^^^^^^^^^
  File "D:\projects\qr\qr\env\scripts\python.py\Lib\site-packages\django\views\decorators\cache.py", line 80, in _view_wrapper
    response = view_func(request, *args, **kwargs)
               ^^^^^^^^^^^^^^^^^^^^^^^^^^^^^^^^^^^
  File "D:\projects\qr\qr\env\scripts\python.py\Lib\site-packages\django\contrib\admin\sites.py", line 241, in inner
    return view(request, *args, **kwargs)
           ^^^^^^^^^^^^^^^^^^^^^^^^^^^^^^
  File "D:\projects\qr\qr\env\scripts\python.py\Lib\site-packages\django\contrib\admin\options.py", line 1959, in add_view
    return self.changeform_view(request, None, form_url, extra_context)
           ^^^^^^^^^^^^^^^^^^^^^^^^^^^^^^^^^^^^^^^^^^^^^^^^^^^^^^^^^^^^
  File "D:\projects\qr\qr\env\scripts\python.py\Lib\site-packages\django\utils\decorators.py", line 48, in _wrapper
    return bound_method(*args, **kwargs)
           ^^^^^^^^^^^^^^^^^^^^^^^^^^^^^
  File "D:\projects\qr\qr\env\scripts\python.py\Lib\site-packages\django\utils\decorators.py", line 188, in _view_wrapper
    result = _process_exception(request, e)
             ^^^^^^^^^^^^^^^^^^^^^^^^^^^^^^
  File "D:\projects\qr\qr\env\scripts\python.py\Lib\site-packages\django\utils\decorators.py", line 186, in _view_wrapper
    response = view_func(request, *args, **kwargs)
               ^^^^^^^^^^^^^^^^^^^^^^^^^^^^^^^^^^^
  File "D:\projects\qr\qr\env\scripts\python.py\Lib\site-packages\django\contrib\admin\options.py", line 1818, in changeform_view
    return self._changeform_view(request, object_id, form_url, extra_context)
           ^^^^^^^^^^^^^^^^^^^^^^^^^^^^^^^^^^^^^^^^^^^^^^^^^^^^^^^^^^^^^^^^^^
  File "D:\projects\qr\qr\env\scripts\python.py\Lib\site-packages\django\contrib\admin\options.py", line 1869, in _changeform_view
    self.save_model(request, new_object, form, not add)
  File "D:\projects\qr\qr\env\scripts\python.py\Lib\site-packages\django\contrib\admin\options.py", line 1292, in save_model
    obj.save()
  File "D:\projects\qr\qr\qr\website\models.py", line 26, in save
    qr_code_image = self.generate_qr_code()
                    ^^^^^^^^^^^^^^^^^^^^^^^
TypeError: Image.generate_qr_code() missing 1 required positional argument: 'request'
ERROR 2025-03-18 13:35:36,878 D:\projects\qr\qr\env\scripts\python.py\Lib\site-packages\django\core\servers\basehttp.py:213 "POST /admin/website/image/add/ HTTP/1.1" 500 133119
ERROR 2025-03-18 13:35:51,907 D:\projects\qr\qr\env\scripts\python.py\Lib\site-packages\django\utils\log.py:248 Internal Server Error: /admin/website/image/add/
Traceback (most recent call last):
  File "D:\projects\qr\qr\env\scripts\python.py\Lib\site-packages\django\core\handlers\exception.py", line 55, in inner
    response = get_response(request)
               ^^^^^^^^^^^^^^^^^^^^^
  File "D:\projects\qr\qr\env\scripts\python.py\Lib\site-packages\django\core\handlers\base.py", line 197, in _get_response
    response = wrapped_callback(request, *callback_args, **callback_kwargs)
               ^^^^^^^^^^^^^^^^^^^^^^^^^^^^^^^^^^^^^^^^^^^^^^^^^^^^^^^^^^^^
  File "D:\projects\qr\qr\env\scripts\python.py\Lib\site-packages\django\contrib\admin\options.py", line 718, in wrapper
    return self.admin_site.admin_view(view)(*args, **kwargs)
           ^^^^^^^^^^^^^^^^^^^^^^^^^^^^^^^^^^^^^^^^^^^^^^^^^
  File "D:\projects\qr\qr\env\scripts\python.py\Lib\site-packages\django\utils\decorators.py", line 188, in _view_wrapper
    result = _process_exception(request, e)
             ^^^^^^^^^^^^^^^^^^^^^^^^^^^^^^
  File "D:\projects\qr\qr\env\scripts\python.py\Lib\site-packages\django\utils\decorators.py", line 186, in _view_wrapper
    response = view_func(request, *args, **kwargs)
               ^^^^^^^^^^^^^^^^^^^^^^^^^^^^^^^^^^^
  File "D:\projects\qr\qr\env\scripts\python.py\Lib\site-packages\django\views\decorators\cache.py", line 80, in _view_wrapper
    response = view_func(request, *args, **kwargs)
               ^^^^^^^^^^^^^^^^^^^^^^^^^^^^^^^^^^^
  File "D:\projects\qr\qr\env\scripts\python.py\Lib\site-packages\django\contrib\admin\sites.py", line 241, in inner
    return view(request, *args, **kwargs)
           ^^^^^^^^^^^^^^^^^^^^^^^^^^^^^^
  File "D:\projects\qr\qr\env\scripts\python.py\Lib\site-packages\django\contrib\admin\options.py", line 1959, in add_view
    return self.changeform_view(request, None, form_url, extra_context)
           ^^^^^^^^^^^^^^^^^^^^^^^^^^^^^^^^^^^^^^^^^^^^^^^^^^^^^^^^^^^^
  File "D:\projects\qr\qr\env\scripts\python.py\Lib\site-packages\django\utils\decorators.py", line 48, in _wrapper
    return bound_method(*args, **kwargs)
           ^^^^^^^^^^^^^^^^^^^^^^^^^^^^^
  File "D:\projects\qr\qr\env\scripts\python.py\Lib\site-packages\django\utils\decorators.py", line 188, in _view_wrapper
    result = _process_exception(request, e)
             ^^^^^^^^^^^^^^^^^^^^^^^^^^^^^^
  File "D:\projects\qr\qr\env\scripts\python.py\Lib\site-packages\django\utils\decorators.py", line 186, in _view_wrapper
    response = view_func(request, *args, **kwargs)
               ^^^^^^^^^^^^^^^^^^^^^^^^^^^^^^^^^^^
  File "D:\projects\qr\qr\env\scripts\python.py\Lib\site-packages\django\contrib\admin\options.py", line 1818, in changeform_view
    return self._changeform_view(request, object_id, form_url, extra_context)
           ^^^^^^^^^^^^^^^^^^^^^^^^^^^^^^^^^^^^^^^^^^^^^^^^^^^^^^^^^^^^^^^^^^
  File "D:\projects\qr\qr\env\scripts\python.py\Lib\site-packages\django\contrib\admin\options.py", line 1869, in _changeform_view
    self.save_model(request, new_object, form, not add)
  File "D:\projects\qr\qr\env\scripts\python.py\Lib\site-packages\django\contrib\admin\options.py", line 1292, in save_model
    obj.save()
  File "D:\projects\qr\qr\qr\website\models.py", line 26, in save
    qr_code_image = self.generate_qr_code()
                    ^^^^^^^^^^^^^^^^^^^^^^^
TypeError: Image.generate_qr_code() missing 1 required positional argument: 'request'
ERROR 2025-03-18 13:35:51,910 D:\projects\qr\qr\env\scripts\python.py\Lib\site-packages\django\core\servers\basehttp.py:213 "POST /admin/website/image/add/ HTTP/1.1" 500 133119
ERROR 2025-03-18 13:36:04,335 D:\projects\qr\qr\env\scripts\python.py\Lib\site-packages\django\utils\log.py:248 Internal Server Error: /admin/website/image/add/
Traceback (most recent call last):
  File "D:\projects\qr\qr\env\scripts\python.py\Lib\site-packages\django\core\handlers\exception.py", line 55, in inner
    response = get_response(request)
               ^^^^^^^^^^^^^^^^^^^^^
  File "D:\projects\qr\qr\env\scripts\python.py\Lib\site-packages\django\core\handlers\base.py", line 197, in _get_response
    response = wrapped_callback(request, *callback_args, **callback_kwargs)
               ^^^^^^^^^^^^^^^^^^^^^^^^^^^^^^^^^^^^^^^^^^^^^^^^^^^^^^^^^^^^
  File "D:\projects\qr\qr\env\scripts\python.py\Lib\site-packages\django\contrib\admin\options.py", line 718, in wrapper
    return self.admin_site.admin_view(view)(*args, **kwargs)
           ^^^^^^^^^^^^^^^^^^^^^^^^^^^^^^^^^^^^^^^^^^^^^^^^^
  File "D:\projects\qr\qr\env\scripts\python.py\Lib\site-packages\django\utils\decorators.py", line 188, in _view_wrapper
    result = _process_exception(request, e)
             ^^^^^^^^^^^^^^^^^^^^^^^^^^^^^^
  File "D:\projects\qr\qr\env\scripts\python.py\Lib\site-packages\django\utils\decorators.py", line 186, in _view_wrapper
    response = view_func(request, *args, **kwargs)
               ^^^^^^^^^^^^^^^^^^^^^^^^^^^^^^^^^^^
  File "D:\projects\qr\qr\env\scripts\python.py\Lib\site-packages\django\views\decorators\cache.py", line 80, in _view_wrapper
    response = view_func(request, *args, **kwargs)
               ^^^^^^^^^^^^^^^^^^^^^^^^^^^^^^^^^^^
  File "D:\projects\qr\qr\env\scripts\python.py\Lib\site-packages\django\contrib\admin\sites.py", line 241, in inner
    return view(request, *args, **kwargs)
           ^^^^^^^^^^^^^^^^^^^^^^^^^^^^^^
  File "D:\projects\qr\qr\env\scripts\python.py\Lib\site-packages\django\contrib\admin\options.py", line 1959, in add_view
    return self.changeform_view(request, None, form_url, extra_context)
           ^^^^^^^^^^^^^^^^^^^^^^^^^^^^^^^^^^^^^^^^^^^^^^^^^^^^^^^^^^^^
  File "D:\projects\qr\qr\env\scripts\python.py\Lib\site-packages\django\utils\decorators.py", line 48, in _wrapper
    return bound_method(*args, **kwargs)
           ^^^^^^^^^^^^^^^^^^^^^^^^^^^^^
  File "D:\projects\qr\qr\env\scripts\python.py\Lib\site-packages\django\utils\decorators.py", line 188, in _view_wrapper
    result = _process_exception(request, e)
             ^^^^^^^^^^^^^^^^^^^^^^^^^^^^^^
  File "D:\projects\qr\qr\env\scripts\python.py\Lib\site-packages\django\utils\decorators.py", line 186, in _view_wrapper
    response = view_func(request, *args, **kwargs)
               ^^^^^^^^^^^^^^^^^^^^^^^^^^^^^^^^^^^
  File "D:\projects\qr\qr\env\scripts\python.py\Lib\site-packages\django\contrib\admin\options.py", line 1818, in changeform_view
    return self._changeform_view(request, object_id, form_url, extra_context)
           ^^^^^^^^^^^^^^^^^^^^^^^^^^^^^^^^^^^^^^^^^^^^^^^^^^^^^^^^^^^^^^^^^^
  File "D:\projects\qr\qr\env\scripts\python.py\Lib\site-packages\django\contrib\admin\options.py", line 1869, in _changeform_view
    self.save_model(request, new_object, form, not add)
  File "D:\projects\qr\qr\env\scripts\python.py\Lib\site-packages\django\contrib\admin\options.py", line 1292, in save_model
    obj.save()
  File "D:\projects\qr\qr\qr\website\models.py", line 26, in save
    qr_code_image = self.generate_qr_code()
                    ^^^^^^^^^^^^^^^^^^^^^^^
  File "D:\projects\qr\qr\qr\website\models.py", line 32, in generate_qr_code
    domain = Site.objects.get_current().domain
             ^^^^^^^^^^^^^^^^^^^^^^^^^^
  File "D:\projects\qr\qr\env\scripts\python.py\Lib\site-packages\django\contrib\sites\models.py", line 63, in get_current
    raise ImproperlyConfigured(
django.core.exceptions.ImproperlyConfigured: You're using the Django "sites framework" without having set the SITE_ID setting. Create a site in your database and set the SITE_ID setting or pass a request to Site.objects.get_current() to fix this error.
ERROR 2025-03-18 13:36:04,344 D:\projects\qr\qr\env\scripts\python.py\Lib\site-packages\django\core\servers\basehttp.py:213 "POST /admin/website/image/add/ HTTP/1.1" 500 141371
ERROR 2025-03-18 13:36:22,805 D:\projects\qr\qr\env\scripts\python.py\Lib\site-packages\django\utils\log.py:248 Internal Server Error: /admin/website/image/add/
Traceback (most recent call last):
  File "D:\projects\qr\qr\env\scripts\python.py\Lib\site-packages\django\core\handlers\exception.py", line 55, in inner
    response = get_response(request)
               ^^^^^^^^^^^^^^^^^^^^^
  File "D:\projects\qr\qr\env\scripts\python.py\Lib\site-packages\django\core\handlers\base.py", line 197, in _get_response
    response = wrapped_callback(request, *callback_args, **callback_kwargs)
               ^^^^^^^^^^^^^^^^^^^^^^^^^^^^^^^^^^^^^^^^^^^^^^^^^^^^^^^^^^^^
  File "D:\projects\qr\qr\env\scripts\python.py\Lib\site-packages\django\contrib\admin\options.py", line 718, in wrapper
    return self.admin_site.admin_view(view)(*args, **kwargs)
           ^^^^^^^^^^^^^^^^^^^^^^^^^^^^^^^^^^^^^^^^^^^^^^^^^
  File "D:\projects\qr\qr\env\scripts\python.py\Lib\site-packages\django\utils\decorators.py", line 188, in _view_wrapper
    result = _process_exception(request, e)
             ^^^^^^^^^^^^^^^^^^^^^^^^^^^^^^
  File "D:\projects\qr\qr\env\scripts\python.py\Lib\site-packages\django\utils\decorators.py", line 186, in _view_wrapper
    response = view_func(request, *args, **kwargs)
               ^^^^^^^^^^^^^^^^^^^^^^^^^^^^^^^^^^^
  File "D:\projects\qr\qr\env\scripts\python.py\Lib\site-packages\django\views\decorators\cache.py", line 80, in _view_wrapper
    response = view_func(request, *args, **kwargs)
               ^^^^^^^^^^^^^^^^^^^^^^^^^^^^^^^^^^^
  File "D:\projects\qr\qr\env\scripts\python.py\Lib\site-packages\django\contrib\admin\sites.py", line 241, in inner
    return view(request, *args, **kwargs)
           ^^^^^^^^^^^^^^^^^^^^^^^^^^^^^^
  File "D:\projects\qr\qr\env\scripts\python.py\Lib\site-packages\django\contrib\admin\options.py", line 1959, in add_view
    return self.changeform_view(request, None, form_url, extra_context)
           ^^^^^^^^^^^^^^^^^^^^^^^^^^^^^^^^^^^^^^^^^^^^^^^^^^^^^^^^^^^^
  File "D:\projects\qr\qr\env\scripts\python.py\Lib\site-packages\django\utils\decorators.py", line 48, in _wrapper
    return bound_method(*args, **kwargs)
           ^^^^^^^^^^^^^^^^^^^^^^^^^^^^^
  File "D:\projects\qr\qr\env\scripts\python.py\Lib\site-packages\django\utils\decorators.py", line 188, in _view_wrapper
    result = _process_exception(request, e)
             ^^^^^^^^^^^^^^^^^^^^^^^^^^^^^^
  File "D:\projects\qr\qr\env\scripts\python.py\Lib\site-packages\django\utils\decorators.py", line 186, in _view_wrapper
    response = view_func(request, *args, **kwargs)
               ^^^^^^^^^^^^^^^^^^^^^^^^^^^^^^^^^^^
  File "D:\projects\qr\qr\env\scripts\python.py\Lib\site-packages\django\contrib\admin\options.py", line 1818, in changeform_view
    return self._changeform_view(request, object_id, form_url, extra_context)
           ^^^^^^^^^^^^^^^^^^^^^^^^^^^^^^^^^^^^^^^^^^^^^^^^^^^^^^^^^^^^^^^^^^
  File "D:\projects\qr\qr\env\scripts\python.py\Lib\site-packages\django\contrib\admin\options.py", line 1869, in _changeform_view
    self.save_model(request, new_object, form, not add)
  File "D:\projects\qr\qr\env\scripts\python.py\Lib\site-packages\django\contrib\admin\options.py", line 1292, in save_model
    obj.save()
  File "D:\projects\qr\qr\qr\website\models.py", line 26, in save
    qr_code_image = self.generate_qr_code()
                    ^^^^^^^^^^^^^^^^^^^^^^^
  File "D:\projects\qr\qr\qr\website\models.py", line 33, in generate_qr_code
    domain = Site.objects.get_current().domain
             ^^^^^^^^^^^^^^^^^^^^^^^^^^
  File "D:\projects\qr\qr\env\scripts\python.py\Lib\site-packages\django\contrib\sites\models.py", line 63, in get_current
    raise ImproperlyConfigured(
django.core.exceptions.ImproperlyConfigured: You're using the Django "sites framework" without having set the SITE_ID setting. Create a site in your database and set the SITE_ID setting or pass a request to Site.objects.get_current() to fix this error.
ERROR 2025-03-18 13:36:22,812 D:\projects\qr\qr\env\scripts\python.py\Lib\site-packages\django\core\servers\basehttp.py:213 "POST /admin/website/image/add/ HTTP/1.1" 500 141320
ERROR 2025-03-18 13:36:26,219 D:\projects\qr\qr\env\scripts\python.py\Lib\site-packages\django\utils\log.py:248 Internal Server Error: /admin/website/image/add/
Traceback (most recent call last):
  File "D:\projects\qr\qr\env\scripts\python.py\Lib\site-packages\django\core\handlers\exception.py", line 55, in inner
    response = get_response(request)
               ^^^^^^^^^^^^^^^^^^^^^
  File "D:\projects\qr\qr\env\scripts\python.py\Lib\site-packages\django\core\handlers\base.py", line 197, in _get_response
    response = wrapped_callback(request, *callback_args, **callback_kwargs)
               ^^^^^^^^^^^^^^^^^^^^^^^^^^^^^^^^^^^^^^^^^^^^^^^^^^^^^^^^^^^^
  File "D:\projects\qr\qr\env\scripts\python.py\Lib\site-packages\django\contrib\admin\options.py", line 718, in wrapper
    return self.admin_site.admin_view(view)(*args, **kwargs)
           ^^^^^^^^^^^^^^^^^^^^^^^^^^^^^^^^^^^^^^^^^^^^^^^^^
  File "D:\projects\qr\qr\env\scripts\python.py\Lib\site-packages\django\utils\decorators.py", line 188, in _view_wrapper
    result = _process_exception(request, e)
             ^^^^^^^^^^^^^^^^^^^^^^^^^^^^^^
  File "D:\projects\qr\qr\env\scripts\python.py\Lib\site-packages\django\utils\decorators.py", line 186, in _view_wrapper
    response = view_func(request, *args, **kwargs)
               ^^^^^^^^^^^^^^^^^^^^^^^^^^^^^^^^^^^
  File "D:\projects\qr\qr\env\scripts\python.py\Lib\site-packages\django\views\decorators\cache.py", line 80, in _view_wrapper
    response = view_func(request, *args, **kwargs)
               ^^^^^^^^^^^^^^^^^^^^^^^^^^^^^^^^^^^
  File "D:\projects\qr\qr\env\scripts\python.py\Lib\site-packages\django\contrib\admin\sites.py", line 241, in inner
    return view(request, *args, **kwargs)
           ^^^^^^^^^^^^^^^^^^^^^^^^^^^^^^
  File "D:\projects\qr\qr\env\scripts\python.py\Lib\site-packages\django\contrib\admin\options.py", line 1959, in add_view
    return self.changeform_view(request, None, form_url, extra_context)
           ^^^^^^^^^^^^^^^^^^^^^^^^^^^^^^^^^^^^^^^^^^^^^^^^^^^^^^^^^^^^
  File "D:\projects\qr\qr\env\scripts\python.py\Lib\site-packages\django\utils\decorators.py", line 48, in _wrapper
    return bound_method(*args, **kwargs)
           ^^^^^^^^^^^^^^^^^^^^^^^^^^^^^
  File "D:\projects\qr\qr\env\scripts\python.py\Lib\site-packages\django\utils\decorators.py", line 188, in _view_wrapper
    result = _process_exception(request, e)
             ^^^^^^^^^^^^^^^^^^^^^^^^^^^^^^
  File "D:\projects\qr\qr\env\scripts\python.py\Lib\site-packages\django\utils\decorators.py", line 186, in _view_wrapper
    response = view_func(request, *args, **kwargs)
               ^^^^^^^^^^^^^^^^^^^^^^^^^^^^^^^^^^^
  File "D:\projects\qr\qr\env\scripts\python.py\Lib\site-packages\django\contrib\admin\options.py", line 1818, in changeform_view
    return self._changeform_view(request, object_id, form_url, extra_context)
           ^^^^^^^^^^^^^^^^^^^^^^^^^^^^^^^^^^^^^^^^^^^^^^^^^^^^^^^^^^^^^^^^^^
  File "D:\projects\qr\qr\env\scripts\python.py\Lib\site-packages\django\contrib\admin\options.py", line 1869, in _changeform_view
    self.save_model(request, new_object, form, not add)
  File "D:\projects\qr\qr\env\scripts\python.py\Lib\site-packages\django\contrib\admin\options.py", line 1292, in save_model
    obj.save()
  File "D:\projects\qr\qr\qr\website\models.py", line 26, in save
    qr_code_image = self.generate_qr_code()
                    ^^^^^^^^^^^^^^^^^^^^^^^
  File "D:\projects\qr\qr\qr\website\models.py", line 33, in generate_qr_code
    domain = Site.objects.get_current().domain
             ^^^^^^^^^^^^^^^^^^^^^^^^^^
  File "D:\projects\qr\qr\env\scripts\python.py\Lib\site-packages\django\contrib\sites\models.py", line 63, in get_current
    raise ImproperlyConfigured(
django.core.exceptions.ImproperlyConfigured: You're using the Django "sites framework" without having set the SITE_ID setting. Create a site in your database and set the SITE_ID setting or pass a request to Site.objects.get_current() to fix this error.
ERROR 2025-03-18 13:36:26,221 D:\projects\qr\qr\env\scripts\python.py\Lib\site-packages\django\core\servers\basehttp.py:213 "POST /admin/website/image/add/ HTTP/1.1" 500 141451
ERROR 2025-03-18 13:37:34,111 D:\projects\qr\qr\env\scripts\python.py\Lib\site-packages\django\utils\log.py:248 Internal Server Error: /admin/website/image/add/
Traceback (most recent call last):
  File "D:\projects\qr\qr\env\scripts\python.py\Lib\site-packages\django\db\backends\utils.py", line 105, in _execute
    return self.cursor.execute(sql, params)
           ^^^^^^^^^^^^^^^^^^^^^^^^^^^^^^^^
  File "D:\projects\qr\qr\env\scripts\python.py\Lib\site-packages\django\db\backends\sqlite3\base.py", line 354, in execute
    return super().execute(query, params)
           ^^^^^^^^^^^^^^^^^^^^^^^^^^^^^^
sqlite3.OperationalError: no such table: django_site

The above exception was the direct cause of the following exception:

Traceback (most recent call last):
  File "D:\projects\qr\qr\env\scripts\python.py\Lib\site-packages\django\core\handlers\exception.py", line 55, in inner
    response = get_response(request)
               ^^^^^^^^^^^^^^^^^^^^^
  File "D:\projects\qr\qr\env\scripts\python.py\Lib\site-packages\django\core\handlers\base.py", line 197, in _get_response
    response = wrapped_callback(request, *callback_args, **callback_kwargs)
               ^^^^^^^^^^^^^^^^^^^^^^^^^^^^^^^^^^^^^^^^^^^^^^^^^^^^^^^^^^^^
  File "D:\projects\qr\qr\env\scripts\python.py\Lib\site-packages\django\contrib\admin\options.py", line 718, in wrapper
    return self.admin_site.admin_view(view)(*args, **kwargs)
           ^^^^^^^^^^^^^^^^^^^^^^^^^^^^^^^^^^^^^^^^^^^^^^^^^
  File "D:\projects\qr\qr\env\scripts\python.py\Lib\site-packages\django\utils\decorators.py", line 188, in _view_wrapper
    result = _process_exception(request, e)
             ^^^^^^^^^^^^^^^^^^^^^^^^^^^^^^
  File "D:\projects\qr\qr\env\scripts\python.py\Lib\site-packages\django\utils\decorators.py", line 186, in _view_wrapper
    response = view_func(request, *args, **kwargs)
               ^^^^^^^^^^^^^^^^^^^^^^^^^^^^^^^^^^^
  File "D:\projects\qr\qr\env\scripts\python.py\Lib\site-packages\django\views\decorators\cache.py", line 80, in _view_wrapper
    response = view_func(request, *args, **kwargs)
               ^^^^^^^^^^^^^^^^^^^^^^^^^^^^^^^^^^^
  File "D:\projects\qr\qr\env\scripts\python.py\Lib\site-packages\django\contrib\admin\sites.py", line 241, in inner
    return view(request, *args, **kwargs)
           ^^^^^^^^^^^^^^^^^^^^^^^^^^^^^^
  File "D:\projects\qr\qr\env\scripts\python.py\Lib\site-packages\django\contrib\admin\options.py", line 1959, in add_view
    return self.changeform_view(request, None, form_url, extra_context)
           ^^^^^^^^^^^^^^^^^^^^^^^^^^^^^^^^^^^^^^^^^^^^^^^^^^^^^^^^^^^^
  File "D:\projects\qr\qr\env\scripts\python.py\Lib\site-packages\django\utils\decorators.py", line 48, in _wrapper
    return bound_method(*args, **kwargs)
           ^^^^^^^^^^^^^^^^^^^^^^^^^^^^^
  File "D:\projects\qr\qr\env\scripts\python.py\Lib\site-packages\django\utils\decorators.py", line 188, in _view_wrapper
    result = _process_exception(request, e)
             ^^^^^^^^^^^^^^^^^^^^^^^^^^^^^^
  File "D:\projects\qr\qr\env\scripts\python.py\Lib\site-packages\django\utils\decorators.py", line 186, in _view_wrapper
    response = view_func(request, *args, **kwargs)
               ^^^^^^^^^^^^^^^^^^^^^^^^^^^^^^^^^^^
  File "D:\projects\qr\qr\env\scripts\python.py\Lib\site-packages\django\contrib\admin\options.py", line 1818, in changeform_view
    return self._changeform_view(request, object_id, form_url, extra_context)
           ^^^^^^^^^^^^^^^^^^^^^^^^^^^^^^^^^^^^^^^^^^^^^^^^^^^^^^^^^^^^^^^^^^
  File "D:\projects\qr\qr\env\scripts\python.py\Lib\site-packages\django\contrib\admin\options.py", line 1869, in _changeform_view
    self.save_model(request, new_object, form, not add)
  File "D:\projects\qr\qr\env\scripts\python.py\Lib\site-packages\django\contrib\admin\options.py", line 1292, in save_model
    obj.save()
  File "D:\projects\qr\qr\qr\website\models.py", line 26, in save
    qr_code_image = self.generate_qr_code()
                    ^^^^^^^^^^^^^^^^^^^^^^^
  File "D:\projects\qr\qr\qr\website\models.py", line 33, in generate_qr_code
    domain = Site.objects.get_current().domain
             ^^^^^^^^^^^^^^^^^^^^^^^^^^
  File "D:\projects\qr\qr\env\scripts\python.py\Lib\site-packages\django\contrib\sites\models.py", line 59, in get_current
    return self._get_site_by_id(site_id)
           ^^^^^^^^^^^^^^^^^^^^^^^^^^^^^
  File "D:\projects\qr\qr\env\scripts\python.py\Lib\site-packages\django\contrib\sites\models.py", line 30, in _get_site_by_id
    site = self.get(pk=site_id)
           ^^^^^^^^^^^^^^^^^^^^
  File "D:\projects\qr\qr\env\scripts\python.py\Lib\site-packages\django\db\models\manager.py", line 87, in manager_method
    return getattr(self.get_queryset(), name)(*args, **kwargs)
           ^^^^^^^^^^^^^^^^^^^^^^^^^^^^^^^^^^^^^^^^^^^^^^^^^^^
  File "D:\projects\qr\qr\env\scripts\python.py\Lib\site-packages\django\db\models\query.py", line 645, in get
    num = len(clone)
          ^^^^^^^^^^
  File "D:\projects\qr\qr\env\scripts\python.py\Lib\site-packages\django\db\models\query.py", line 382, in __len__
    self._fetch_all()
  File "D:\projects\qr\qr\env\scripts\python.py\Lib\site-packages\django\db\models\query.py", line 1928, in _fetch_all
    self._result_cache = list(self._iterable_class(self))
                         ^^^^^^^^^^^^^^^^^^^^^^^^^^^^^^^^
  File "D:\projects\qr\qr\env\scripts\python.py\Lib\site-packages\django\db\models\query.py", line 91, in __iter__
    results = compiler.execute_sql(
              ^^^^^^^^^^^^^^^^^^^^^
  File "D:\projects\qr\qr\env\scripts\python.py\Lib\site-packages\django\db\models\sql\compiler.py", line 1574, in execute_sql
    cursor.execute(sql, params)
  File "D:\projects\qr\qr\env\scripts\python.py\Lib\site-packages\django\db\backends\utils.py", line 122, in execute
    return super().execute(sql, params)
           ^^^^^^^^^^^^^^^^^^^^^^^^^^^^
  File "D:\projects\qr\qr\env\scripts\python.py\Lib\site-packages\django\db\backends\utils.py", line 79, in execute
    return self._execute_with_wrappers(
           ^^^^^^^^^^^^^^^^^^^^^^^^^^^^
  File "D:\projects\qr\qr\env\scripts\python.py\Lib\site-packages\django\db\backends\utils.py", line 92, in _execute_with_wrappers
    return executor(sql, params, many, context)
           ^^^^^^^^^^^^^^^^^^^^^^^^^^^^^^^^^^^^
  File "D:\projects\qr\qr\env\scripts\python.py\Lib\site-packages\django\db\backends\utils.py", line 100, in _execute
    with self.db.wrap_database_errors:
         ^^^^^^^^^^^^^^^^^^^^^^^^^^^^
  File "D:\projects\qr\qr\env\scripts\python.py\Lib\site-packages\django\db\utils.py", line 91, in __exit__
    raise dj_exc_value.with_traceback(traceback) from exc_value
  File "D:\projects\qr\qr\env\scripts\python.py\Lib\site-packages\django\db\backends\utils.py", line 105, in _execute
    return self.cursor.execute(sql, params)
           ^^^^^^^^^^^^^^^^^^^^^^^^^^^^^^^^
  File "D:\projects\qr\qr\env\scripts\python.py\Lib\site-packages\django\db\backends\sqlite3\base.py", line 354, in execute
    return super().execute(query, params)
           ^^^^^^^^^^^^^^^^^^^^^^^^^^^^^^
django.db.utils.OperationalError: no such table: django_site
ERROR 2025-03-18 13:37:34,120 D:\projects\qr\qr\env\scripts\python.py\Lib\site-packages\django\core\servers\basehttp.py:213 "POST /admin/website/image/add/ HTTP/1.1" 500 214339
ERROR 2025-03-18 14:09:25,928 D:\projects\qr\qr\env\scripts\python.py\Lib\site-packages\django\utils\log.py:248 Internal Server Error: /
Traceback (most recent call last):
  File "D:\projects\qr\qr\env\scripts\python.py\Lib\site-packages\django\core\handlers\exception.py", line 55, in inner
    response = get_response(request)
               ^^^^^^^^^^^^^^^^^^^^^
  File "D:\projects\qr\qr\env\scripts\python.py\Lib\site-packages\django\core\handlers\base.py", line 197, in _get_response
    response = wrapped_callback(request, *callback_args, **callback_kwargs)
               ^^^^^^^^^^^^^^^^^^^^^^^^^^^^^^^^^^^^^^^^^^^^^^^^^^^^^^^^^^^^
  File "D:\projects\qr\qr\qr\website\views.py", line 22, in home
    return render(request, 'website/pages/index.html', context)
           ^^^^^^^^^^^^^^^^^^^^^^^^^^^^^^^^^^^^^^^^^^^^^^^^^^^^
  File "D:\projects\qr\qr\env\scripts\python.py\Lib\site-packages\django\shortcuts.py", line 25, in render
    content = loader.render_to_string(template_name, context, request, using=using)
              ^^^^^^^^^^^^^^^^^^^^^^^^^^^^^^^^^^^^^^^^^^^^^^^^^^^^^^^^^^^^^^^^^^^^^
  File "D:\projects\qr\qr\env\scripts\python.py\Lib\site-packages\django\template\loader.py", line 62, in render_to_string
    return template.render(context, request)
           ^^^^^^^^^^^^^^^^^^^^^^^^^^^^^^^^^
  File "D:\projects\qr\qr\env\scripts\python.py\Lib\site-packages\django\template\backends\django.py", line 107, in render
    return self.template.render(context)
           ^^^^^^^^^^^^^^^^^^^^^^^^^^^^^
  File "D:\projects\qr\qr\env\scripts\python.py\Lib\site-packages\django\template\base.py", line 171, in render
    return self._render(context)
           ^^^^^^^^^^^^^^^^^^^^^
  File "D:\projects\qr\qr\env\scripts\python.py\Lib\site-packages\django\template\base.py", line 163, in _render
    return self.nodelist.render(context)
           ^^^^^^^^^^^^^^^^^^^^^^^^^^^^^
  File "D:\projects\qr\qr\env\scripts\python.py\Lib\site-packages\django\template\base.py", line 1008, in render
    return SafeString("".join([node.render_annotated(context) for node in self]))
                               ^^^^^^^^^^^^^^^^^^^^^^^^^^^^^^
  File "D:\projects\qr\qr\env\scripts\python.py\Lib\site-packages\django\template\base.py", line 969, in render_annotated
    return self.render(context)
           ^^^^^^^^^^^^^^^^^^^^
  File "D:\projects\qr\qr\env\scripts\python.py\Lib\site-packages\django\template\loader_tags.py", line 134, in render
    compiled_parent = self.get_parent(context)
                      ^^^^^^^^^^^^^^^^^^^^^^^^
  File "D:\projects\qr\qr\env\scripts\python.py\Lib\site-packages\django\template\loader_tags.py", line 131, in get_parent
    return self.find_template(parent, context)
           ^^^^^^^^^^^^^^^^^^^^^^^^^^^^^^^^^^^
  File "D:\projects\qr\qr\env\scripts\python.py\Lib\site-packages\django\template\loader_tags.py", line 109, in find_template
    template, origin = context.template.engine.find_template(
                       ^^^^^^^^^^^^^^^^^^^^^^^^^^^^^^^^^^^^^^
  File "D:\projects\qr\qr\env\scripts\python.py\Lib\site-packages\django\template\engine.py", line 159, in find_template
    template = loader.get_template(name, skip=skip)
               ^^^^^^^^^^^^^^^^^^^^^^^^^^^^^^^^^^^^
  File "D:\projects\qr\qr\env\scripts\python.py\Lib\site-packages\django\template\loaders\cached.py", line 57, in get_template
    template = super().get_template(template_name, skip)
               ^^^^^^^^^^^^^^^^^^^^^^^^^^^^^^^^^^^^^^^^^
  File "D:\projects\qr\qr\env\scripts\python.py\Lib\site-packages\django\template\loaders\base.py", line 28, in get_template
    return Template(
           ^^^^^^^^^
  File "D:\projects\qr\qr\env\scripts\python.py\Lib\site-packages\django\template\base.py", line 154, in __init__
    self.nodelist = self.compile_nodelist()
                    ^^^^^^^^^^^^^^^^^^^^^^^
  File "D:\projects\qr\qr\env\scripts\python.py\Lib\site-packages\django\template\base.py", line 196, in compile_nodelist
    nodelist = parser.parse()
               ^^^^^^^^^^^^^^
  File "D:\projects\qr\qr\env\scripts\python.py\Lib\site-packages\django\template\base.py", line 518, in parse
    raise self.error(token, e)
  File "D:\projects\qr\qr\env\scripts\python.py\Lib\site-packages\django\template\base.py", line 516, in parse
    compiled_result = compile_func(self, token)
                      ^^^^^^^^^^^^^^^^^^^^^^^^^
  File "D:\projects\qr\qr\env\scripts\python.py\Lib\site-packages\django\template\loader_tags.py", line 228, in do_block
    raise TemplateSyntaxError(
django.template.exceptions.TemplateSyntaxError: 'block' tag with name 'content' appears more than once
ERROR 2025-03-18 14:09:25,934 D:\projects\qr\qr\env\scripts\python.py\Lib\site-packages\django\core\servers\basehttp.py:213 "GET / HTTP/1.1" 500 163879
ERROR 2025-03-18 14:14:42,602 D:\projects\qr\qr\env\scripts\python.py\Lib\site-packages\django\utils\log.py:248 Internal Server Error: /
Traceback (most recent call last):
  File "D:\projects\qr\qr\env\scripts\python.py\Lib\site-packages\django\core\handlers\exception.py", line 55, in inner
    response = get_response(request)
               ^^^^^^^^^^^^^^^^^^^^^
  File "D:\projects\qr\qr\env\scripts\python.py\Lib\site-packages\django\core\handlers\base.py", line 197, in _get_response
    response = wrapped_callback(request, *callback_args, **callback_kwargs)
               ^^^^^^^^^^^^^^^^^^^^^^^^^^^^^^^^^^^^^^^^^^^^^^^^^^^^^^^^^^^^
  File "D:\projects\qr\qr\qr\website\views.py", line 22, in home
    return render(request, 'website/pages/index.html', context)
           ^^^^^^^^^^^^^^^^^^^^^^^^^^^^^^^^^^^^^^^^^^^^^^^^^^^^
  File "D:\projects\qr\qr\env\scripts\python.py\Lib\site-packages\django\shortcuts.py", line 25, in render
    content = loader.render_to_string(template_name, context, request, using=using)
              ^^^^^^^^^^^^^^^^^^^^^^^^^^^^^^^^^^^^^^^^^^^^^^^^^^^^^^^^^^^^^^^^^^^^^
  File "D:\projects\qr\qr\env\scripts\python.py\Lib\site-packages\django\template\loader.py", line 62, in render_to_string
    return template.render(context, request)
           ^^^^^^^^^^^^^^^^^^^^^^^^^^^^^^^^^
  File "D:\projects\qr\qr\env\scripts\python.py\Lib\site-packages\django\template\backends\django.py", line 107, in render
    return self.template.render(context)
           ^^^^^^^^^^^^^^^^^^^^^^^^^^^^^
  File "D:\projects\qr\qr\env\scripts\python.py\Lib\site-packages\django\template\base.py", line 171, in render
    return self._render(context)
           ^^^^^^^^^^^^^^^^^^^^^
  File "D:\projects\qr\qr\env\scripts\python.py\Lib\site-packages\django\template\base.py", line 163, in _render
    return self.nodelist.render(context)
           ^^^^^^^^^^^^^^^^^^^^^^^^^^^^^
  File "D:\projects\qr\qr\env\scripts\python.py\Lib\site-packages\django\template\base.py", line 1008, in render
    return SafeString("".join([node.render_annotated(context) for node in self]))
                               ^^^^^^^^^^^^^^^^^^^^^^^^^^^^^^
  File "D:\projects\qr\qr\env\scripts\python.py\Lib\site-packages\django\template\base.py", line 969, in render_annotated
    return self.render(context)
           ^^^^^^^^^^^^^^^^^^^^
  File "D:\projects\qr\qr\env\scripts\python.py\Lib\site-packages\django\template\loader_tags.py", line 159, in render
    return compiled_parent._render(context)
           ^^^^^^^^^^^^^^^^^^^^^^^^^^^^^^^^
  File "D:\projects\qr\qr\env\scripts\python.py\Lib\site-packages\django\template\base.py", line 163, in _render
    return self.nodelist.render(context)
           ^^^^^^^^^^^^^^^^^^^^^^^^^^^^^
  File "D:\projects\qr\qr\env\scripts\python.py\Lib\site-packages\django\template\base.py", line 1008, in render
    return SafeString("".join([node.render_annotated(context) for node in self]))
                               ^^^^^^^^^^^^^^^^^^^^^^^^^^^^^^
  File "D:\projects\qr\qr\env\scripts\python.py\Lib\site-packages\django\template\base.py", line 969, in render_annotated
    return self.render(context)
           ^^^^^^^^^^^^^^^^^^^^
  File "D:\projects\qr\qr\env\scripts\python.py\Lib\site-packages\django\template\defaulttags.py", line 480, in render
    url = reverse(view_name, args=args, kwargs=kwargs, current_app=current_app)
          ^^^^^^^^^^^^^^^^^^^^^^^^^^^^^^^^^^^^^^^^^^^^^^^^^^^^^^^^^^^^^^^^^^^^^
  File "D:\projects\qr\qr\env\scripts\python.py\Lib\site-packages\django\urls\base.py", line 88, in reverse
    return resolver._reverse_with_prefix(view, prefix, *args, **kwargs)
           ^^^^^^^^^^^^^^^^^^^^^^^^^^^^^^^^^^^^^^^^^^^^^^^^^^^^^^^^^^^^
  File "D:\projects\qr\qr\env\scripts\python.py\Lib\site-packages\django\urls\resolvers.py", line 831, in _reverse_with_prefix
    raise NoReverseMatch(msg)
django.urls.exceptions.NoReverseMatch: Reverse for 'admin' not found. 'admin' is not a valid view function or pattern name.
ERROR 2025-03-18 14:14:42,605 D:\projects\qr\qr\env\scripts\python.py\Lib\site-packages\django\core\servers\basehttp.py:213 "GET / HTTP/1.1" 500 138351
ERROR 2025-03-18 14:14:57,637 D:\projects\qr\qr\env\scripts\python.py\Lib\site-packages\django\utils\log.py:248 Internal Server Error: /
Traceback (most recent call last):
  File "D:\projects\qr\qr\env\scripts\python.py\Lib\site-packages\django\core\handlers\exception.py", line 55, in inner
    response = get_response(request)
               ^^^^^^^^^^^^^^^^^^^^^
  File "D:\projects\qr\qr\env\scripts\python.py\Lib\site-packages\django\core\handlers\base.py", line 197, in _get_response
    response = wrapped_callback(request, *callback_args, **callback_kwargs)
               ^^^^^^^^^^^^^^^^^^^^^^^^^^^^^^^^^^^^^^^^^^^^^^^^^^^^^^^^^^^^
  File "D:\projects\qr\qr\qr\website\views.py", line 22, in home
    return render(request, 'website/pages/index.html', context)
           ^^^^^^^^^^^^^^^^^^^^^^^^^^^^^^^^^^^^^^^^^^^^^^^^^^^^
  File "D:\projects\qr\qr\env\scripts\python.py\Lib\site-packages\django\shortcuts.py", line 25, in render
    content = loader.render_to_string(template_name, context, request, using=using)
              ^^^^^^^^^^^^^^^^^^^^^^^^^^^^^^^^^^^^^^^^^^^^^^^^^^^^^^^^^^^^^^^^^^^^^
  File "D:\projects\qr\qr\env\scripts\python.py\Lib\site-packages\django\template\loader.py", line 62, in render_to_string
    return template.render(context, request)
           ^^^^^^^^^^^^^^^^^^^^^^^^^^^^^^^^^
  File "D:\projects\qr\qr\env\scripts\python.py\Lib\site-packages\django\template\backends\django.py", line 107, in render
    return self.template.render(context)
           ^^^^^^^^^^^^^^^^^^^^^^^^^^^^^
  File "D:\projects\qr\qr\env\scripts\python.py\Lib\site-packages\django\template\base.py", line 171, in render
    return self._render(context)
           ^^^^^^^^^^^^^^^^^^^^^
  File "D:\projects\qr\qr\env\scripts\python.py\Lib\site-packages\django\template\base.py", line 163, in _render
    return self.nodelist.render(context)
           ^^^^^^^^^^^^^^^^^^^^^^^^^^^^^
  File "D:\projects\qr\qr\env\scripts\python.py\Lib\site-packages\django\template\base.py", line 1008, in render
    return SafeString("".join([node.render_annotated(context) for node in self]))
                               ^^^^^^^^^^^^^^^^^^^^^^^^^^^^^^
  File "D:\projects\qr\qr\env\scripts\python.py\Lib\site-packages\django\template\base.py", line 969, in render_annotated
    return self.render(context)
           ^^^^^^^^^^^^^^^^^^^^
  File "D:\projects\qr\qr\env\scripts\python.py\Lib\site-packages\django\template\loader_tags.py", line 159, in render
    return compiled_parent._render(context)
           ^^^^^^^^^^^^^^^^^^^^^^^^^^^^^^^^
  File "D:\projects\qr\qr\env\scripts\python.py\Lib\site-packages\django\template\base.py", line 163, in _render
    return self.nodelist.render(context)
           ^^^^^^^^^^^^^^^^^^^^^^^^^^^^^
  File "D:\projects\qr\qr\env\scripts\python.py\Lib\site-packages\django\template\base.py", line 1008, in render
    return SafeString("".join([node.render_annotated(context) for node in self]))
                               ^^^^^^^^^^^^^^^^^^^^^^^^^^^^^^
  File "D:\projects\qr\qr\env\scripts\python.py\Lib\site-packages\django\template\base.py", line 969, in render_annotated
    return self.render(context)
           ^^^^^^^^^^^^^^^^^^^^
  File "D:\projects\qr\qr\env\scripts\python.py\Lib\site-packages\django\template\defaulttags.py", line 480, in render
    url = reverse(view_name, args=args, kwargs=kwargs, current_app=current_app)
          ^^^^^^^^^^^^^^^^^^^^^^^^^^^^^^^^^^^^^^^^^^^^^^^^^^^^^^^^^^^^^^^^^^^^^
  File "D:\projects\qr\qr\env\scripts\python.py\Lib\site-packages\django\urls\base.py", line 88, in reverse
    return resolver._reverse_with_prefix(view, prefix, *args, **kwargs)
           ^^^^^^^^^^^^^^^^^^^^^^^^^^^^^^^^^^^^^^^^^^^^^^^^^^^^^^^^^^^^
  File "D:\projects\qr\qr\env\scripts\python.py\Lib\site-packages\django\urls\resolvers.py", line 831, in _reverse_with_prefix
    raise NoReverseMatch(msg)
django.urls.exceptions.NoReverseMatch: Reverse for 'admin' not found. 'admin' is not a valid view function or pattern name.
ERROR 2025-03-18 14:14:57,641 D:\projects\qr\qr\env\scripts\python.py\Lib\site-packages\django\core\servers\basehttp.py:213 "GET / HTTP/1.1" 500 138482
ERROR 2025-03-18 14:14:57,893 D:\projects\qr\qr\env\scripts\python.py\Lib\site-packages\django\utils\log.py:248 Internal Server Error: /
Traceback (most recent call last):
  File "D:\projects\qr\qr\env\scripts\python.py\Lib\site-packages\django\core\handlers\exception.py", line 55, in inner
    response = get_response(request)
               ^^^^^^^^^^^^^^^^^^^^^
  File "D:\projects\qr\qr\env\scripts\python.py\Lib\site-packages\django\core\handlers\base.py", line 197, in _get_response
    response = wrapped_callback(request, *callback_args, **callback_kwargs)
               ^^^^^^^^^^^^^^^^^^^^^^^^^^^^^^^^^^^^^^^^^^^^^^^^^^^^^^^^^^^^
  File "D:\projects\qr\qr\qr\website\views.py", line 22, in home
    return render(request, 'website/pages/index.html', context)
           ^^^^^^^^^^^^^^^^^^^^^^^^^^^^^^^^^^^^^^^^^^^^^^^^^^^^
  File "D:\projects\qr\qr\env\scripts\python.py\Lib\site-packages\django\shortcuts.py", line 25, in render
    content = loader.render_to_string(template_name, context, request, using=using)
              ^^^^^^^^^^^^^^^^^^^^^^^^^^^^^^^^^^^^^^^^^^^^^^^^^^^^^^^^^^^^^^^^^^^^^
  File "D:\projects\qr\qr\env\scripts\python.py\Lib\site-packages\django\template\loader.py", line 62, in render_to_string
    return template.render(context, request)
           ^^^^^^^^^^^^^^^^^^^^^^^^^^^^^^^^^
  File "D:\projects\qr\qr\env\scripts\python.py\Lib\site-packages\django\template\backends\django.py", line 107, in render
    return self.template.render(context)
           ^^^^^^^^^^^^^^^^^^^^^^^^^^^^^
  File "D:\projects\qr\qr\env\scripts\python.py\Lib\site-packages\django\template\base.py", line 171, in render
    return self._render(context)
           ^^^^^^^^^^^^^^^^^^^^^
  File "D:\projects\qr\qr\env\scripts\python.py\Lib\site-packages\django\template\base.py", line 163, in _render
    return self.nodelist.render(context)
           ^^^^^^^^^^^^^^^^^^^^^^^^^^^^^
  File "D:\projects\qr\qr\env\scripts\python.py\Lib\site-packages\django\template\base.py", line 1008, in render
    return SafeString("".join([node.render_annotated(context) for node in self]))
                               ^^^^^^^^^^^^^^^^^^^^^^^^^^^^^^
  File "D:\projects\qr\qr\env\scripts\python.py\Lib\site-packages\django\template\base.py", line 969, in render_annotated
    return self.render(context)
           ^^^^^^^^^^^^^^^^^^^^
  File "D:\projects\qr\qr\env\scripts\python.py\Lib\site-packages\django\template\loader_tags.py", line 159, in render
    return compiled_parent._render(context)
           ^^^^^^^^^^^^^^^^^^^^^^^^^^^^^^^^
  File "D:\projects\qr\qr\env\scripts\python.py\Lib\site-packages\django\template\base.py", line 163, in _render
    return self.nodelist.render(context)
           ^^^^^^^^^^^^^^^^^^^^^^^^^^^^^
  File "D:\projects\qr\qr\env\scripts\python.py\Lib\site-packages\django\template\base.py", line 1008, in render
    return SafeString("".join([node.render_annotated(context) for node in self]))
                               ^^^^^^^^^^^^^^^^^^^^^^^^^^^^^^
  File "D:\projects\qr\qr\env\scripts\python.py\Lib\site-packages\django\template\base.py", line 969, in render_annotated
    return self.render(context)
           ^^^^^^^^^^^^^^^^^^^^
  File "D:\projects\qr\qr\env\scripts\python.py\Lib\site-packages\django\template\defaulttags.py", line 480, in render
    url = reverse(view_name, args=args, kwargs=kwargs, current_app=current_app)
          ^^^^^^^^^^^^^^^^^^^^^^^^^^^^^^^^^^^^^^^^^^^^^^^^^^^^^^^^^^^^^^^^^^^^^
  File "D:\projects\qr\qr\env\scripts\python.py\Lib\site-packages\django\urls\base.py", line 88, in reverse
    return resolver._reverse_with_prefix(view, prefix, *args, **kwargs)
           ^^^^^^^^^^^^^^^^^^^^^^^^^^^^^^^^^^^^^^^^^^^^^^^^^^^^^^^^^^^^
  File "D:\projects\qr\qr\env\scripts\python.py\Lib\site-packages\django\urls\resolvers.py", line 831, in _reverse_with_prefix
    raise NoReverseMatch(msg)
django.urls.exceptions.NoReverseMatch: Reverse for 'admin' not found. 'admin' is not a valid view function or pattern name.
ERROR 2025-03-18 14:14:57,896 D:\projects\qr\qr\env\scripts\python.py\Lib\site-packages\django\core\servers\basehttp.py:213 "GET / HTTP/1.1" 500 138482
ERROR 2025-03-18 14:14:58,972 D:\projects\qr\qr\env\scripts\python.py\Lib\site-packages\django\utils\log.py:248 Internal Server Error: /
Traceback (most recent call last):
  File "D:\projects\qr\qr\env\scripts\python.py\Lib\site-packages\django\core\handlers\exception.py", line 55, in inner
    response = get_response(request)
               ^^^^^^^^^^^^^^^^^^^^^
  File "D:\projects\qr\qr\env\scripts\python.py\Lib\site-packages\django\core\handlers\base.py", line 197, in _get_response
    response = wrapped_callback(request, *callback_args, **callback_kwargs)
               ^^^^^^^^^^^^^^^^^^^^^^^^^^^^^^^^^^^^^^^^^^^^^^^^^^^^^^^^^^^^
  File "D:\projects\qr\qr\qr\website\views.py", line 22, in home
    return render(request, 'website/pages/index.html', context)
           ^^^^^^^^^^^^^^^^^^^^^^^^^^^^^^^^^^^^^^^^^^^^^^^^^^^^
  File "D:\projects\qr\qr\env\scripts\python.py\Lib\site-packages\django\shortcuts.py", line 25, in render
    content = loader.render_to_string(template_name, context, request, using=using)
              ^^^^^^^^^^^^^^^^^^^^^^^^^^^^^^^^^^^^^^^^^^^^^^^^^^^^^^^^^^^^^^^^^^^^^
  File "D:\projects\qr\qr\env\scripts\python.py\Lib\site-packages\django\template\loader.py", line 62, in render_to_string
    return template.render(context, request)
           ^^^^^^^^^^^^^^^^^^^^^^^^^^^^^^^^^
  File "D:\projects\qr\qr\env\scripts\python.py\Lib\site-packages\django\template\backends\django.py", line 107, in render
    return self.template.render(context)
           ^^^^^^^^^^^^^^^^^^^^^^^^^^^^^
  File "D:\projects\qr\qr\env\scripts\python.py\Lib\site-packages\django\template\base.py", line 171, in render
    return self._render(context)
           ^^^^^^^^^^^^^^^^^^^^^
  File "D:\projects\qr\qr\env\scripts\python.py\Lib\site-packages\django\template\base.py", line 163, in _render
    return self.nodelist.render(context)
           ^^^^^^^^^^^^^^^^^^^^^^^^^^^^^
  File "D:\projects\qr\qr\env\scripts\python.py\Lib\site-packages\django\template\base.py", line 1008, in render
    return SafeString("".join([node.render_annotated(context) for node in self]))
                               ^^^^^^^^^^^^^^^^^^^^^^^^^^^^^^
  File "D:\projects\qr\qr\env\scripts\python.py\Lib\site-packages\django\template\base.py", line 969, in render_annotated
    return self.render(context)
           ^^^^^^^^^^^^^^^^^^^^
  File "D:\projects\qr\qr\env\scripts\python.py\Lib\site-packages\django\template\loader_tags.py", line 159, in render
    return compiled_parent._render(context)
           ^^^^^^^^^^^^^^^^^^^^^^^^^^^^^^^^
  File "D:\projects\qr\qr\env\scripts\python.py\Lib\site-packages\django\template\base.py", line 163, in _render
    return self.nodelist.render(context)
           ^^^^^^^^^^^^^^^^^^^^^^^^^^^^^
  File "D:\projects\qr\qr\env\scripts\python.py\Lib\site-packages\django\template\base.py", line 1008, in render
    return SafeString("".join([node.render_annotated(context) for node in self]))
                               ^^^^^^^^^^^^^^^^^^^^^^^^^^^^^^
  File "D:\projects\qr\qr\env\scripts\python.py\Lib\site-packages\django\template\base.py", line 969, in render_annotated
    return self.render(context)
           ^^^^^^^^^^^^^^^^^^^^
  File "D:\projects\qr\qr\env\scripts\python.py\Lib\site-packages\django\template\defaulttags.py", line 480, in render
    url = reverse(view_name, args=args, kwargs=kwargs, current_app=current_app)
          ^^^^^^^^^^^^^^^^^^^^^^^^^^^^^^^^^^^^^^^^^^^^^^^^^^^^^^^^^^^^^^^^^^^^^
  File "D:\projects\qr\qr\env\scripts\python.py\Lib\site-packages\django\urls\base.py", line 88, in reverse
    return resolver._reverse_with_prefix(view, prefix, *args, **kwargs)
           ^^^^^^^^^^^^^^^^^^^^^^^^^^^^^^^^^^^^^^^^^^^^^^^^^^^^^^^^^^^^
  File "D:\projects\qr\qr\env\scripts\python.py\Lib\site-packages\django\urls\resolvers.py", line 831, in _reverse_with_prefix
    raise NoReverseMatch(msg)
django.urls.exceptions.NoReverseMatch: Reverse for 'admin' not found. 'admin' is not a valid view function or pattern name.
ERROR 2025-03-18 14:14:58,975 D:\projects\qr\qr\env\scripts\python.py\Lib\site-packages\django\core\servers\basehttp.py:213 "GET / HTTP/1.1" 500 138482
ERROR 2025-03-18 14:15:15,339 D:\projects\qr\qr\env\scripts\python.py\Lib\site-packages\django\utils\log.py:248 Internal Server Error: /
Traceback (most recent call last):
  File "D:\projects\qr\qr\env\scripts\python.py\Lib\site-packages\django\core\handlers\exception.py", line 55, in inner
    response = get_response(request)
               ^^^^^^^^^^^^^^^^^^^^^
  File "D:\projects\qr\qr\env\scripts\python.py\Lib\site-packages\django\core\handlers\base.py", line 197, in _get_response
    response = wrapped_callback(request, *callback_args, **callback_kwargs)
               ^^^^^^^^^^^^^^^^^^^^^^^^^^^^^^^^^^^^^^^^^^^^^^^^^^^^^^^^^^^^
  File "D:\projects\qr\qr\qr\website\views.py", line 22, in home
    return render(request, 'website/pages/index.html', context)
           ^^^^^^^^^^^^^^^^^^^^^^^^^^^^^^^^^^^^^^^^^^^^^^^^^^^^
  File "D:\projects\qr\qr\env\scripts\python.py\Lib\site-packages\django\shortcuts.py", line 25, in render
    content = loader.render_to_string(template_name, context, request, using=using)
              ^^^^^^^^^^^^^^^^^^^^^^^^^^^^^^^^^^^^^^^^^^^^^^^^^^^^^^^^^^^^^^^^^^^^^
  File "D:\projects\qr\qr\env\scripts\python.py\Lib\site-packages\django\template\loader.py", line 62, in render_to_string
    return template.render(context, request)
           ^^^^^^^^^^^^^^^^^^^^^^^^^^^^^^^^^
  File "D:\projects\qr\qr\env\scripts\python.py\Lib\site-packages\django\template\backends\django.py", line 107, in render
    return self.template.render(context)
           ^^^^^^^^^^^^^^^^^^^^^^^^^^^^^
  File "D:\projects\qr\qr\env\scripts\python.py\Lib\site-packages\django\template\base.py", line 171, in render
    return self._render(context)
           ^^^^^^^^^^^^^^^^^^^^^
  File "D:\projects\qr\qr\env\scripts\python.py\Lib\site-packages\django\template\base.py", line 163, in _render
    return self.nodelist.render(context)
           ^^^^^^^^^^^^^^^^^^^^^^^^^^^^^
  File "D:\projects\qr\qr\env\scripts\python.py\Lib\site-packages\django\template\base.py", line 1008, in render
    return SafeString("".join([node.render_annotated(context) for node in self]))
                               ^^^^^^^^^^^^^^^^^^^^^^^^^^^^^^
  File "D:\projects\qr\qr\env\scripts\python.py\Lib\site-packages\django\template\base.py", line 969, in render_annotated
    return self.render(context)
           ^^^^^^^^^^^^^^^^^^^^
  File "D:\projects\qr\qr\env\scripts\python.py\Lib\site-packages\django\template\loader_tags.py", line 159, in render
    return compiled_parent._render(context)
           ^^^^^^^^^^^^^^^^^^^^^^^^^^^^^^^^
  File "D:\projects\qr\qr\env\scripts\python.py\Lib\site-packages\django\template\base.py", line 163, in _render
    return self.nodelist.render(context)
           ^^^^^^^^^^^^^^^^^^^^^^^^^^^^^
  File "D:\projects\qr\qr\env\scripts\python.py\Lib\site-packages\django\template\base.py", line 1008, in render
    return SafeString("".join([node.render_annotated(context) for node in self]))
                               ^^^^^^^^^^^^^^^^^^^^^^^^^^^^^^
  File "D:\projects\qr\qr\env\scripts\python.py\Lib\site-packages\django\template\base.py", line 969, in render_annotated
    return self.render(context)
           ^^^^^^^^^^^^^^^^^^^^
  File "D:\projects\qr\qr\env\scripts\python.py\Lib\site-packages\django\template\defaulttags.py", line 480, in render
    url = reverse(view_name, args=args, kwargs=kwargs, current_app=current_app)
          ^^^^^^^^^^^^^^^^^^^^^^^^^^^^^^^^^^^^^^^^^^^^^^^^^^^^^^^^^^^^^^^^^^^^^
  File "D:\projects\qr\qr\env\scripts\python.py\Lib\site-packages\django\urls\base.py", line 88, in reverse
    return resolver._reverse_with_prefix(view, prefix, *args, **kwargs)
           ^^^^^^^^^^^^^^^^^^^^^^^^^^^^^^^^^^^^^^^^^^^^^^^^^^^^^^^^^^^^
  File "D:\projects\qr\qr\env\scripts\python.py\Lib\site-packages\django\urls\resolvers.py", line 831, in _reverse_with_prefix
    raise NoReverseMatch(msg)
django.urls.exceptions.NoReverseMatch: Reverse for '/admin' not found. '/admin' is not a valid view function or pattern name.
ERROR 2025-03-18 14:15:15,341 D:\projects\qr\qr\env\scripts\python.py\Lib\site-packages\django\core\servers\basehttp.py:213 "GET / HTTP/1.1" 500 138375
ERROR 2025-03-18 14:15:16,846 D:\projects\qr\qr\env\scripts\python.py\Lib\site-packages\django\utils\log.py:248 Internal Server Error: /
Traceback (most recent call last):
  File "D:\projects\qr\qr\env\scripts\python.py\Lib\site-packages\django\core\handlers\exception.py", line 55, in inner
    response = get_response(request)
               ^^^^^^^^^^^^^^^^^^^^^
  File "D:\projects\qr\qr\env\scripts\python.py\Lib\site-packages\django\core\handlers\base.py", line 197, in _get_response
    response = wrapped_callback(request, *callback_args, **callback_kwargs)
               ^^^^^^^^^^^^^^^^^^^^^^^^^^^^^^^^^^^^^^^^^^^^^^^^^^^^^^^^^^^^
  File "D:\projects\qr\qr\qr\website\views.py", line 22, in home
    return render(request, 'website/pages/index.html', context)
           ^^^^^^^^^^^^^^^^^^^^^^^^^^^^^^^^^^^^^^^^^^^^^^^^^^^^
  File "D:\projects\qr\qr\env\scripts\python.py\Lib\site-packages\django\shortcuts.py", line 25, in render
    content = loader.render_to_string(template_name, context, request, using=using)
              ^^^^^^^^^^^^^^^^^^^^^^^^^^^^^^^^^^^^^^^^^^^^^^^^^^^^^^^^^^^^^^^^^^^^^
  File "D:\projects\qr\qr\env\scripts\python.py\Lib\site-packages\django\template\loader.py", line 62, in render_to_string
    return template.render(context, request)
           ^^^^^^^^^^^^^^^^^^^^^^^^^^^^^^^^^
  File "D:\projects\qr\qr\env\scripts\python.py\Lib\site-packages\django\template\backends\django.py", line 107, in render
    return self.template.render(context)
           ^^^^^^^^^^^^^^^^^^^^^^^^^^^^^
  File "D:\projects\qr\qr\env\scripts\python.py\Lib\site-packages\django\template\base.py", line 171, in render
    return self._render(context)
           ^^^^^^^^^^^^^^^^^^^^^
  File "D:\projects\qr\qr\env\scripts\python.py\Lib\site-packages\django\template\base.py", line 163, in _render
    return self.nodelist.render(context)
           ^^^^^^^^^^^^^^^^^^^^^^^^^^^^^
  File "D:\projects\qr\qr\env\scripts\python.py\Lib\site-packages\django\template\base.py", line 1008, in render
    return SafeString("".join([node.render_annotated(context) for node in self]))
                               ^^^^^^^^^^^^^^^^^^^^^^^^^^^^^^
  File "D:\projects\qr\qr\env\scripts\python.py\Lib\site-packages\django\template\base.py", line 969, in render_annotated
    return self.render(context)
           ^^^^^^^^^^^^^^^^^^^^
  File "D:\projects\qr\qr\env\scripts\python.py\Lib\site-packages\django\template\loader_tags.py", line 159, in render
    return compiled_parent._render(context)
           ^^^^^^^^^^^^^^^^^^^^^^^^^^^^^^^^
  File "D:\projects\qr\qr\env\scripts\python.py\Lib\site-packages\django\template\base.py", line 163, in _render
    return self.nodelist.render(context)
           ^^^^^^^^^^^^^^^^^^^^^^^^^^^^^
  File "D:\projects\qr\qr\env\scripts\python.py\Lib\site-packages\django\template\base.py", line 1008, in render
    return SafeString("".join([node.render_annotated(context) for node in self]))
                               ^^^^^^^^^^^^^^^^^^^^^^^^^^^^^^
  File "D:\projects\qr\qr\env\scripts\python.py\Lib\site-packages\django\template\base.py", line 969, in render_annotated
    return self.render(context)
           ^^^^^^^^^^^^^^^^^^^^
  File "D:\projects\qr\qr\env\scripts\python.py\Lib\site-packages\django\template\defaulttags.py", line 480, in render
    url = reverse(view_name, args=args, kwargs=kwargs, current_app=current_app)
          ^^^^^^^^^^^^^^^^^^^^^^^^^^^^^^^^^^^^^^^^^^^^^^^^^^^^^^^^^^^^^^^^^^^^^
  File "D:\projects\qr\qr\env\scripts\python.py\Lib\site-packages\django\urls\base.py", line 88, in reverse
    return resolver._reverse_with_prefix(view, prefix, *args, **kwargs)
           ^^^^^^^^^^^^^^^^^^^^^^^^^^^^^^^^^^^^^^^^^^^^^^^^^^^^^^^^^^^^
  File "D:\projects\qr\qr\env\scripts\python.py\Lib\site-packages\django\urls\resolvers.py", line 831, in _reverse_with_prefix
    raise NoReverseMatch(msg)
django.urls.exceptions.NoReverseMatch: Reverse for '/admin' not found. '/admin' is not a valid view function or pattern name.
ERROR 2025-03-18 14:15:16,849 D:\projects\qr\qr\env\scripts\python.py\Lib\site-packages\django\core\servers\basehttp.py:213 "GET / HTTP/1.1" 500 138506
ERROR 2025-03-18 14:16:14,208 D:\projects\qr\qr\env\scripts\python.py\Lib\site-packages\django\utils\log.py:248 Internal Server Error: /
Traceback (most recent call last):
  File "D:\projects\qr\qr\env\scripts\python.py\Lib\site-packages\django\core\handlers\exception.py", line 55, in inner
    response = get_response(request)
               ^^^^^^^^^^^^^^^^^^^^^
  File "D:\projects\qr\qr\env\scripts\python.py\Lib\site-packages\django\core\handlers\base.py", line 197, in _get_response
    response = wrapped_callback(request, *callback_args, **callback_kwargs)
               ^^^^^^^^^^^^^^^^^^^^^^^^^^^^^^^^^^^^^^^^^^^^^^^^^^^^^^^^^^^^
  File "D:\projects\qr\qr\qr\website\views.py", line 22, in home
    return render(request, 'website/pages/index.html', context)
           ^^^^^^^^^^^^^^^^^^^^^^^^^^^^^^^^^^^^^^^^^^^^^^^^^^^^
  File "D:\projects\qr\qr\env\scripts\python.py\Lib\site-packages\django\shortcuts.py", line 25, in render
    content = loader.render_to_string(template_name, context, request, using=using)
              ^^^^^^^^^^^^^^^^^^^^^^^^^^^^^^^^^^^^^^^^^^^^^^^^^^^^^^^^^^^^^^^^^^^^^
  File "D:\projects\qr\qr\env\scripts\python.py\Lib\site-packages\django\template\loader.py", line 62, in render_to_string
    return template.render(context, request)
           ^^^^^^^^^^^^^^^^^^^^^^^^^^^^^^^^^
  File "D:\projects\qr\qr\env\scripts\python.py\Lib\site-packages\django\template\backends\django.py", line 107, in render
    return self.template.render(context)
           ^^^^^^^^^^^^^^^^^^^^^^^^^^^^^
  File "D:\projects\qr\qr\env\scripts\python.py\Lib\site-packages\django\template\base.py", line 171, in render
    return self._render(context)
           ^^^^^^^^^^^^^^^^^^^^^
  File "D:\projects\qr\qr\env\scripts\python.py\Lib\site-packages\django\template\base.py", line 163, in _render
    return self.nodelist.render(context)
           ^^^^^^^^^^^^^^^^^^^^^^^^^^^^^
  File "D:\projects\qr\qr\env\scripts\python.py\Lib\site-packages\django\template\base.py", line 1008, in render
    return SafeString("".join([node.render_annotated(context) for node in self]))
                               ^^^^^^^^^^^^^^^^^^^^^^^^^^^^^^
  File "D:\projects\qr\qr\env\scripts\python.py\Lib\site-packages\django\template\base.py", line 969, in render_annotated
    return self.render(context)
           ^^^^^^^^^^^^^^^^^^^^
  File "D:\projects\qr\qr\env\scripts\python.py\Lib\site-packages\django\template\loader_tags.py", line 159, in render
    return compiled_parent._render(context)
           ^^^^^^^^^^^^^^^^^^^^^^^^^^^^^^^^
  File "D:\projects\qr\qr\env\scripts\python.py\Lib\site-packages\django\template\base.py", line 163, in _render
    return self.nodelist.render(context)
           ^^^^^^^^^^^^^^^^^^^^^^^^^^^^^
  File "D:\projects\qr\qr\env\scripts\python.py\Lib\site-packages\django\template\base.py", line 1008, in render
    return SafeString("".join([node.render_annotated(context) for node in self]))
                               ^^^^^^^^^^^^^^^^^^^^^^^^^^^^^^
  File "D:\projects\qr\qr\env\scripts\python.py\Lib\site-packages\django\template\base.py", line 969, in render_annotated
    return self.render(context)
           ^^^^^^^^^^^^^^^^^^^^
  File "D:\projects\qr\qr\env\scripts\python.py\Lib\site-packages\django\template\defaulttags.py", line 480, in render
    url = reverse(view_name, args=args, kwargs=kwargs, current_app=current_app)
          ^^^^^^^^^^^^^^^^^^^^^^^^^^^^^^^^^^^^^^^^^^^^^^^^^^^^^^^^^^^^^^^^^^^^^
  File "D:\projects\qr\qr\env\scripts\python.py\Lib\site-packages\django\urls\base.py", line 88, in reverse
    return resolver._reverse_with_prefix(view, prefix, *args, **kwargs)
           ^^^^^^^^^^^^^^^^^^^^^^^^^^^^^^^^^^^^^^^^^^^^^^^^^^^^^^^^^^^^
  File "D:\projects\qr\qr\env\scripts\python.py\Lib\site-packages\django\urls\resolvers.py", line 831, in _reverse_with_prefix
    raise NoReverseMatch(msg)
django.urls.exceptions.NoReverseMatch: Reverse for 'admin' not found. 'admin' is not a valid view function or pattern name.
ERROR 2025-03-18 14:16:14,210 D:\projects\qr\qr\env\scripts\python.py\Lib\site-packages\django\core\servers\basehttp.py:213 "GET / HTTP/1.1" 500 139118
