ERROR 2025-03-18 10:53:09,068 D:\projects\qr\qr\env\scripts\python.py\Lib\site-packages\django\utils\log.py:248 Internal Server Error: /
Traceback (most recent call last):
  File "D:\projects\qr\qr\env\scripts\python.py\Lib\site-packages\django\core\handlers\exception.py", line 55, in inner
    response = get_response(request)
               ^^^^^^^^^^^^^^^^^^^^^
  File "D:\projects\qr\qr\env\scripts\python.py\Lib\site-packages\django\core\handlers\base.py", line 197, in _get_response
    response = wrapped_callback(request, *callback_args, **callback_kwargs)
               ^^^^^^^^^^^^^^^^^^^^^^^^^^^^^^^^^^^^^^^^^^^^^^^^^^^^^^^^^^^^
  File "D:\projects\qr\qr\qr\website\views.py", line 6, in home
    return render(request, 'website/pages/index.html', context)
           ^^^^^^^^^^^^^^^^^^^^^^^^^^^^^^^^^^^^^^^^^^^^^^^^^^^^
  File "D:\projects\qr\qr\env\scripts\python.py\Lib\site-packages\django\shortcuts.py", line 25, in render
    content = loader.render_to_string(template_name, context, request, using=using)
              ^^^^^^^^^^^^^^^^^^^^^^^^^^^^^^^^^^^^^^^^^^^^^^^^^^^^^^^^^^^^^^^^^^^^^
  File "D:\projects\qr\qr\env\scripts\python.py\Lib\site-packages\django\template\loader.py", line 61, in render_to_string
    template = get_template(template_name, using=using)
               ^^^^^^^^^^^^^^^^^^^^^^^^^^^^^^^^^^^^^^^^
  File "D:\projects\qr\qr\env\scripts\python.py\Lib\site-packages\django\template\loader.py", line 19, in get_template
    raise TemplateDoesNotExist(template_name, chain=chain)
django.template.exceptions.TemplateDoesNotExist: website/pages/index.html
ERROR 2025-03-18 10:53:09,101 D:\projects\qr\qr\env\scripts\python.py\Lib\site-packages\django\utils\log.py:248 Internal Server Error: /
Traceback (most recent call last):
  File "D:\projects\qr\qr\env\scripts\python.py\Lib\site-packages\django\urls\base.py", line 71, in reverse
    extra, resolver = resolver.namespace_dict[ns]
                      ~~~~~~~~~~~~~~~~~~~~~~~^^^^
KeyError: 'django_browser_reload'

During handling of the above exception, another exception occurred:

Traceback (most recent call last):
  File "D:\projects\qr\qr\env\scripts\python.py\Lib\site-packages\django\core\handlers\exception.py", line 55, in inner
    response = get_response(request)
               ^^^^^^^^^^^^^^^^^^^^^
  File "D:\projects\qr\qr\env\scripts\python.py\Lib\site-packages\django_browser_reload\middleware.py", line 50, in __call__
    self.maybe_inject(response)
  File "D:\projects\qr\qr\env\scripts\python.py\Lib\site-packages\django_browser_reload\middleware.py", line 82, in maybe_inject
    response.content = head + django_browser_reload_script() + tag + tail
                              ^^^^^^^^^^^^^^^^^^^^^^^^^^^^^^
  File "D:\projects\qr\qr\env\scripts\python.py\Lib\site-packages\django_browser_reload\jinja.py", line 21, in django_browser_reload_script
    reverse("django_browser_reload:events"),
    ^^^^^^^^^^^^^^^^^^^^^^^^^^^^^^^^^^^^^^^
  File "D:\projects\qr\qr\env\scripts\python.py\Lib\site-packages\django\urls\base.py", line 82, in reverse
    raise NoReverseMatch("%s is not a registered namespace" % key)
django.urls.exceptions.NoReverseMatch: 'django_browser_reload' is not a registered namespace
ERROR 2025-03-18 10:53:09,102 D:\projects\qr\qr\env\scripts\python.py\Lib\site-packages\django\core\servers\basehttp.py:213 "GET / HTTP/1.1" 500 93204
ERROR 2025-03-18 10:53:37,193 D:\projects\qr\qr\env\scripts\python.py\Lib\site-packages\django\utils\log.py:248 Internal Server Error: /
Traceback (most recent call last):
  File "D:\projects\qr\qr\env\scripts\python.py\Lib\site-packages\django\core\handlers\exception.py", line 55, in inner
    response = get_response(request)
               ^^^^^^^^^^^^^^^^^^^^^
  File "D:\projects\qr\qr\env\scripts\python.py\Lib\site-packages\django\core\handlers\base.py", line 197, in _get_response
    response = wrapped_callback(request, *callback_args, **callback_kwargs)
               ^^^^^^^^^^^^^^^^^^^^^^^^^^^^^^^^^^^^^^^^^^^^^^^^^^^^^^^^^^^^
  File "D:\projects\qr\qr\qr\website\views.py", line 6, in home
    return render(request, 'website/pages/index.html', context)
           ^^^^^^^^^^^^^^^^^^^^^^^^^^^^^^^^^^^^^^^^^^^^^^^^^^^^
  File "D:\projects\qr\qr\env\scripts\python.py\Lib\site-packages\django\shortcuts.py", line 25, in render
    content = loader.render_to_string(template_name, context, request, using=using)
              ^^^^^^^^^^^^^^^^^^^^^^^^^^^^^^^^^^^^^^^^^^^^^^^^^^^^^^^^^^^^^^^^^^^^^
  File "D:\projects\qr\qr\env\scripts\python.py\Lib\site-packages\django\template\loader.py", line 61, in render_to_string
    template = get_template(template_name, using=using)
               ^^^^^^^^^^^^^^^^^^^^^^^^^^^^^^^^^^^^^^^^
  File "D:\projects\qr\qr\env\scripts\python.py\Lib\site-packages\django\template\loader.py", line 19, in get_template
    raise TemplateDoesNotExist(template_name, chain=chain)
django.template.exceptions.TemplateDoesNotExist: website/pages/index.html
ERROR 2025-03-18 10:53:37,197 D:\projects\qr\qr\env\scripts\python.py\Lib\site-packages\django\core\servers\basehttp.py:213 "GET / HTTP/1.1" 500 83931
ERROR 2025-03-18 10:54:03,459 D:\projects\qr\qr\env\scripts\python.py\Lib\site-packages\django\utils\log.py:248 Internal Server Error: /
Traceback (most recent call last):
  File "D:\projects\qr\qr\env\scripts\python.py\Lib\site-packages\django\core\handlers\exception.py", line 55, in inner
    response = get_response(request)
               ^^^^^^^^^^^^^^^^^^^^^
  File "D:\projects\qr\qr\env\scripts\python.py\Lib\site-packages\django\core\handlers\base.py", line 197, in _get_response
    response = wrapped_callback(request, *callback_args, **callback_kwargs)
               ^^^^^^^^^^^^^^^^^^^^^^^^^^^^^^^^^^^^^^^^^^^^^^^^^^^^^^^^^^^^
  File "D:\projects\qr\qr\qr\website\views.py", line 6, in home
    return render(request, 'website/pages/index.html', context)
           ^^^^^^^^^^^^^^^^^^^^^^^^^^^^^^^^^^^^^^^^^^^^^^^^^^^^
  File "D:\projects\qr\qr\env\scripts\python.py\Lib\site-packages\django\shortcuts.py", line 25, in render
    content = loader.render_to_string(template_name, context, request, using=using)
              ^^^^^^^^^^^^^^^^^^^^^^^^^^^^^^^^^^^^^^^^^^^^^^^^^^^^^^^^^^^^^^^^^^^^^
  File "D:\projects\qr\qr\env\scripts\python.py\Lib\site-packages\django\template\loader.py", line 61, in render_to_string
    template = get_template(template_name, using=using)
               ^^^^^^^^^^^^^^^^^^^^^^^^^^^^^^^^^^^^^^^^
  File "D:\projects\qr\qr\env\scripts\python.py\Lib\site-packages\django\template\loader.py", line 19, in get_template
    raise TemplateDoesNotExist(template_name, chain=chain)
django.template.exceptions.TemplateDoesNotExist: website/pages/index.html
ERROR 2025-03-18 10:54:03,466 D:\projects\qr\qr\env\scripts\python.py\Lib\site-packages\django\core\servers\basehttp.py:213 "GET / HTTP/1.1" 500 83951
ERROR 2025-03-18 10:54:05,096 D:\projects\qr\qr\env\scripts\python.py\Lib\site-packages\django\utils\log.py:248 Internal Server Error: /
Traceback (most recent call last):
  File "D:\projects\qr\qr\env\scripts\python.py\Lib\site-packages\django\core\handlers\exception.py", line 55, in inner
    response = get_response(request)
               ^^^^^^^^^^^^^^^^^^^^^
  File "D:\projects\qr\qr\env\scripts\python.py\Lib\site-packages\django\core\handlers\base.py", line 197, in _get_response
    response = wrapped_callback(request, *callback_args, **callback_kwargs)
               ^^^^^^^^^^^^^^^^^^^^^^^^^^^^^^^^^^^^^^^^^^^^^^^^^^^^^^^^^^^^
  File "D:\projects\qr\qr\qr\website\views.py", line 6, in home
    return render(request, 'website/pages/index.html', context)
           ^^^^^^^^^^^^^^^^^^^^^^^^^^^^^^^^^^^^^^^^^^^^^^^^^^^^
  File "D:\projects\qr\qr\env\scripts\python.py\Lib\site-packages\django\shortcuts.py", line 25, in render
    content = loader.render_to_string(template_name, context, request, using=using)
              ^^^^^^^^^^^^^^^^^^^^^^^^^^^^^^^^^^^^^^^^^^^^^^^^^^^^^^^^^^^^^^^^^^^^^
  File "D:\projects\qr\qr\env\scripts\python.py\Lib\site-packages\django\template\loader.py", line 61, in render_to_string
    template = get_template(template_name, using=using)
               ^^^^^^^^^^^^^^^^^^^^^^^^^^^^^^^^^^^^^^^^
  File "D:\projects\qr\qr\env\scripts\python.py\Lib\site-packages\django\template\loader.py", line 19, in get_template
    raise TemplateDoesNotExist(template_name, chain=chain)
django.template.exceptions.TemplateDoesNotExist: website/pages/index.html
ERROR 2025-03-18 10:54:05,096 D:\projects\qr\qr\env\scripts\python.py\Lib\site-packages\django\core\servers\basehttp.py:213 "GET / HTTP/1.1" 500 84082
ERROR 2025-03-18 10:54:05,824 D:\projects\qr\qr\env\scripts\python.py\Lib\site-packages\django\utils\log.py:248 Internal Server Error: /
Traceback (most recent call last):
  File "D:\projects\qr\qr\env\scripts\python.py\Lib\site-packages\django\core\handlers\exception.py", line 55, in inner
    response = get_response(request)
               ^^^^^^^^^^^^^^^^^^^^^
  File "D:\projects\qr\qr\env\scripts\python.py\Lib\site-packages\django\core\handlers\base.py", line 197, in _get_response
    response = wrapped_callback(request, *callback_args, **callback_kwargs)
               ^^^^^^^^^^^^^^^^^^^^^^^^^^^^^^^^^^^^^^^^^^^^^^^^^^^^^^^^^^^^
  File "D:\projects\qr\qr\qr\website\views.py", line 6, in home
    return render(request, 'website/pages/index.html', context)
           ^^^^^^^^^^^^^^^^^^^^^^^^^^^^^^^^^^^^^^^^^^^^^^^^^^^^
  File "D:\projects\qr\qr\env\scripts\python.py\Lib\site-packages\django\shortcuts.py", line 25, in render
    content = loader.render_to_string(template_name, context, request, using=using)
              ^^^^^^^^^^^^^^^^^^^^^^^^^^^^^^^^^^^^^^^^^^^^^^^^^^^^^^^^^^^^^^^^^^^^^
  File "D:\projects\qr\qr\env\scripts\python.py\Lib\site-packages\django\template\loader.py", line 61, in render_to_string
    template = get_template(template_name, using=using)
               ^^^^^^^^^^^^^^^^^^^^^^^^^^^^^^^^^^^^^^^^
  File "D:\projects\qr\qr\env\scripts\python.py\Lib\site-packages\django\template\loader.py", line 19, in get_template
    raise TemplateDoesNotExist(template_name, chain=chain)
django.template.exceptions.TemplateDoesNotExist: website/pages/index.html
ERROR 2025-03-18 10:54:05,825 D:\projects\qr\qr\env\scripts\python.py\Lib\site-packages\django\core\servers\basehttp.py:213 "GET / HTTP/1.1" 500 84210
ERROR 2025-03-18 10:54:55,691 D:\projects\qr\qr\env\scripts\python.py\Lib\site-packages\django\utils\log.py:248 Internal Server Error: /
Traceback (most recent call last):
  File "D:\projects\qr\qr\env\scripts\python.py\Lib\site-packages\django\core\handlers\exception.py", line 55, in inner
    response = get_response(request)
               ^^^^^^^^^^^^^^^^^^^^^
  File "D:\projects\qr\qr\env\scripts\python.py\Lib\site-packages\django\core\handlers\base.py", line 197, in _get_response
    response = wrapped_callback(request, *callback_args, **callback_kwargs)
               ^^^^^^^^^^^^^^^^^^^^^^^^^^^^^^^^^^^^^^^^^^^^^^^^^^^^^^^^^^^^
  File "D:\projects\qr\qr\qr\website\views.py", line 6, in home
    return render(request, 'website/pages/index.html', context)
           ^^^^^^^^^^^^^^^^^^^^^^^^^^^^^^^^^^^^^^^^^^^^^^^^^^^^
  File "D:\projects\qr\qr\env\scripts\python.py\Lib\site-packages\django\shortcuts.py", line 25, in render
    content = loader.render_to_string(template_name, context, request, using=using)
              ^^^^^^^^^^^^^^^^^^^^^^^^^^^^^^^^^^^^^^^^^^^^^^^^^^^^^^^^^^^^^^^^^^^^^
  File "D:\projects\qr\qr\env\scripts\python.py\Lib\site-packages\django\template\loader.py", line 61, in render_to_string
    template = get_template(template_name, using=using)
               ^^^^^^^^^^^^^^^^^^^^^^^^^^^^^^^^^^^^^^^^
  File "D:\projects\qr\qr\env\scripts\python.py\Lib\site-packages\django\template\loader.py", line 19, in get_template
    raise TemplateDoesNotExist(template_name, chain=chain)
django.template.exceptions.TemplateDoesNotExist: website/pages/index.html
ERROR 2025-03-18 10:54:55,696 D:\projects\qr\qr\env\scripts\python.py\Lib\site-packages\django\core\servers\basehttp.py:213 "GET / HTTP/1.1" 500 83794
ERROR 2025-03-18 10:55:33,007 D:\projects\qr\qr\env\scripts\python.py\Lib\site-packages\django\utils\log.py:248 Internal Server Error: /
Traceback (most recent call last):
  File "D:\projects\qr\qr\env\scripts\python.py\Lib\site-packages\django\core\handlers\exception.py", line 55, in inner
    response = get_response(request)
               ^^^^^^^^^^^^^^^^^^^^^
  File "D:\projects\qr\qr\env\scripts\python.py\Lib\site-packages\django\core\handlers\base.py", line 197, in _get_response
    response = wrapped_callback(request, *callback_args, **callback_kwargs)
               ^^^^^^^^^^^^^^^^^^^^^^^^^^^^^^^^^^^^^^^^^^^^^^^^^^^^^^^^^^^^
  File "D:\projects\qr\qr\qr\website\views.py", line 6, in home
    return render(request, 'website/pages/index.html', context)
           ^^^^^^^^^^^^^^^^^^^^^^^^^^^^^^^^^^^^^^^^^^^^^^^^^^^^
  File "D:\projects\qr\qr\env\scripts\python.py\Lib\site-packages\django\shortcuts.py", line 25, in render
    content = loader.render_to_string(template_name, context, request, using=using)
              ^^^^^^^^^^^^^^^^^^^^^^^^^^^^^^^^^^^^^^^^^^^^^^^^^^^^^^^^^^^^^^^^^^^^^
  File "D:\projects\qr\qr\env\scripts\python.py\Lib\site-packages\django\template\loader.py", line 61, in render_to_string
    template = get_template(template_name, using=using)
               ^^^^^^^^^^^^^^^^^^^^^^^^^^^^^^^^^^^^^^^^
  File "D:\projects\qr\qr\env\scripts\python.py\Lib\site-packages\django\template\loader.py", line 19, in get_template
    raise TemplateDoesNotExist(template_name, chain=chain)
django.template.exceptions.TemplateDoesNotExist: website/pages/index.html
ERROR 2025-03-18 10:55:33,009 D:\projects\qr\qr\env\scripts\python.py\Lib\site-packages\django\core\servers\basehttp.py:213 "GET / HTTP/1.1" 500 83951
ERROR 2025-03-18 10:55:37,145 D:\projects\qr\qr\env\scripts\python.py\Lib\site-packages\django\utils\log.py:248 Internal Server Error: /
Traceback (most recent call last):
  File "D:\projects\qr\qr\env\scripts\python.py\Lib\site-packages\django\core\handlers\exception.py", line 55, in inner
    response = get_response(request)
               ^^^^^^^^^^^^^^^^^^^^^
  File "D:\projects\qr\qr\env\scripts\python.py\Lib\site-packages\django\core\handlers\base.py", line 197, in _get_response
    response = wrapped_callback(request, *callback_args, **callback_kwargs)
               ^^^^^^^^^^^^^^^^^^^^^^^^^^^^^^^^^^^^^^^^^^^^^^^^^^^^^^^^^^^^
  File "D:\projects\qr\qr\qr\website\views.py", line 6, in home
    return render(request, 'website/pages/index.html', context)
           ^^^^^^^^^^^^^^^^^^^^^^^^^^^^^^^^^^^^^^^^^^^^^^^^^^^^
  File "D:\projects\qr\qr\env\scripts\python.py\Lib\site-packages\django\shortcuts.py", line 25, in render
    content = loader.render_to_string(template_name, context, request, using=using)
              ^^^^^^^^^^^^^^^^^^^^^^^^^^^^^^^^^^^^^^^^^^^^^^^^^^^^^^^^^^^^^^^^^^^^^
  File "D:\projects\qr\qr\env\scripts\python.py\Lib\site-packages\django\template\loader.py", line 61, in render_to_string
    template = get_template(template_name, using=using)
               ^^^^^^^^^^^^^^^^^^^^^^^^^^^^^^^^^^^^^^^^
  File "D:\projects\qr\qr\env\scripts\python.py\Lib\site-packages\django\template\loader.py", line 19, in get_template
    raise TemplateDoesNotExist(template_name, chain=chain)
django.template.exceptions.TemplateDoesNotExist: website/pages/index.html
ERROR 2025-03-18 10:55:37,149 D:\projects\qr\qr\env\scripts\python.py\Lib\site-packages\django\core\servers\basehttp.py:213 "GET / HTTP/1.1" 500 83951
ERROR 2025-03-18 10:55:40,076 D:\projects\qr\qr\env\scripts\python.py\Lib\site-packages\django\utils\log.py:248 Internal Server Error: /
Traceback (most recent call last):
  File "D:\projects\qr\qr\env\scripts\python.py\Lib\site-packages\django\core\handlers\exception.py", line 55, in inner
    response = get_response(request)
               ^^^^^^^^^^^^^^^^^^^^^
  File "D:\projects\qr\qr\env\scripts\python.py\Lib\site-packages\django\core\handlers\base.py", line 197, in _get_response
    response = wrapped_callback(request, *callback_args, **callback_kwargs)
               ^^^^^^^^^^^^^^^^^^^^^^^^^^^^^^^^^^^^^^^^^^^^^^^^^^^^^^^^^^^^
  File "D:\projects\qr\qr\qr\website\views.py", line 6, in home
    return render(request, 'website/pages/index.html', context)
           ^^^^^^^^^^^^^^^^^^^^^^^^^^^^^^^^^^^^^^^^^^^^^^^^^^^^
  File "D:\projects\qr\qr\env\scripts\python.py\Lib\site-packages\django\shortcuts.py", line 25, in render
    content = loader.render_to_string(template_name, context, request, using=using)
              ^^^^^^^^^^^^^^^^^^^^^^^^^^^^^^^^^^^^^^^^^^^^^^^^^^^^^^^^^^^^^^^^^^^^^
  File "D:\projects\qr\qr\env\scripts\python.py\Lib\site-packages\django\template\loader.py", line 61, in render_to_string
    template = get_template(template_name, using=using)
               ^^^^^^^^^^^^^^^^^^^^^^^^^^^^^^^^^^^^^^^^
  File "D:\projects\qr\qr\env\scripts\python.py\Lib\site-packages\django\template\loader.py", line 19, in get_template
    raise TemplateDoesNotExist(template_name, chain=chain)
django.template.exceptions.TemplateDoesNotExist: website/pages/index.html
ERROR 2025-03-18 10:55:40,079 D:\projects\qr\qr\env\scripts\python.py\Lib\site-packages\django\core\servers\basehttp.py:213 "GET / HTTP/1.1" 500 84082
ERROR 2025-03-18 11:25:31,550 D:\projects\qr\qr\env\scripts\python.py\Lib\site-packages\django\utils\log.py:248 Internal Server Error: /
Traceback (most recent call last):
  File "D:\projects\qr\qr\env\scripts\python.py\Lib\site-packages\django\core\handlers\exception.py", line 55, in inner
    response = get_response(request)
               ^^^^^^^^^^^^^^^^^^^^^
  File "D:\projects\qr\qr\env\scripts\python.py\Lib\site-packages\django\core\handlers\base.py", line 197, in _get_response
    response = wrapped_callback(request, *callback_args, **callback_kwargs)
               ^^^^^^^^^^^^^^^^^^^^^^^^^^^^^^^^^^^^^^^^^^^^^^^^^^^^^^^^^^^^
  File "D:\projects\qr\qr\qr\website\views.py", line 12, in home
    image = Image.get_last_updated_image_for_user(user)
            ^^^^^^^^^^^^^^^^^^^^^^^^^^^^^^^^^^^^^^^^^^^
  File "D:\projects\qr\qr\qr\website\models.py", line 50, in get_last_updated_image_for_user
    return cls.objects.filter(user=user).order_by('-updated_at').first()
           ^^^^^^^^^^^^^^^^^^^^^^^^^^^^^^^^^^^^^^^^^^^^^^^^^^^^^
  File "D:\projects\qr\qr\env\scripts\python.py\Lib\site-packages\django\db\models\query.py", line 1701, in order_by
    obj.query.add_ordering(*field_names)
  File "D:\projects\qr\qr\env\scripts\python.py\Lib\site-packages\django\db\models\sql\query.py", line 2249, in add_ordering
    self.names_to_path(item.split(LOOKUP_SEP), self.model._meta)
  File "D:\projects\qr\qr\env\scripts\python.py\Lib\site-packages\django\db\models\sql\query.py", line 1768, in names_to_path
    raise FieldError(
django.core.exceptions.FieldError: Cannot resolve keyword 'updated_at' into field. Choices are: id, image, qr_code, user, user_id
ERROR 2025-03-18 11:25:31,554 D:\projects\qr\qr\env\scripts\python.py\Lib\site-packages\django\core\servers\basehttp.py:213 "GET / HTTP/1.1" 500 88111
ERROR 2025-03-18 11:26:17,770 D:\projects\qr\qr\env\scripts\python.py\Lib\site-packages\django\utils\log.py:248 Internal Server Error: /
Traceback (most recent call last):
  File "D:\projects\qr\qr\env\scripts\python.py\Lib\site-packages\django\db\backends\utils.py", line 105, in _execute
    return self.cursor.execute(sql, params)
           ^^^^^^^^^^^^^^^^^^^^^^^^^^^^^^^^
  File "D:\projects\qr\qr\env\scripts\python.py\Lib\site-packages\django\db\backends\sqlite3\base.py", line 354, in execute
    return super().execute(query, params)
           ^^^^^^^^^^^^^^^^^^^^^^^^^^^^^^
sqlite3.OperationalError: no such column: website_image.updated_at

The above exception was the direct cause of the following exception:

Traceback (most recent call last):
  File "D:\projects\qr\qr\env\scripts\python.py\Lib\site-packages\django\core\handlers\exception.py", line 55, in inner
    response = get_response(request)
               ^^^^^^^^^^^^^^^^^^^^^
  File "D:\projects\qr\qr\env\scripts\python.py\Lib\site-packages\django\core\handlers\base.py", line 197, in _get_response
    response = wrapped_callback(request, *callback_args, **callback_kwargs)
               ^^^^^^^^^^^^^^^^^^^^^^^^^^^^^^^^^^^^^^^^^^^^^^^^^^^^^^^^^^^^
  File "D:\projects\qr\qr\qr\website\views.py", line 12, in home
    image = Image.get_last_updated_image_for_user(user)
            ^^^^^^^^^^^^^^^^^^^^^^^^^^^^^^^^^^^^^^^^^^^
  File "D:\projects\qr\qr\qr\website\models.py", line 51, in get_last_updated_image_for_user
    return cls.objects.filter(user=user).order_by('-updated_at').first()
           ^^^^^^^^^^^^^^^^^^^^^^^^^^^^^^^^^^^^^^^^^^^^^^^^^^^^^^^^^^^^^
  File "D:\projects\qr\qr\env\scripts\python.py\Lib\site-packages\django\db\models\query.py", line 1097, in first
    for obj in queryset[:1]:
               ~~~~~~~~^^^^
  File "D:\projects\qr\qr\env\scripts\python.py\Lib\site-packages\django\db\models\query.py", line 400, in __iter__
    self._fetch_all()
  File "D:\projects\qr\qr\env\scripts\python.py\Lib\site-packages\django\db\models\query.py", line 1928, in _fetch_all
    self._result_cache = list(self._iterable_class(self))
                         ^^^^^^^^^^^^^^^^^^^^^^^^^^^^^^^^
  File "D:\projects\qr\qr\env\scripts\python.py\Lib\site-packages\django\db\models\query.py", line 91, in __iter__
    results = compiler.execute_sql(
              ^^^^^^^^^^^^^^^^^^^^^
  File "D:\projects\qr\qr\env\scripts\python.py\Lib\site-packages\django\db\models\sql\compiler.py", line 1574, in execute_sql
    cursor.execute(sql, params)
  File "D:\projects\qr\qr\env\scripts\python.py\Lib\site-packages\django\db\backends\utils.py", line 122, in execute
    return super().execute(sql, params)
           ^^^^^^^^^^^^^^^^^^^^^^^^^^^^
  File "D:\projects\qr\qr\env\scripts\python.py\Lib\site-packages\django\db\backends\utils.py", line 79, in execute
    return self._execute_with_wrappers(
           ^^^^^^^^^^^^^^^^^^^^^^^^^^^^
  File "D:\projects\qr\qr\env\scripts\python.py\Lib\site-packages\django\db\backends\utils.py", line 92, in _execute_with_wrappers
    return executor(sql, params, many, context)
           ^^^^^^^^^^^^^^^^^^^^^^^^^^^^^^^^^^^^
  File "D:\projects\qr\qr\env\scripts\python.py\Lib\site-packages\django\db\backends\utils.py", line 100, in _execute
    with self.db.wrap_database_errors:
         ^^^^^^^^^^^^^^^^^^^^^^^^^^^^
  File "D:\projects\qr\qr\env\scripts\python.py\Lib\site-packages\django\db\utils.py", line 91, in __exit__
    raise dj_exc_value.with_traceback(traceback) from exc_value
  File "D:\projects\qr\qr\env\scripts\python.py\Lib\site-packages\django\db\backends\utils.py", line 105, in _execute
    return self.cursor.execute(sql, params)
           ^^^^^^^^^^^^^^^^^^^^^^^^^^^^^^^^
  File "D:\projects\qr\qr\env\scripts\python.py\Lib\site-packages\django\db\backends\sqlite3\base.py", line 354, in execute
    return super().execute(query, params)
           ^^^^^^^^^^^^^^^^^^^^^^^^^^^^^^
django.db.utils.OperationalError: no such column: website_image.updated_at
ERROR 2025-03-18 11:26:17,775 D:\projects\qr\qr\env\scripts\python.py\Lib\site-packages\django\core\servers\basehttp.py:213 "GET / HTTP/1.1" 500 140027
